Workbook

Sheet Sheet1
A1: Q1_Age | B1: Q2_Gender | C1: Q3_Place_of_residence | D1: Q4_Occupation | E1: Q5_Monthly_household_income | F1: Q6_Q_commerce_apps_used | G1: Q7_Order_frequency_Q_commerce | H1: Q8_Received_poor_quality_perishable | I1: Q9_App_most_recent_poor_item | J1: Q10_Poor_quality_frequency_6_months | K1: Q11_Reaction_to_poor_quality | L1: Q12_Used_Zepto | M1: Q13_Trust_Zepto_fresh_perishables_1_5 | N1: Q14_Satisfaction_perishables_overall_1_5 | O1: Q15_Quality_influences_reorder_1_5 | P1: Q16_Quality_controls_reliable_1_5 | Q1: Q17_Price_fair_given_quality_1_5 | R1: Q18_Likely_continue_next_month | S1: Q19_Switched_due_to_quality_1_5 | T1: Q20_Recommend_Zepto | U1: Q21_Freshness_guarantee_intent_1_5 | V1: Q22_Strict_sourcing_trust_increase_1_5 | W1: Q23_Subscription_likely_to_subscribe | X1: Q24_Subscription_WTP_Rs_per_month | Y1: Q25_Premium_percent_willing
A2: 25–34 | B2: Male | C2: Village | D2: Employed (salaried) | E2: < ₹20,000 | F2: Instamart, Local grocery app, None | G2: Weekly | H2: Yes | I2: Instamart | J2: 6+ times | K2: Complain to friends/family, Do nothing, Return item in app | L2: No | M2: 2 | N2: 3 | O2: 3 | P2: 3 | Q2: 2 | R2: Very unlikely | S2: 3 | T2: Probably no | U2: 3 | V2: 3 | W2: Very likely | X2: 165 | Y2: 6–10%
A3: 25–34 | B3: Non-binary | C3: Urban | D3: Student | E3: ₹20–40k | F3: Local grocery app, Zepto | G3: 2–3 times/week | H3: No | J3: 0 times | K3: Do nothing | L3: Yes | M3: 4 | N3: 4 | O3: 4 | P3: 4 | Q3: 4 | R3: Likely | S3: 2 | T3: Definitely yes | U3: 4 | V3: 4 | W3: Neutral | X3: 47 | Y3: 11–20%
A4: 18–24 | B4: Female | C4: Urban | D4: Student | E4: ₹40–60k | F4: Blinkit, Local grocery app, Zepto | G4: Weekly | H4: Yes | I4: Zepto | J4: 0 times | K4: Complain to customer support, Return item in app | L4: Yes | M4: 3 | N4: 3 | O4: 3 | P4: 3 | Q4: 3 | R4: Very likely | S4: 2 | T4: Probably yes | U4: 4 | V4: 4 | W4: Neutral | X4: 114 | Y4: up to 5%
A5: 18–24 | B5: Male | C5: Sub-urban | D5: Student | E5: < ₹20,000 | F5: Blinkit, Local grocery app, Zepto | G5: 2–3 times/week | H5: Yes | I5: Zepto | J5: 2–3 times | K5: Do nothing, Return item in app | L5: Yes | M5: 2 | N5: 2 | O5: 2 | P5: 2 | Q5: 2 | R5: Unlikely | S5: 4 | T5: Might or might not | U5: 3 | V5: 2 | W5: Very unlikely | X5: 70 | Y5: up to 5%
A6: 18–24 | B6: Female | C6: Urban | D6: Self-employed | E6: ₹60–100k | F6: Blinkit, None | G6: Weekly | H6: No | J6: 0 times | K6: Do nothing | L6: Yes | M6: 4 | N6: 4 | O6: 4 | P6: 4 | Q6: 4 | R6: Likely | S6: 3 | T6: Probably no | U6: 4 | V6: 4 | W6: Neutral | X6: 91 | Y6: >20%
A7: 18–24 | B7: Female | C7: Urban | D7: Student | E7: ₹20–40k | F7: Instamart | G7: Weekly | H7: Yes | I7: Instamart | J7: 0 times | K7: Do nothing, Post on social media | L7: Yes | M7: 4 | N7: 3 | O7: 4 | P7: 3 | Q7: 3 | R7: Very likely | S7: 2 | T7: Might or might not | U7: 4 | V7: 4 | W7: Very unlikely | X7: 19 | Y7: 0%
A8: 25–34 | B8: Male | C8: Sub-urban | D8: Self-employed | E8: ₹20–40k | F8: Blinkit, Local grocery app | G8: 2–3 times/week | H8: No | J8: 0 times | K8: Do nothing | L8: No | M8: 3 | N8: 3 | O8: 4 | P8: 4 | Q8: 3 | R8: Unlikely | S8: 3 | T8: Probably yes | U8: 4 | V8: 3 | W8: Neutral | X8: 114 | Y8: 6–10%
A9: 18–24 | B9: Female | C9: Urban | D9: Student | E9: ₹60–100k | F9: Blinkit, Instamart, Zepto | G9: 2–3 times/week | H9: Yes | I9: Instamart | J9: 2–3 times | K9: Do nothing | L9: Yes | M9: 3 | N9: 3 | O9: 4 | P9: 3 | Q9: 3 | R9: Very likely | S9: 3 | T9: Probably no | U9: 3 | V9: 3 | W9: Unlikely | X9: 71 | Y9: 6–10%
A10: 18–24 | B10: Male | C10: Village | D10: Student | E10: ₹20–40k | F10: Blinkit, Instamart | G10: 2–3 times/week | H10: No | J10: 0 times | K10: Do nothing | L10: Yes | M10: 4 | N10: 3 | O10: 4 | P10: 4 | Q10: 4 | R10: Likely | S10: 3 | T10: Might or might not | U10: 4 | V10: 4 | W10: Very likely | X10: 197 | Y10: 11–20%
A11: 25–34 | B11: Male | C11: Urban | D11: Employed (salaried) | E11: > ₹100k | F11: Instamart | G11: 2–3 times/week | H11: Yes | I11: Instamart | J11: 2–3 times | K11: Do nothing, Post on social media, Return item in app | L11: No | M11: 3 | N11: 3 | O11: 2 | P11: 2 | Q11: 2 | R11: Unlikely | S11: 4 | T11: Probably yes | U11: 3 | V11: 3 | W11: Likely | X11: 143 | Y11: 0%
A12: 18–24 | B12: Male | C12: Urban | D12: Student | E12: ₹40–60k | F12: Blinkit, Local grocery app, None | G12: Rarely | H12: No | J12: 0 times | K12: Do nothing | L12: Yes | M12: 4 | N12: 4 | O12: 4 | P12: 3 | Q12: 3 | R12: Neutral | S12: 3 | T12: Probably no | U12: 3 | V12: 4 | W12: Very unlikely | X12: 21 | Y12: 11–20%
A13: 25–34 | B13: Female | C13: Sub-urban | D13: Student | E13: ₹40–60k | F13: Instamart, Local grocery app, None | G13: Weekly | H13: Yes | I13: Instamart | J13: 0 times | K13: Complain to customer support, Return item in app | L13: No | M13: 2 | N13: 2 | O13: 2 | P13: 2 | Q13: 2 | R13: Very unlikely | S13: 4 | T13: Might or might not | U13: 3 | V13: 3 | W13: Unlikely | X13: 59 | Y13: 11–20%
A14: 18–24 | B14: Female | C14: Urban | D14: Employed (salaried) | E14: < ₹20,000 | F14: Local grocery app, None | G14: Weekly | H14: Yes | I14: Zepto | J14: 2–3 times | K14: Complain to customer support, Post on social media | L14: Yes | M14: 2 | N14: 3 | O14: 3 | P14: 2 | Q14: 2 | R14: Likely | S14: 4 | T14: Definitely yes | U14: 3 | V14: 3 | W14: Neutral | X14: 18 | Y14: 6–10%
A15: 25–34 | B15: Female | C15: Urban | D15: Employed (salaried) | E15: Prefer not to say | F15: Instamart, None, Zepto | G15: Weekly | H15: No | J15: 0 times | K15: Do nothing | L15: Yes | M15: 4 | N15: 4 | O15: 4 | P15: 4 | Q15: 4 | R15: Very likely | S15: 3 | T15: Definitely yes | U15: 5 | V15: 4 | W15: Likely | X15: 208 | Y15: 6–10%
A16: 45–54 | B16: Female | C16: Urban | D16: Student | E16: Prefer not to say | F16: Blinkit, Instamart, Zepto | G16: Weekly | H16: Yes | I16: Blinkit | J16: 1 time | K16: Complain to friends/family | L16: Yes | M16: 3 | N16: 2 | O16: 3 | P16: 2 | Q16: 3 | R16: Likely | S16: 3 | T16: Probably no | U16: 3 | V16: 3 | W16: Very unlikely | X16: 37 | Y16: 11–20%
A17: 18–24 | B17: Prefer not to say | C17: Sub-urban | D17: Employed (salaried) | E17: < ₹20,000 | F17: Blinkit, Local grocery app, Zepto | G17: Monthly | H17: Yes | I17: Zepto | J17: 4–5 times | K17: Complain to friends/family | L17: Yes | M17: 2 | N17: 3 | O17: 2 | P17: 2 | Q17: 2 | R17: Unlikely | S17: 4 | T17: Definitely no | U17: 3 | V17: 3 | W17: Unlikely | X17: 82 | Y17: 0%
A18: 18–24 | B18: Male | C18: Urban | D18: Employed (salaried) | E18: ₹40–60k | F18: None, Zepto | G18: 2–3 times/week | H18: Yes | I18: Zepto | J18: 2–3 times | K18: Complain to friends/family, Do nothing | L18: Yes | M18: 3 | N18: 3 | O18: 3 | P18: 2 | Q18: 3 | R18: Very likely | S18: 3 | T18: Definitely no | U18: 3 | V18: 4 | W18: Neutral | X18: 110 | Y18: 0%
A19: 45–54 | B19: Male | C19: Urban | D19: Employed (salaried) | E19: ₹40–60k | F19: Zepto | G19: Weekly | H19: Yes | I19: Zepto | J19: 1 time | K19: Complain to customer support | L19: Yes | M19: 3 | N19: 3 | O19: 3 | P19: 3 | Q19: 3 | R19: Likely | S19: 3 | T19: Probably yes | U19: 3 | V19: 3 | W19: Very likely | X19: 137 | Y19: up to 5%
A20: 18–24 | B20: Female | C20: Urban | D20: Employed (salaried) | E20: ₹40–60k | F20: Blinkit, None | G20: Weekly | H20: Yes | I20: Blinkit | J20: 2–3 times | K20: Do nothing, Return item in app | L20: No | M20: 3 | N20: 3 | O20: 3 | P20: 3 | Q20: 3 | R20: Unlikely | S20: 3 | T20: Definitely no | U20: 4 | V20: 3 | W20: Likely | X20: 136 | Y20: up to 5%
A21: 25–34 | B21: Male | C21: Sub-urban | D21: Self-employed | E21: ₹20–40k | F21: Local grocery app | G21: Daily | H21: Yes | I21: Blinkit | J21: 6+ times | K21: Do nothing | L21: No | M21: 2 | N21: 2 | O21: 2 | P21: 2 | Q21: 2 | R21: Likely | S21: 4 | T21: Probably yes | U21: 2 | V21: 3 | W21: Very unlikely | X21: 24 | Y21: 11–20%
A22: 55+ | B22: Male | C22: Urban | D22: Student | E22: < ₹20,000 | F22: Instamart | G22: Weekly | H22: Yes | I22: Instamart | J22: 0 times | K22: Do nothing | L22: Yes | M22: 2 | N22: 2 | O22: 3 | P22: 1 | Q22: 2 | R22: Likely | S22: 4 | T22: Probably no | U22: 2 | V22: 2 | W22: Unlikely | X22: 54 | Y22: up to 5%
A23: 18–24 | B23: Male | C23: Sub-urban | D23: Student | E23: ₹60–100k | F23: Instamart, None | G23: Weekly | H23: No | J23: 0 times | K23: Do nothing | L23: No | M23: 3 | N23: 3 | O23: 3 | P23: 3 | Q23: 3 | R23: Likely | S23: 4 | T23: Definitely no | U23: 4 | V23: 3 | W23: Neutral | X23: 96 | Y23: up to 5%
A24: 25–34 | B24: Female | C24: Village | D24: Employed (salaried) | E24: ₹20–40k | F24: Instamart, Local grocery app | G24: Never | H24: No | J24: 0 times | K24: Do nothing | L24: No | M24: 4 | N24: 3 | O24: 4 | P24: 4 | Q24: 4 | R24: Very unlikely | S24: 2 | T24: Probably yes | U24: 4 | V24: 4 | W24: Unlikely | X24: 35 | Y24: >20%
A25: 18–24 | B25: Non-binary | C25: Urban | D25: Employed (salaried) | E25: < ₹20,000 | F25: Blinkit, Local grocery app | G25: Monthly | H25: Yes | I25: Blinkit | J25: 1 time | K25: Complain to customer support, Do nothing, Return item in app | L25: No | M25: 3 | N25: 3 | O25: 4 | P25: 3 | Q25: 3 | R25: Likely | S25: 3 | T25: Definitely yes | U25: 4 | V25: 3 | W25: Very likely | X25: 127 | Y25: 11–20%
A26: 25–34 | B26: Male | C26: Village | D26: Student | E26: > ₹100k | F26: Blinkit, Local grocery app, None | G26: Rarely | H26: Yes | I26: Blinkit | J26: 0 times | K26: Complain to friends/family, Do nothing, Return item in app | L26: No | M26: 3 | N26: 3 | O26: 4 | P26: 2 | Q26: 3 | R26: Very unlikely | S26: 3 | T26: Probably yes | U26: 4 | V26: 3 | W26: Likely | X26: 161 | Y26: up to 5%
A27: 25–34 | B27: Male | C27: Urban | D27: Other | E27: ₹60–100k | F27: Blinkit, None, Zepto | G27: 2–3 times/week | H27: No | J27: 0 times | K27: Do nothing | L27: Yes | M27: 2 | N27: 3 | O27: 4 | P27: 3 | Q27: 3 | R27: Very likely | S27: 3 | T27: Probably no | U27: 4 | V27: 4 | W27: Unlikely | X27: 44 | Y27: up to 5%
A28: 18–24 | B28: Prefer not to say | C28: Sub-urban | D28: Self-employed | E28: Prefer not to say | F28: None, Zepto | G28: Daily | H28: No | J28: 0 times | K28: Do nothing | L28: Yes | M28: 3 | N28: 3 | O28: 4 | P28: 2 | Q28: 3 | R28: Very likely | S28: 4 | T28: Definitely yes | U28: 3 | V28: 4 | W28: Likely | X28: 139 | Y28: 0%
A29: 18–24 | B29: Male | C29: Sub-urban | D29: Student | E29: ₹20–40k | F29: Instamart | G29: Daily | H29: Yes | I29: Instamart | J29: 4–5 times | K29: Complain to customer support | L29: No | M29: 1 | N29: 2 | O29: 2 | P29: 1 | Q29: 2 | R29: Likely | S29: 5 | T29: Might or might not | U29: 2 | V29: 3 | W29: Likely | X29: 179 | Y29: 0%
A30: 18–24 | B30: Female | C30: Urban | D30: Student | E30: < ₹20,000 | F30: Zepto | G30: 2–3 times/week | H30: Yes | I30: Zepto | J30: 0 times | K30: Complain to friends/family, Do nothing, Return item in app | L30: Yes | M30: 2 | N30: 2 | O30: 3 | P30: 3 | Q30: 2 | R30: Unlikely | S30: 4 | T30: Probably yes | U30: 3 | V30: 2 | W30: Neutral | X30: 161 | Y30: up to 5%
A31: 35–44 | B31: Male | C31: Sub-urban | D31: Employed (salaried) | E31: < ₹20,000 | F31: Blinkit, None | G31: Daily | H31: Yes | I31: Blinkit | J31: 0 times | K31: Complain to customer support, Complain to friends/family, Post on social media | L31: No | M31: 3 | N31: 4 | O31: 4 | P31: 4 | Q31: 3 | R31: Very likely | S31: 2 | T31: Definitely no | U31: 4 | V31: 4 | W31: Very unlikely | X31: 71 | Y31: 0%
A32: 35–44 | B32: Female | C32: Urban | D32: Employed (salaried) | E32: ₹20–40k | F32: Instamart, Zepto | G32: Twice a month | H32: No | J32: 0 times | K32: Do nothing | L32: Yes | M32: 4 | N32: 4 | O32: 4 | P32: 3 | Q32: 3 | R32: Likely | S32: 3 | T32: Might or might not | U32: 4 | V32: 4 | W32: Unlikely | X32: 17 | Y32: up to 5%
A33: 18–24 | B33: Male | C33: Sub-urban | D33: Student | E33: ₹20–40k | F33: Blinkit, Instamart, Local grocery app | G33: Daily | H33: No | J33: 0 times | K33: Do nothing | L33: No | M33: 4 | N33: 4 | O33: 4 | P33: 4 | Q33: 4 | R33: Likely | S33: 2 | T33: Probably yes | U33: 5 | V33: 5 | W33: Very likely | X33: 133 | Y33: 11–20%
A34: 25–34 | B34: Male | C34: Urban | D34: Employed (salaried) | E34: < ₹20,000 | F34: Blinkit, Local grocery app, None | G34: 2–3 times/week | H34: Yes | I34: Blinkit | J34: 2–3 times | K34: Post on social media, Return item in app | L34: No | M34: 2 | N34: 3 | O34: 3 | P34: 3 | Q34: 3 | R34: Likely | S34: 3 | T34: Might or might not | U34: 3 | V34: 3 | W34: Very likely | X34: 146 | Y34: 11–20%
A35: 18–24 | B35: Male | C35: Urban | D35: Student | E35: ₹20–40k | F35: Zepto | G35: Weekly | H35: No | J35: 0 times | K35: Do nothing | L35: Yes | M35: 3 | N35: 3 | O35: 4 | P35: 3 | Q35: 3 | R35: Unlikely | S35: 3 | T35: Definitely no | U35: 4 | V35: 4 | W35: Very likely | X35: 160 | Y35: up to 5%
A36: 25–34 | B36: Male | C36: Sub-urban | D36: Employed (salaried) | E36: ₹40–60k | F36: Blinkit | G36: 2–3 times/week | H36: No | J36: 0 times | K36: Do nothing | L36: No | M36: 3 | N36: 2 | O36: 3 | P36: 3 | Q36: 3 | R36: Likely | S36: 4 | T36: Probably yes | U36: 3 | V36: 3 | W36: Likely | X36: 105 | Y36: up to 5%
A37: 18–24 | B37: Male | C37: Urban | D37: Employed (salaried) | E37: > ₹100k | F37: Blinkit, Instamart, None | G37: 2–3 times/week | H37: Yes | I37: Blinkit | J37: 6+ times | K37: Do nothing | L37: No | M37: 3 | N37: 2 | O37: 3 | P37: 2 | Q37: 2 | R37: Very likely | S37: 4 | T37: Might or might not | U37: 3 | V37: 3 | W37: Neutral | X37: 58 | Y37: up to 5%
A38: 18–24 | B38: Male | C38: Village | D38: Student | E38: ₹40–60k | F38: Blinkit, Instamart, None | G38: Never | H38: No | J38: 0 times | K38: Do nothing | L38: No | M38: 2 | N38: 3 | O38: 2 | P38: 2 | Q38: 3 | R38: Unlikely | S38: 3 | T38: Probably no | U38: 3 | V38: 3 | W38: Very unlikely | X38: 23 | Y38: 6–10%
A39: 18–24 | B39: Prefer not to say | C39: Urban | D39: Student | E39: ₹20–40k | F39: Local grocery app, Zepto | G39: 2–3 times/week | H39: No | J39: 0 times | K39: Do nothing | L39: Yes | M39: 3 | N39: 3 | O39: 3 | P39: 2 | Q39: 3 | R39: Very unlikely | S39: 4 | T39: Probably yes | U39: 4 | V39: 3 | W39: Very likely | X39: 92 | Y39: 11–20%
A40: 25–34 | B40: Prefer not to say | C40: Urban | D40: Employed (salaried) | E40: ₹20–40k | F40: Blinkit, Instamart, Local grocery app | G40: Weekly | H40: No | J40: 0 times | K40: Do nothing | L40: No | M40: 4 | N40: 3 | O40: 4 | P40: 3 | Q40: 4 | R40: Very likely | S40: 3 | T40: Might or might not | U40: 4 | V40: 4 | W40: Very likely | X40: 99 | Y40: up to 5%
...

Sheet LOOKUPS
A1: QUESTION 7
A2: Category | B2: Numeric_Code
A3: Daily | B3: 7
A4: 2–3 times/week | B4: 6
A5: Weekly | B5: 5
A6: Twice a month | B6: 4
A7: Monthly | B7: 3
A8: Rarely | B8: 2
A9: Never | B9: 1
A11: QUESTION 8
A12: Category | B12: Numeric_Code
A13: Yes | B13: 1
A14: No | B14: 0
A16: QUESTION 10
A17: Category | B17: Numeric_Code
A18: 6+ times | B18: 5
A19: 4–5 times | B19: 4
A20: 2–3 times | B20: 3
A21: 1 time | B21: 2
A22: 0 times | B22: 1
A24: QUESTION 12
A25: Category | B25: Numeric_Code
A26: No | B26: 0
A27: Yes | B27: 1
A29: QUESTION 20
A30: Category | B30: Numeric_Code
A31: Definitely yes | B31: 5
A32: Probably yes | B32: 4
A33: Might or might not | B33: 3
A34: Probably no | B34: 2
A35: Definitely no | B35: 1
A37: QUESTION 18
A38: Category | B38: Numeric_Code
A39: Very likely | B39: 5
A40: Likely | B40: 4
A41: Neutral | B41: 3
A42: Unlikely | B42: 2
A43: Very unlikely | B43: 1
A45: QUESTION 23
A46: Category | B46: Numeric_Code
...

Sheet QUANTIFIED RESPONSES
A1: Q1_Age | B1: Q2_Gender | C1: Q3_Place_of_residence | D1: Q4_Occupation | E1: Q5_Monthly_household_income | F1: Q6_Q_commerce_apps_used | G1: Q7_Order_frequency_Q_commerce | H1: Q8_Received_poor_quality_perishable | I1: Q9_App_most_recent_poor_item | J1: Q10_Poor_quality_frequency_6_months | K1: Q11_Reaction_to_poor_quality | L1: Q12_Used_Zepto | M1: Q13_Trust_Zepto_fresh_perishables_1_5 | N1: Q14_Satisfaction_perishables_overall_1_5 | O1: Q15_Quality_influences_reorder_1_5 | P1: Q16_Quality_controls_reliable_1_5 | Q1: Q17_Price_fair_given_quality_1_5 | R1: Q18_Likely_continue_next_month | S1: Q19_Switched_due_to_quality_1_5 | T1: Q20_Recommend_Zepto | U1: Q21_Freshness_guarantee_intent_1_5 | V1: Q22_Strict_sourcing_trust_increase_1_5 | W1: Q23_Subscription_likely_to_subscribe | X1: Q24_Subscription_WTP_Rs_per_month | Y1: Q25_Premium_percent_willing
A2: 25–34 | B2: Male | C2: Village | D2: Employed (salaried) | E2: < ₹20,000 | F2: Instamart, Local grocery app, None | G2: =VLOOKUP(Sheet1!G2,LOOKUPS!$A$3:$B$9,2,FALSE) -> 5 | H2: =VLOOKUP(Sheet1!H2,LOOKUPS!$A$13:$B$14,2,FALSE) -> 1 | I2: Instamart | J2: =VLOOKUP(Sheet1!J2,LOOKUPS!$A$18:$B$22,2,FALSE) -> 5 | K2: Complain to friends/family, Do nothing, Return item in app | L2: =VLOOKUP(Sheet1!L2,LOOKUPS!$A$26:$B$27,2,FALSE) -> 0 | M2: 2 | N2: 3 | O2: 3 | P2: 3 | Q2: 2 | R2: =VLOOKUP(Sheet1!R2,LOOKUPS!$A$39:$B$43,2,FALSE) -> 1 | S2: 3 | T2: =VLOOKUP(Sheet1!T2,LOOKUPS!$A$31:$E$35,2,FALSE) -> 2 | U2: 3 | V2: 3 | W2: Very likely | X2: 165 | Y2: 6–10%
A3: 25–34 | B3: Non-binary | C3: Urban | D3: Student | E3: ₹20–40k | F3: Local grocery app, Zepto | G3: =VLOOKUP(Sheet1!G3,LOOKUPS!$A$3:$B$9,2,FALSE) -> 6 | H3: =VLOOKUP(Sheet1!H3,LOOKUPS!$A$13:$B$14,2,FALSE) -> 0 | J3: =VLOOKUP(Sheet1!J3,LOOKUPS!$A$18:$B$22,2,FALSE) -> 1 | K3: Do nothing | L3: =VLOOKUP(Sheet1!L3,LOOKUPS!$A$26:$B$27,2,FALSE) -> 1 | M3: 4 | N3: 4 | O3: 4 | P3: 4 | Q3: 4 | R3: =VLOOKUP(Sheet1!R3,LOOKUPS!$A$39:$B$43,2,FALSE) -> 4 | S3: 2 | T3: =VLOOKUP(Sheet1!T3,LOOKUPS!$A$31:$E$35,2,FALSE) -> 5 | U3: 4 | V3: 4 | W3: Neutral | X3: 47 | Y3: 11–20%
A4: 18–24 | B4: Female | C4: Urban | D4: Student | E4: ₹40–60k | F4: Blinkit, Local grocery app, Zepto | G4: =VLOOKUP(Sheet1!G4,LOOKUPS!$A$3:$B$9,2,FALSE) -> 5 | H4: =VLOOKUP(Sheet1!H4,LOOKUPS!$A$13:$B$14,2,FALSE) -> 1 | I4: Zepto | J4: =VLOOKUP(Sheet1!J4,LOOKUPS!$A$18:$B$22,2,FALSE) -> 1 | K4: Complain to customer support, Return item in app | L4: =VLOOKUP(Sheet1!L4,LOOKUPS!$A$26:$B$27,2,FALSE) -> 1 | M4: 3 | N4: 3 | O4: 3 | P4: 3 | Q4: 3 | R4: =VLOOKUP(Sheet1!R4,LOOKUPS!$A$39:$B$43,2,FALSE) -> 5 | S4: 2 | T4: =VLOOKUP(Sheet1!T4,LOOKUPS!$A$31:$E$35,2,FALSE) -> 4 | U4: 4 | V4: 4 | W4: Neutral | X4: 114 | Y4: up to 5%
A5: 18–24 | B5: Male | C5: Sub-urban | D5: Student | E5: < ₹20,000 | F5: Blinkit, Local grocery app, Zepto | G5: =VLOOKUP(Sheet1!G5,LOOKUPS!$A$3:$B$9,2,FALSE) -> 6 | H5: =VLOOKUP(Sheet1!H5,LOOKUPS!$A$13:$B$14,2,FALSE) -> 1 | I5: Zepto | J5: =VLOOKUP(Sheet1!J5,LOOKUPS!$A$18:$B$22,2,FALSE) -> 3 | K5: Do nothing, Return item in app | L5: =VLOOKUP(Sheet1!L5,LOOKUPS!$A$26:$B$27,2,FALSE) -> 1 | M5: 2 | N5: 2 | O5: 2 | P5: 2 | Q5: 2 | R5: =VLOOKUP(Sheet1!R5,LOOKUPS!$A$39:$B$43,2,FALSE) -> 2 | S5: 4 | T5: =VLOOKUP(Sheet1!T5,LOOKUPS!$A$31:$E$35,2,FALSE) -> 3 | U5: 3 | V5: 2 | W5: Very unlikely | X5: 70 | Y5: up to 5%
A6: 18–24 | B6: Female | C6: Urban | D6: Self-employed | E6: ₹60–100k | F6: Blinkit, None | G6: =VLOOKUP(Sheet1!G6,LOOKUPS!$A$3:$B$9,2,FALSE) -> 5 | H6: =VLOOKUP(Sheet1!H6,LOOKUPS!$A$13:$B$14,2,FALSE) -> 0 | J6: =VLOOKUP(Sheet1!J6,LOOKUPS!$A$18:$B$22,2,FALSE) -> 1 | K6: Do nothing | L6: =VLOOKUP(Sheet1!L6,LOOKUPS!$A$26:$B$27,2,FALSE) -> 1 | M6: 4 | N6: 4 | O6: 4 | P6: 4 | Q6: 4 | R6: =VLOOKUP(Sheet1!R6,LOOKUPS!$A$39:$B$43,2,FALSE) -> 4 | S6: 3 | T6: =VLOOKUP(Sheet1!T6,LOOKUPS!$A$31:$E$35,2,FALSE) -> 2 | U6: 4 | V6: 4 | W6: Neutral | X6: 91 | Y6: >20%
A7: 18–24 | B7: Female | C7: Urban | D7: Student | E7: ₹20–40k | F7: Instamart | G7: =VLOOKUP(Sheet1!G7,LOOKUPS!$A$3:$B$9,2,FALSE) -> 5 | H7: =VLOOKUP(Sheet1!H7,LOOKUPS!$A$13:$B$14,2,FALSE) -> 1 | I7: Instamart | J7: =VLOOKUP(Sheet1!J7,LOOKUPS!$A$18:$B$22,2,FALSE) -> 1 | K7: Do nothing, Post on social media | L7: =VLOOKUP(Sheet1!L7,LOOKUPS!$A$26:$B$27,2,FALSE) -> 1 | M7: 4 | N7: 3 | O7: 4 | P7: 3 | Q7: 3 | R7: =VLOOKUP(Sheet1!R7,LOOKUPS!$A$39:$B$43,2,FALSE) -> 5 | S7: 2 | T7: =VLOOKUP(Sheet1!T7,LOOKUPS!$A$31:$E$35,2,FALSE) -> 3 | U7: 4 | V7: 4 | W7: Very unlikely | X7: 19 | Y7: 0%
A8: 25–34 | B8: Male | C8: Sub-urban | D8: Self-employed | E8: ₹20–40k | F8: Blinkit, Local grocery app | G8: =VLOOKUP(Sheet1!G8,LOOKUPS!$A$3:$B$9,2,FALSE) -> 6 | H8: =VLOOKUP(Sheet1!H8,LOOKUPS!$A$13:$B$14,2,FALSE) -> 0 | J8: =VLOOKUP(Sheet1!J8,LOOKUPS!$A$18:$B$22,2,FALSE) -> 1 | K8: Do nothing | L8: =VLOOKUP(Sheet1!L8,LOOKUPS!$A$26:$B$27,2,FALSE) -> 0 | M8: 3 | N8: 3 | O8: 4 | P8: 4 | Q8: 3 | R8: =VLOOKUP(Sheet1!R8,LOOKUPS!$A$39:$B$43,2,FALSE) -> 2 | S8: 3 | T8: =VLOOKUP(Sheet1!T8,LOOKUPS!$A$31:$E$35,2,FALSE) -> 4 | U8: 4 | V8: 3 | W8: Neutral | X8: 114 | Y8: 6–10%
A9: 18–24 | B9: Female | C9: Urban | D9: Student | E9: ₹60–100k | F9: Blinkit, Instamart, Zepto | G9: =VLOOKUP(Sheet1!G9,LOOKUPS!$A$3:$B$9,2,FALSE) -> 6 | H9: =VLOOKUP(Sheet1!H9,LOOKUPS!$A$13:$B$14,2,FALSE) -> 1 | I9: Instamart | J9: =VLOOKUP(Sheet1!J9,LOOKUPS!$A$18:$B$22,2,FALSE) -> 3 | K9: Do nothing | L9: =VLOOKUP(Sheet1!L9,LOOKUPS!$A$26:$B$27,2,FALSE) -> 1 | M9: 3 | N9: 3 | O9: 4 | P9: 3 | Q9: 3 | R9: =VLOOKUP(Sheet1!R9,LOOKUPS!$A$39:$B$43,2,FALSE) -> 5 | S9: 3 | T9: =VLOOKUP(Sheet1!T9,LOOKUPS!$A$31:$E$35,2,FALSE) -> 2 | U9: 3 | V9: 3 | W9: Unlikely | X9: 71 | Y9: 6–10%
A10: 18–24 | B10: Male | C10: Village | D10: Student | E10: ₹20–40k | F10: Blinkit, Instamart | G10: =VLOOKUP(Sheet1!G10,LOOKUPS!$A$3:$B$9,2,FALSE) -> 6 | H10: =VLOOKUP(Sheet1!H10,LOOKUPS!$A$13:$B$14,2,FALSE) -> 0 | J10: =VLOOKUP(Sheet1!J10,LOOKUPS!$A$18:$B$22,2,FALSE) -> 1 | K10: Do nothing | L10: =VLOOKUP(Sheet1!L10,LOOKUPS!$A$26:$B$27,2,FALSE) -> 1 | M10: 4 | N10: 3 | O10: 4 | P10: 4 | Q10: 4 | R10: =VLOOKUP(Sheet1!R10,LOOKUPS!$A$39:$B$43,2,FALSE) -> 4 | S10: 3 | T10: =VLOOKUP(Sheet1!T10,LOOKUPS!$A$31:$E$35,2,FALSE) -> 3 | U10: 4 | V10: 4 | W10: Very likely | X10: 197 | Y10: 11–20%
A11: 25–34 | B11: Male | C11: Urban | D11: Employed (salaried) | E11: > ₹100k | F11: Instamart | G11: =VLOOKUP(Sheet1!G11,LOOKUPS!$A$3:$B$9,2,FALSE) -> 6 | H11: =VLOOKUP(Sheet1!H11,LOOKUPS!$A$13:$B$14,2,FALSE) -> 1 | I11: Instamart | J11: =VLOOKUP(Sheet1!J11,LOOKUPS!$A$18:$B$22,2,FALSE) -> 3 | K11: Do nothing, Post on social media, Return item in app | L11: =VLOOKUP(Sheet1!L11,LOOKUPS!$A$26:$B$27,2,FALSE) -> 0 | M11: 3 | N11: 3 | O11: 2 | P11: 2 | Q11: 2 | R11: =VLOOKUP(Sheet1!R11,LOOKUPS!$A$39:$B$43,2,FALSE) -> 2 | S11: 4 | T11: =VLOOKUP(Sheet1!T11,LOOKUPS!$A$31:$E$35,2,FALSE) -> 4 | U11: 3 | V11: 3 | W11: Likely | X11: 143 | Y11: 0%
A12: 18–24 | B12: Male | C12: Urban | D12: Student | E12: ₹40–60k | F12: Blinkit, Local grocery app, None | G12: =VLOOKUP(Sheet1!G12,LOOKUPS!$A$3:$B$9,2,FALSE) -> 2 | H12: =VLOOKUP(Sheet1!H12,LOOKUPS!$A$13:$B$14,2,FALSE) -> 0 | J12: =VLOOKUP(Sheet1!J12,LOOKUPS!$A$18:$B$22,2,FALSE) -> 1 | K12: Do nothing | L12: =VLOOKUP(Sheet1!L12,LOOKUPS!$A$26:$B$27,2,FALSE) -> 1 | M12: 4 | N12: 4 | O12: 4 | P12: 3 | Q12: 3 | R12: =VLOOKUP(Sheet1!R12,LOOKUPS!$A$39:$B$43,2,FALSE) -> 3 | S12: 3 | T12: =VLOOKUP(Sheet1!T12,LOOKUPS!$A$31:$E$35,2,FALSE) -> 2 | U12: 3 | V12: 4 | W12: Very unlikely | X12: 21 | Y12: 11–20%
A13: 25–34 | B13: Female | C13: Sub-urban | D13: Student | E13: ₹40–60k | F13: Instamart, Local grocery app, None | G13: =VLOOKUP(Sheet1!G13,LOOKUPS!$A$3:$B$9,2,FALSE) -> 5 | H13: =VLOOKUP(Sheet1!H13,LOOKUPS!$A$13:$B$14,2,FALSE) -> 1 | I13: Instamart | J13: =VLOOKUP(Sheet1!J13,LOOKUPS!$A$18:$B$22,2,FALSE) -> 1 | K13: Complain to customer support, Return item in app | L13: =VLOOKUP(Sheet1!L13,LOOKUPS!$A$26:$B$27,2,FALSE) -> 0 | M13: 2 | N13: 2 | O13: 2 | P13: 2 | Q13: 2 | R13: =VLOOKUP(Sheet1!R13,LOOKUPS!$A$39:$B$43,2,FALSE) -> 1 | S13: 4 | T13: =VLOOKUP(Sheet1!T13,LOOKUPS!$A$31:$E$35,2,FALSE) -> 3 | U13: 3 | V13: 3 | W13: Unlikely | X13: 59 | Y13: 11–20%
A14: 18–24 | B14: Female | C14: Urban | D14: Employed (salaried) | E14: < ₹20,000 | F14: Local grocery app, None | G14: =VLOOKUP(Sheet1!G14,LOOKUPS!$A$3:$B$9,2,FALSE) -> 5 | H14: =VLOOKUP(Sheet1!H14,LOOKUPS!$A$13:$B$14,2,FALSE) -> 1 | I14: Zepto | J14: =VLOOKUP(Sheet1!J14,LOOKUPS!$A$18:$B$22,2,FALSE) -> 3 | K14: Complain to customer support, Post on social media | L14: =VLOOKUP(Sheet1!L14,LOOKUPS!$A$26:$B$27,2,FALSE) -> 1 | M14: 2 | N14: 3 | O14: 3 | P14: 2 | Q14: 2 | R14: =VLOOKUP(Sheet1!R14,LOOKUPS!$A$39:$B$43,2,FALSE) -> 4 | S14: 4 | T14: =VLOOKUP(Sheet1!T14,LOOKUPS!$A$31:$E$35,2,FALSE) -> 5 | U14: 3 | V14: 3 | W14: Neutral | X14: 18 | Y14: 6–10%
A15: 25–34 | B15: Female | C15: Urban | D15: Employed (salaried) | E15: Prefer not to say | F15: Instamart, None, Zepto | G15: =VLOOKUP(Sheet1!G15,LOOKUPS!$A$3:$B$9,2,FALSE) -> 5 | H15: =VLOOKUP(Sheet1!H15,LOOKUPS!$A$13:$B$14,2,FALSE) -> 0 | J15: =VLOOKUP(Sheet1!J15,LOOKUPS!$A$18:$B$22,2,FALSE) -> 1 | K15: Do nothing | L15: =VLOOKUP(Sheet1!L15,LOOKUPS!$A$26:$B$27,2,FALSE) -> 1 | M15: 4 | N15: 4 | O15: 4 | P15: 4 | Q15: 4 | R15: =VLOOKUP(Sheet1!R15,LOOKUPS!$A$39:$B$43,2,FALSE) -> 5 | S15: 3 | T15: =VLOOKUP(Sheet1!T15,LOOKUPS!$A$31:$E$35,2,FALSE) -> 5 | U15: 5 | V15: 4 | W15: Likely | X15: 208 | Y15: 6–10%
A16: 45–54 | B16: Female | C16: Urban | D16: Student | E16: Prefer not to say | F16: Blinkit, Instamart, Zepto | G16: =VLOOKUP(Sheet1!G16,LOOKUPS!$A$3:$B$9,2,FALSE) -> 5 | H16: =VLOOKUP(Sheet1!H16,LOOKUPS!$A$13:$B$14,2,FALSE) -> 1 | I16: Blinkit | J16: =VLOOKUP(Sheet1!J16,LOOKUPS!$A$18:$B$22,2,FALSE) -> 2 | K16: Complain to friends/family | L16: =VLOOKUP(Sheet1!L16,LOOKUPS!$A$26:$B$27,2,FALSE) -> 1 | M16: 3 | N16: 2 | O16: 3 | P16: 2 | Q16: 3 | R16: =VLOOKUP(Sheet1!R16,LOOKUPS!$A$39:$B$43,2,FALSE) -> 4 | S16: 3 | T16: =VLOOKUP(Sheet1!T16,LOOKUPS!$A$31:$E$35,2,FALSE) -> 2 | U16: 3 | V16: 3 | W16: Very unlikely | X16: 37 | Y16: 11–20%
A17: 18–24 | B17: Prefer not to say | C17: Sub-urban | D17: Employed (salaried) | E17: < ₹20,000 | F17: Blinkit, Local grocery app, Zepto | G17: =VLOOKUP(Sheet1!G17,LOOKUPS!$A$3:$B$9,2,FALSE) -> 3 | H17: =VLOOKUP(Sheet1!H17,LOOKUPS!$A$13:$B$14,2,FALSE) -> 1 | I17: Zepto | J17: =VLOOKUP(Sheet1!J17,LOOKUPS!$A$18:$B$22,2,FALSE) -> 4 | K17: Complain to friends/family | L17: =VLOOKUP(Sheet1!L17,LOOKUPS!$A$26:$B$27,2,FALSE) -> 1 | M17: 2 | N17: 3 | O17: 2 | P17: 2 | Q17: 2 | R17: =VLOOKUP(Sheet1!R17,LOOKUPS!$A$39:$B$43,2,FALSE) -> 2 | S17: 4 | T17: =VLOOKUP(Sheet1!T17,LOOKUPS!$A$31:$E$35,2,FALSE) -> 1 | U17: 3 | V17: 3 | W17: Unlikely | X17: 82 | Y17: 0%
A18: 18–24 | B18: Male | C18: Urban | D18: Employed (salaried) | E18: ₹40–60k | F18: None, Zepto | G18: =VLOOKUP(Sheet1!G18,LOOKUPS!$A$3:$B$9,2,FALSE) -> 6 | H18: =VLOOKUP(Sheet1!H18,LOOKUPS!$A$13:$B$14,2,FALSE) -> 1 | I18: Zepto | J18: =VLOOKUP(Sheet1!J18,LOOKUPS!$A$18:$B$22,2,FALSE) -> 3 | K18: Complain to friends/family, Do nothing | L18: =VLOOKUP(Sheet1!L18,LOOKUPS!$A$26:$B$27,2,FALSE) -> 1 | M18: 3 | N18: 3 | O18: 3 | P18: 2 | Q18: 3 | R18: =VLOOKUP(Sheet1!R18,LOOKUPS!$A$39:$B$43,2,FALSE) -> 5 | S18: 3 | T18: =VLOOKUP(Sheet1!T18,LOOKUPS!$A$31:$E$35,2,FALSE) -> 1 | U18: 3 | V18: 4 | W18: Neutral | X18: 110 | Y18: 0%
A19: 45–54 | B19: Male | C19: Urban | D19: Employed (salaried) | E19: ₹40–60k | F19: Zepto | G19: =VLOOKUP(Sheet1!G19,LOOKUPS!$A$3:$B$9,2,FALSE) -> 5 | H19: =VLOOKUP(Sheet1!H19,LOOKUPS!$A$13:$B$14,2,FALSE) -> 1 | I19: Zepto | J19: =VLOOKUP(Sheet1!J19,LOOKUPS!$A$18:$B$22,2,FALSE) -> 2 | K19: Complain to customer support | L19: =VLOOKUP(Sheet1!L19,LOOKUPS!$A$26:$B$27,2,FALSE) -> 1 | M19: 3 | N19: 3 | O19: 3 | P19: 3 | Q19: 3 | R19: =VLOOKUP(Sheet1!R19,LOOKUPS!$A$39:$B$43,2,FALSE) -> 4 | S19: 3 | T19: =VLOOKUP(Sheet1!T19,LOOKUPS!$A$31:$E$35,2,FALSE) -> 4 | U19: 3 | V19: 3 | W19: Very likely | X19: 137 | Y19: up to 5%
A20: 18–24 | B20: Female | C20: Urban | D20: Employed (salaried) | E20: ₹40–60k | F20: Blinkit, None | G20: =VLOOKUP(Sheet1!G20,LOOKUPS!$A$3:$B$9,2,FALSE) -> 5 | H20: =VLOOKUP(Sheet1!H20,LOOKUPS!$A$13:$B$14,2,FALSE) -> 1 | I20: Blinkit | J20: =VLOOKUP(Sheet1!J20,LOOKUPS!$A$18:$B$22,2,FALSE) -> 3 | K20: Do nothing, Return item in app | L20: =VLOOKUP(Sheet1!L20,LOOKUPS!$A$26:$B$27,2,FALSE) -> 0 | M20: 3 | N20: 3 | O20: 3 | P20: 3 | Q20: 3 | R20: =VLOOKUP(Sheet1!R20,LOOKUPS!$A$39:$B$43,2,FALSE) -> 2 | S20: 3 | T20: =VLOOKUP(Sheet1!T20,LOOKUPS!$A$31:$E$35,2,FALSE) -> 1 | U20: 4 | V20: 3 | W20: Likely | X20: 136 | Y20: up to 5%
A21: 25–34 | B21: Male | C21: Sub-urban | D21: Self-employed | E21: ₹20–40k | F21: Local grocery app | G21: =VLOOKUP(Sheet1!G21,LOOKUPS!$A$3:$B$9,2,FALSE) -> 7 | H21: =VLOOKUP(Sheet1!H21,LOOKUPS!$A$13:$B$14,2,FALSE) -> 1 | I21: Blinkit | J21: =VLOOKUP(Sheet1!J21,LOOKUPS!$A$18:$B$22,2,FALSE) -> 5 | K21: Do nothing | L21: =VLOOKUP(Sheet1!L21,LOOKUPS!$A$26:$B$27,2,FALSE) -> 0 | M21: 2 | N21: 2 | O21: 2 | P21: 2 | Q21: 2 | R21: =VLOOKUP(Sheet1!R21,LOOKUPS!$A$39:$B$43,2,FALSE) -> 4 | S21: 4 | T21: =VLOOKUP(Sheet1!T21,LOOKUPS!$A$31:$E$35,2,FALSE) -> 4 | U21: 2 | V21: 3 | W21: Very unlikely | X21: 24 | Y21: 11–20%
A22: 55+ | B22: Male | C22: Urban | D22: Student | E22: < ₹20,000 | F22: Instamart | G22: =VLOOKUP(Sheet1!G22,LOOKUPS!$A$3:$B$9,2,FALSE) -> 5 | H22: =VLOOKUP(Sheet1!H22,LOOKUPS!$A$13:$B$14,2,FALSE) -> 1 | I22: Instamart | J22: =VLOOKUP(Sheet1!J22,LOOKUPS!$A$18:$B$22,2,FALSE) -> 1 | K22: Do nothing | L22: =VLOOKUP(Sheet1!L22,LOOKUPS!$A$26:$B$27,2,FALSE) -> 1 | M22: 2 | N22: 2 | O22: 3 | P22: 1 | Q22: 2 | R22: =VLOOKUP(Sheet1!R22,LOOKUPS!$A$39:$B$43,2,FALSE) -> 4 | S22: 4 | T22: =VLOOKUP(Sheet1!T22,LOOKUPS!$A$31:$E$35,2,FALSE) -> 2 | U22: 2 | V22: 2 | W22: Unlikely | X22: 54 | Y22: up to 5%
A23: 18–24 | B23: Male | C23: Sub-urban | D23: Student | E23: ₹60–100k | F23: Instamart, None | G23: =VLOOKUP(Sheet1!G23,LOOKUPS!$A$3:$B$9,2,FALSE) -> 5 | H23: =VLOOKUP(Sheet1!H23,LOOKUPS!$A$13:$B$14,2,FALSE) -> 0 | J23: =VLOOKUP(Sheet1!J23,LOOKUPS!$A$18:$B$22,2,FALSE) -> 1 | K23: Do nothing | L23: =VLOOKUP(Sheet1!L23,LOOKUPS!$A$26:$B$27,2,FALSE) -> 0 | M23: 3 | N23: 3 | O23: 3 | P23: 3 | Q23: 3 | R23: =VLOOKUP(Sheet1!R23,LOOKUPS!$A$39:$B$43,2,FALSE) -> 4 | S23: 4 | T23: =VLOOKUP(Sheet1!T23,LOOKUPS!$A$31:$E$35,2,FALSE) -> 1 | U23: 4 | V23: 3 | W23: Neutral | X23: 96 | Y23: up to 5%
A24: 25–34 | B24: Female | C24: Village | D24: Employed (salaried) | E24: ₹20–40k | F24: Instamart, Local grocery app | G24: =VLOOKUP(Sheet1!G24,LOOKUPS!$A$3:$B$9,2,FALSE) -> 1 | H24: =VLOOKUP(Sheet1!H24,LOOKUPS!$A$13:$B$14,2,FALSE) -> 0 | J24: =VLOOKUP(Sheet1!J24,LOOKUPS!$A$18:$B$22,2,FALSE) -> 1 | K24: Do nothing | L24: =VLOOKUP(Sheet1!L24,LOOKUPS!$A$26:$B$27,2,FALSE) -> 0 | M24: 4 | N24: 3 | O24: 4 | P24: 4 | Q24: 4 | R24: =VLOOKUP(Sheet1!R24,LOOKUPS!$A$39:$B$43,2,FALSE) -> 1 | S24: 2 | T24: =VLOOKUP(Sheet1!T24,LOOKUPS!$A$31:$E$35,2,FALSE) -> 4 | U24: 4 | V24: 4 | W24: Unlikely | X24: 35 | Y24: >20%
A25: 18–24 | B25: Non-binary | C25: Urban | D25: Employed (salaried) | E25: < ₹20,000 | F25: Blinkit, Local grocery app | G25: =VLOOKUP(Sheet1!G25,LOOKUPS!$A$3:$B$9,2,FALSE) -> 3 | H25: =VLOOKUP(Sheet1!H25,LOOKUPS!$A$13:$B$14,2,FALSE) -> 1 | I25: Blinkit | J25: =VLOOKUP(Sheet1!J25,LOOKUPS!$A$18:$B$22,2,FALSE) -> 2 | K25: Complain to customer support, Do nothing, Return item in app | L25: =VLOOKUP(Sheet1!L25,LOOKUPS!$A$26:$B$27,2,FALSE) -> 0 | M25: 3 | N25: 3 | O25: 4 | P25: 3 | Q25: 3 | R25: =VLOOKUP(Sheet1!R25,LOOKUPS!$A$39:$B$43,2,FALSE) -> 4 | S25: 3 | T25: =VLOOKUP(Sheet1!T25,LOOKUPS!$A$31:$E$35,2,FALSE) -> 5 | U25: 4 | V25: 3 | W25: Very likely | X25: 127 | Y25: 11–20%
A26: 25–34 | B26: Male | C26: Village | D26: Student | E26: > ₹100k | F26: Blinkit, Local grocery app, None | G26: =VLOOKUP(Sheet1!G26,LOOKUPS!$A$3:$B$9,2,FALSE) -> 2 | H26: =VLOOKUP(Sheet1!H26,LOOKUPS!$A$13:$B$14,2,FALSE) -> 1 | I26: Blinkit | J26: =VLOOKUP(Sheet1!J26,LOOKUPS!$A$18:$B$22,2,FALSE) -> 1 | K26: Complain to friends/family, Do nothing, Return item in app | L26: =VLOOKUP(Sheet1!L26,LOOKUPS!$A$26:$B$27,2,FALSE) -> 0 | M26: 3 | N26: 3 | O26: 4 | P26: 2 | Q26: 3 | R26: =VLOOKUP(Sheet1!R26,LOOKUPS!$A$39:$B$43,2,FALSE) -> 1 | S26: 3 | T26: =VLOOKUP(Sheet1!T26,LOOKUPS!$A$31:$E$35,2,FALSE) -> 4 | U26: 4 | V26: 3 | W26: Likely | X26: 161 | Y26: up to 5%
A27: 25–34 | B27: Male | C27: Urban | D27: Other | E27: ₹60–100k | F27: Blinkit, None, Zepto | G27: =VLOOKUP(Sheet1!G27,LOOKUPS!$A$3:$B$9,2,FALSE) -> 6 | H27: =VLOOKUP(Sheet1!H27,LOOKUPS!$A$13:$B$14,2,FALSE) -> 0 | J27: =VLOOKUP(Sheet1!J27,LOOKUPS!$A$18:$B$22,2,FALSE) -> 1 | K27: Do nothing | L27: =VLOOKUP(Sheet1!L27,LOOKUPS!$A$26:$B$27,2,FALSE) -> 1 | M27: 2 | N27: 3 | O27: 4 | P27: 3 | Q27: 3 | R27: =VLOOKUP(Sheet1!R27,LOOKUPS!$A$39:$B$43,2,FALSE) -> 5 | S27: 3 | T27: =VLOOKUP(Sheet1!T27,LOOKUPS!$A$31:$E$35,2,FALSE) -> 2 | U27: 4 | V27: 4 | W27: Unlikely | X27: 44 | Y27: up to 5%
A28: 18–24 | B28: Prefer not to say | C28: Sub-urban | D28: Self-employed | E28: Prefer not to say | F28: None, Zepto | G28: =VLOOKUP(Sheet1!G28,LOOKUPS!$A$3:$B$9,2,FALSE) -> 7 | H28: =VLOOKUP(Sheet1!H28,LOOKUPS!$A$13:$B$14,2,FALSE) -> 0 | J28: =VLOOKUP(Sheet1!J28,LOOKUPS!$A$18:$B$22,2,FALSE) -> 1 | K28: Do nothing | L28: =VLOOKUP(Sheet1!L28,LOOKUPS!$A$26:$B$27,2,FALSE) -> 1 | M28: 3 | N28: 3 | O28: 4 | P28: 2 | Q28: 3 | R28: =VLOOKUP(Sheet1!R28,LOOKUPS!$A$39:$B$43,2,FALSE) -> 5 | S28: 4 | T28: =VLOOKUP(Sheet1!T28,LOOKUPS!$A$31:$E$35,2,FALSE) -> 5 | U28: 3 | V28: 4 | W28: Likely | X28: 139 | Y28: 0%
A29: 18–24 | B29: Male | C29: Sub-urban | D29: Student | E29: ₹20–40k | F29: Instamart | G29: =VLOOKUP(Sheet1!G29,LOOKUPS!$A$3:$B$9,2,FALSE) -> 7 | H29: =VLOOKUP(Sheet1!H29,LOOKUPS!$A$13:$B$14,2,FALSE) -> 1 | I29: Instamart | J29: =VLOOKUP(Sheet1!J29,LOOKUPS!$A$18:$B$22,2,FALSE) -> 4 | K29: Complain to customer support | L29: =VLOOKUP(Sheet1!L29,LOOKUPS!$A$26:$B$27,2,FALSE) -> 0 | M29: 1 | N29: 2 | O29: 2 | P29: 1 | Q29: 2 | R29: =VLOOKUP(Sheet1!R29,LOOKUPS!$A$39:$B$43,2,FALSE) -> 4 | S29: 5 | T29: =VLOOKUP(Sheet1!T29,LOOKUPS!$A$31:$E$35,2,FALSE) -> 3 | U29: 2 | V29: 3 | W29: Likely | X29: 179 | Y29: 0%
A30: 18–24 | B30: Female | C30: Urban | D30: Student | E30: < ₹20,000 | F30: Zepto | G30: =VLOOKUP(Sheet1!G30,LOOKUPS!$A$3:$B$9,2,FALSE) -> 6 | H30: =VLOOKUP(Sheet1!H30,LOOKUPS!$A$13:$B$14,2,FALSE) -> 1 | I30: Zepto | J30: =VLOOKUP(Sheet1!J30,LOOKUPS!$A$18:$B$22,2,FALSE) -> 1 | K30: Complain to friends/family, Do nothing, Return item in app | L30: =VLOOKUP(Sheet1!L30,LOOKUPS!$A$26:$B$27,2,FALSE) -> 1 | M30: 2 | N30: 2 | O30: 3 | P30: 3 | Q30: 2 | R30: =VLOOKUP(Sheet1!R30,LOOKUPS!$A$39:$B$43,2,FALSE) -> 2 | S30: 4 | T30: =VLOOKUP(Sheet1!T30,LOOKUPS!$A$31:$E$35,2,FALSE) -> 4 | U30: 3 | V30: 2 | W30: Neutral | X30: 161 | Y30: up to 5%
A31: 35–44 | B31: Male | C31: Sub-urban | D31: Employed (salaried) | E31: < ₹20,000 | F31: Blinkit, None | G31: =VLOOKUP(Sheet1!G31,LOOKUPS!$A$3:$B$9,2,FALSE) -> 7 | H31: =VLOOKUP(Sheet1!H31,LOOKUPS!$A$13:$B$14,2,FALSE) -> 1 | I31: Blinkit | J31: =VLOOKUP(Sheet1!J31,LOOKUPS!$A$18:$B$22,2,FALSE) -> 1 | K31: Complain to customer support, Complain to friends/family, Post on social media | L31: =VLOOKUP(Sheet1!L31,LOOKUPS!$A$26:$B$27,2,FALSE) -> 0 | M31: 3 | N31: 4 | O31: 4 | P31: 4 | Q31: 3 | R31: =VLOOKUP(Sheet1!R31,LOOKUPS!$A$39:$B$43,2,FALSE) -> 5 | S31: 2 | T31: =VLOOKUP(Sheet1!T31,LOOKUPS!$A$31:$E$35,2,FALSE) -> 1 | U31: 4 | V31: 4 | W31: Very unlikely | X31: 71 | Y31: 0%
A32: 35–44 | B32: Female | C32: Urban | D32: Employed (salaried) | E32: ₹20–40k | F32: Instamart, Zepto | G32: =VLOOKUP(Sheet1!G32,LOOKUPS!$A$3:$B$9,2,FALSE) -> 4 | H32: =VLOOKUP(Sheet1!H32,LOOKUPS!$A$13:$B$14,2,FALSE) -> 0 | J32: =VLOOKUP(Sheet1!J32,LOOKUPS!$A$18:$B$22,2,FALSE) -> 1 | K32: Do nothing | L32: =VLOOKUP(Sheet1!L32,LOOKUPS!$A$26:$B$27,2,FALSE) -> 1 | M32: 4 | N32: 4 | O32: 4 | P32: 3 | Q32: 3 | R32: =VLOOKUP(Sheet1!R32,LOOKUPS!$A$39:$B$43,2,FALSE) -> 4 | S32: 3 | T32: =VLOOKUP(Sheet1!T32,LOOKUPS!$A$31:$E$35,2,FALSE) -> 3 | U32: 4 | V32: 4 | W32: Unlikely | X32: 17 | Y32: up to 5%
A33: 18–24 | B33: Male | C33: Sub-urban | D33: Student | E33: ₹20–40k | F33: Blinkit, Instamart, Local grocery app | G33: =VLOOKUP(Sheet1!G33,LOOKUPS!$A$3:$B$9,2,FALSE) -> 7 | H33: =VLOOKUP(Sheet1!H33,LOOKUPS!$A$13:$B$14,2,FALSE) -> 0 | J33: =VLOOKUP(Sheet1!J33,LOOKUPS!$A$18:$B$22,2,FALSE) -> 1 | K33: Do nothing | L33: =VLOOKUP(Sheet1!L33,LOOKUPS!$A$26:$B$27,2,FALSE) -> 0 | M33: 4 | N33: 4 | O33: 4 | P33: 4 | Q33: 4 | R33: =VLOOKUP(Sheet1!R33,LOOKUPS!$A$39:$B$43,2,FALSE) -> 4 | S33: 2 | T33: =VLOOKUP(Sheet1!T33,LOOKUPS!$A$31:$E$35,2,FALSE) -> 4 | U33: 5 | V33: 5 | W33: Very likely | X33: 133 | Y33: 11–20%
A34: 25–34 | B34: Male | C34: Urban | D34: Employed (salaried) | E34: < ₹20,000 | F34: Blinkit, Local grocery app, None | G34: =VLOOKUP(Sheet1!G34,LOOKUPS!$A$3:$B$9,2,FALSE) -> 6 | H34: =VLOOKUP(Sheet1!H34,LOOKUPS!$A$13:$B$14,2,FALSE) -> 1 | I34: Blinkit | J34: =VLOOKUP(Sheet1!J34,LOOKUPS!$A$18:$B$22,2,FALSE) -> 3 | K34: Post on social media, Return item in app | L34: =VLOOKUP(Sheet1!L34,LOOKUPS!$A$26:$B$27,2,FALSE) -> 0 | M34: 2 | N34: 3 | O34: 3 | P34: 3 | Q34: 3 | R34: =VLOOKUP(Sheet1!R34,LOOKUPS!$A$39:$B$43,2,FALSE) -> 4 | S34: 3 | T34: =VLOOKUP(Sheet1!T34,LOOKUPS!$A$31:$E$35,2,FALSE) -> 3 | U34: 3 | V34: 3 | W34: Very likely | X34: 146 | Y34: 11–20%
A35: 18–24 | B35: Male | C35: Urban | D35: Student | E35: ₹20–40k | F35: Zepto | G35: =VLOOKUP(Sheet1!G35,LOOKUPS!$A$3:$B$9,2,FALSE) -> 5 | H35: =VLOOKUP(Sheet1!H35,LOOKUPS!$A$13:$B$14,2,FALSE) -> 0 | J35: =VLOOKUP(Sheet1!J35,LOOKUPS!$A$18:$B$22,2,FALSE) -> 1 | K35: Do nothing | L35: =VLOOKUP(Sheet1!L35,LOOKUPS!$A$26:$B$27,2,FALSE) -> 1 | M35: 3 | N35: 3 | O35: 4 | P35: 3 | Q35: 3 | R35: =VLOOKUP(Sheet1!R35,LOOKUPS!$A$39:$B$43,2,FALSE) -> 2 | S35: 3 | T35: =VLOOKUP(Sheet1!T35,LOOKUPS!$A$31:$E$35,2,FALSE) -> 1 | U35: 4 | V35: 4 | W35: Very likely | X35: 160 | Y35: up to 5%
A36: 25–34 | B36: Male | C36: Sub-urban | D36: Employed (salaried) | E36: ₹40–60k | F36: Blinkit | G36: =VLOOKUP(Sheet1!G36,LOOKUPS!$A$3:$B$9,2,FALSE) -> 6 | H36: =VLOOKUP(Sheet1!H36,LOOKUPS!$A$13:$B$14,2,FALSE) -> 0 | J36: =VLOOKUP(Sheet1!J36,LOOKUPS!$A$18:$B$22,2,FALSE) -> 1 | K36: Do nothing | L36: =VLOOKUP(Sheet1!L36,LOOKUPS!$A$26:$B$27,2,FALSE) -> 0 | M36: 3 | N36: 2 | O36: 3 | P36: 3 | Q36: 3 | R36: =VLOOKUP(Sheet1!R36,LOOKUPS!$A$39:$B$43,2,FALSE) -> 4 | S36: 4 | T36: =VLOOKUP(Sheet1!T36,LOOKUPS!$A$31:$E$35,2,FALSE) -> 4 | U36: 3 | V36: 3 | W36: Likely | X36: 105 | Y36: up to 5%
A37: 18–24 | B37: Male | C37: Urban | D37: Employed (salaried) | E37: > ₹100k | F37: Blinkit, Instamart, None | G37: =VLOOKUP(Sheet1!G37,LOOKUPS!$A$3:$B$9,2,FALSE) -> 6 | H37: =VLOOKUP(Sheet1!H37,LOOKUPS!$A$13:$B$14,2,FALSE) -> 1 | I37: Blinkit | J37: =VLOOKUP(Sheet1!J37,LOOKUPS!$A$18:$B$22,2,FALSE) -> 5 | K37: Do nothing | L37: =VLOOKUP(Sheet1!L37,LOOKUPS!$A$26:$B$27,2,FALSE) -> 0 | M37: 3 | N37: 2 | O37: 3 | P37: 2 | Q37: 2 | R37: =VLOOKUP(Sheet1!R37,LOOKUPS!$A$39:$B$43,2,FALSE) -> 5 | S37: 4 | T37: =VLOOKUP(Sheet1!T37,LOOKUPS!$A$31:$E$35,2,FALSE) -> 3 | U37: 3 | V37: 3 | W37: Neutral | X37: 58 | Y37: up to 5%
A38: 18–24 | B38: Male | C38: Village | D38: Student | E38: ₹40–60k | F38: Blinkit, Instamart, None | G38: =VLOOKUP(Sheet1!G38,LOOKUPS!$A$3:$B$9,2,FALSE) -> 1 | H38: =VLOOKUP(Sheet1!H38,LOOKUPS!$A$13:$B$14,2,FALSE) -> 0 | J38: =VLOOKUP(Sheet1!J38,LOOKUPS!$A$18:$B$22,2,FALSE) -> 1 | K38: Do nothing | L38: =VLOOKUP(Sheet1!L38,LOOKUPS!$A$26:$B$27,2,FALSE) -> 0 | M38: 2 | N38: 3 | O38: 2 | P38: 2 | Q38: 3 | R38: =VLOOKUP(Sheet1!R38,LOOKUPS!$A$39:$B$43,2,FALSE) -> 2 | S38: 3 | T38: =VLOOKUP(Sheet1!T38,LOOKUPS!$A$31:$E$35,2,FALSE) -> 2 | U38: 3 | V38: 3 | W38: Very unlikely | X38: 23 | Y38: 6–10%
A39: 18–24 | B39: Prefer not to say | C39: Urban | D39: Student | E39: ₹20–40k | F39: Local grocery app, Zepto | G39: =VLOOKUP(Sheet1!G39,LOOKUPS!$A$3:$B$9,2,FALSE) -> 6 | H39: =VLOOKUP(Sheet1!H39,LOOKUPS!$A$13:$B$14,2,FALSE) -> 0 | J39: =VLOOKUP(Sheet1!J39,LOOKUPS!$A$18:$B$22,2,FALSE) -> 1 | K39: Do nothing | L39: =VLOOKUP(Sheet1!L39,LOOKUPS!$A$26:$B$27,2,FALSE) -> 1 | M39: 3 | N39: 3 | O39: 3 | P39: 2 | Q39: 3 | R39: =VLOOKUP(Sheet1!R39,LOOKUPS!$A$39:$B$43,2,FALSE) -> 1 | S39: 4 | T39: =VLOOKUP(Sheet1!T39,LOOKUPS!$A$31:$E$35,2,FALSE) -> 4 | U39: 4 | V39: 3 | W39: Very likely | X39: 92 | Y39: 11–20%
A40: 25–34 | B40: Prefer not to say | C40: Urban | D40: Employed (salaried) | E40: ₹20–40k | F40: Blinkit, Instamart, Local grocery app | G40: =VLOOKUP(Sheet1!G40,LOOKUPS!$A$3:$B$9,2,FALSE) -> 5 | H40: =VLOOKUP(Sheet1!H40,LOOKUPS!$A$13:$B$14,2,FALSE) -> 0 | J40: =VLOOKUP(Sheet1!J40,LOOKUPS!$A$18:$B$22,2,FALSE) -> 1 | K40: Do nothing | L40: =VLOOKUP(Sheet1!L40,LOOKUPS!$A$26:$B$27,2,FALSE) -> 0 | M40: 4 | N40: 3 | O40: 4 | P40: 3 | Q40: 4 | R40: =VLOOKUP(Sheet1!R40,LOOKUPS!$A$39:$B$43,2,FALSE) -> 5 | S40: 3 | T40: =VLOOKUP(Sheet1!T40,LOOKUPS!$A$31:$E$35,2,FALSE) -> 3 | U40: 4 | V40: 4 | W40: Very likely | X40: 99 | Y40: up to 5%
...

Sheet ANNOVA RESULTS
A1: ANNOVA TESTS
A3: DEPENDENT VARIABLE | B3: Q13
A4: INDEPENDENT VARIABLE | B4: Q14 TO Q20
A7: QUESTION 14 TEST | K7: QUESTION 18
A9: Anova: Single Factor | K9: Anova: Single Factor
A11: SUMMARY | K11: SUMMARY
A12: Groups | B12: Count | C12: Sum | D12: Average | E12: Variance | K12: Groups | L12: Count | M12: Sum | N12: Average | O12: Variance
A13: 1 | B13: 4 | C13: 7 | D13: 1.75 | E13: 0.25 | K13: 1 | L13: 13 | M13: 37 | N13: 2.8461538 | O13: 0.64102564
A14: 2 | B14: 26 | C14: 58 | D14: 2.2307692 | E14: 0.26461538 | K14: 2 | L14: 22 | M14: 56 | N14: 2.5454545 | O14: 0.25974026
A15: 3 | B15: 83 | C15: 235 | D15: 2.8313253 | E15: 0.33705554 | K15: 3 | L15: 23 | M15: 64 | N15: 2.7826087 | O15: 0.54150198
A16: 4 | B16: 34 | C16: 127 | D16: 3.7352941 | E16: 0.38235294 | K16: 4 | L16: 50 | M16: 156 | N16: 3.12 | O16: 0.92408163
A17: 5 | B17: 3 | C17: 13 | D17: 4.3333333 | E17: 0.33333333 | K17: 5 | L17: 42 | M17: 127 | N17: 3.0238095 | O17: 0.46283391
A20: ANOVA | K20: ANOVA
A21: Source of Variation | B21: SS | C21: df | D21: MS | E21: F | F21: P-value | G21: F crit | K21: Source of Variation | L21: SS | M21: df | N21: MS | O21: F | P21: P-value | Q21: F crit
A22: Between Groups | B22: 47.045081 | C22: 4 | D22: 11.76127 | E22: 35.316751 | F22: 1.4087739e-20 | G22: 2.4340651 | K22: Between Groups | L22: 6.0172462 | M22: 4 | N22: 1.5043116 | O22: 2.4421712 | P22: 0.049372242 | Q22: 2.4340651
A23: Within Groups | B23: 48.288253 | C23: 145 | D23: 0.33302243 | K23: Within Groups | L23: 89.316087 | M23: 145 | N23: 0.61597301
A25: Total | B25: 95.333333 | C25: 149 | K25: Total | L25: 95.333333 | M25: 149
A27: QUESTION 15 | K27: QUESTION 19
A29: Anova: Single Factor | K29: Anova: Single Factor
A31: SUMMARY | K31: SUMMARY
A32: Groups | B32: Count | C32: Sum | D32: Average | E32: Variance | K32: Groups | L32: Count | M32: Sum | N32: Average | O32: Variance
A33: 2 | B33: 19 | C33: 40 | D33: 2.1052632 | E33: 0.32163743 | K33: 1 | L33: 1 | M33: 4 | N33: 4 | O33: #DIV/0!
A34: 3 | B34: 65 | C34: 170 | D34: 2.6153846 | E34: 0.27163462 | K34: 2 | L34: 25 | M34: 93 | N34: 3.72 | O34: 0.54333333
A35: 4 | B35: 57 | C35: 190 | D35: 3.3333333 | E35: 0.36904762 | K35: 3 | L35: 78 | M35: 238 | N35: 3.0512821 | O35: 0.41292041
A36: 5 | B36: 9 | C36: 40 | D36: 4.4444444 | E36: 0.27777778 | K36: 4 | L36: 42 | M36: 99 | N36: 2.3571429 | O36: 0.23519164
K37: 5 | L37: 4 | M37: 6 | N37: 1.5 | O37: 0.33333333
A39: ANOVA
A40: Source of Variation | B40: SS | C40: df | D40: MS | E40: F | F40: P-value | G40: F crit | K40: ANOVA
A41: Between Groups | B41: 49.270355 | C41: 3 | D41: 16.423452 | E41: 52.05534 | F41: 6.1031477e-23 | G41: 2.6665742 | K41: Source of Variation | L41: SS | M41: df | N41: MS | O41: F | P41: P-value | Q41: F crit
A42: Within Groups | B42: 46.062978 | C42: 146 | D42: 0.31549985 | K42: Between Groups | L42: 39.855604 | M42: 4 | N42: 9.9639011 | O42: 26.042264 | P42: 2.8121424e-16 | Q42: 2.4340651
K43: Within Groups | L43: 55.477729 | M43: 145 | N43: 0.38260503
A44: Total | B44: 95.333333 | C44: 149
K45: Total | L45: 95.333333 | M45: 149
A46: QUESTION 16
K47: QUESTION 20
A48: Anova: Single Factor
K49: Anova: Single Factor
A50: SUMMARY
A51: Groups | B51: Count | C51: Sum | D51: Average | E51: Variance | K51: SUMMARY
A52: 1 | B52: 4 | C52: 6 | D52: 1.5 | E52: 0.33333333 | K52: Groups | L52: Count | M52: Sum | N52: Average | O52: Variance
...

Sheet PROJECT X
A1: VARIABLES USED FOR ANOVA
A2: Role | B2: Question | C2: Meaning
A3: Usage Filter | B3: Q12 | C3: Used Zepto (Yes = 1)
A4: Dependent Variable | B4: Q13 | C4: Trust in freshness
A5: Grouping Variable 2 | B5: Q14 | C5: Satisfaction with quality
A6: Grouping Variable 3 | B6: Q15 | C6: Reorder influence
A7: Grouping Variable 3 | B7: Q16 | C7: Reliable quality controls
A8: Grouping Variable 4 | B8: Q17 | C8: Price fairness
A9: Grouping Variable 3 | B9: Q18 | C9: Continuation of using Zepto
A10: Churn Indicator | B10: Q19 | C10: Switching behavior
A11: Grouping Variable 1 | B11: Q20 | C11: Recommendation (Sad reviews proxy)
A14: 1. OVERALL HYPOTHESIS
A16: (Tests whether all IVs together influence trust)
A18: Null Hypothesis (H₀ – Overall):
A20: Customer perceptions measured through Q14–Q20 do not have any significant effect on trust in Zepto’s ability to deliver fresh perishable items (Q13). | B20: Theme likh do
A21: In statistical terms:
A24: Alternative Hypothesis (H₁ – Overall):
A26: At least one perception factor among Q14–Q20 significantly affects trust in Zepto’s ability to deliver fresh perishable items (Q13).
A27: In statistical terms:
A31: INDIVIDUAL HYPOTHESES (ONE PER VARIABLE)
A33: Q14 → Q13
A35: H₀: Q14 has no significant effect on trust in freshness (Q13). | B35: theme likh do in every one
A36: H₁: Q14 has a significant effect on trust in freshness (Q13).
A40: Q15 → Q13
A42: H₀: Q15 has no significant effect on trust in freshness (Q13).
A43: H₁: Q15 has a significant effect on trust in freshness (Q13).
A47: Q16 → Q13
A49: H₀: Q16 has no significant effect on trust in freshness (Q13).
A50: H₁: Q16 has a significant effect on trust in freshness (Q13).
A54: Q17 → Q13
A56: H₀: Q17 has no significant effect on trust in freshness (Q13).
A57: H₁: Q17 has a significant effect on trust in freshness (Q13).
A61: Q18 → Q13
A63: H₀: Q18 has no significant effect on trust in freshness (Q13).
... A78: H₁: Q20 has a significant effect on trust in freshness (Q13).

Sheet ANNOVA_Q14
A1: Group | B1: 1 | C1: 2 | D1: 3 | E1: 4 | F1: 5
B2: {=_xlfn._xlws.FILTER('QUANTIFIED RESPONSES'!$M:$M,'QUANTIFIED RESPONSES'!$N:$N=1,"")} -> 2 | C2: {=_xlfn._xlws.FILTER('QUANTIFIED RESPONSES'!$M:$M,'QUANTIFIED RESPONSES'!$N:$N=2,"")} -> 2 | D2: {=_xlfn._xlws.FILTER('QUANTIFIED RESPONSES'!$M:$M,'QUANTIFIED RESPONSES'!$N:$N=3,"")} -> 2 | E2: {=_xlfn._xlws.FILTER('QUANTIFIED RESPONSES'!$M:$M,'QUANTIFIED RESPONSES'!$N:$N=4,"")} -> 4 | F2: {=_xlfn._xlws.FILTER('QUANTIFIED RESPONSES'!$M:$M,'QUANTIFIED RESPONSES'!$N:$N=5,"")} -> 4
B3: 2 | C3: 2 | D3: 3 | E3: 4 | F3: 4 | H3: Anova: Single Factor
B4: 1 | C4: 3 | D4: 4 | E4: 4 | F4: 5
B5: 2 | C5: 2 | D5: 3 | E5: 4 | H5: SUMMARY
C6: 2 | D6: 3 | E6: 3 | H6: Groups | I6: Count | J6: Sum | K6: Average | L6: Variance
C7: 1 | D7: 4 | E7: 4 | H7: 1 | I7: 4 | J7: 7 | K7: 1.75 | L7: 0.25
C8: 2 | D8: 3 | E8: 4 | H8: 2 | I8: 26 | J8: 58 | K8: 2.2307692 | L8: 0.26461538
C9: 3 | D9: 2 | E9: 3 | H9: 3 | I9: 83 | J9: 235 | K9: 2.8313253 | L9: 0.33705554
C10: 3 | D10: 2 | E10: 5 | H10: 4 | I10: 34 | J10: 127 | K10: 3.7352941 | L10: 0.38235294
C11: 2 | D11: 3 | E11: 4 | H11: 5 | I11: 3 | J11: 13 | K11: 4.3333333 | L11: 0.33333333
C12: 3 | D12: 3 | E12: 3
C13: 3 | D13: 3 | E13: 4
C14: 3 | D14: 3 | E14: 4 | H14: ANOVA
C15: 2 | D15: 4 | E15: 3 | H15: Source of Variation | I15: SS | J15: df | K15: MS | L15: F | M15: P-value | N15: F crit
C16: 2 | D16: 3 | E16: 4 | H16: Between Groups | I16: 47.045081 | J16: 4 | K16: 11.76127 | L16: 35.316751 | M16: 1.4087739e-20 | N16: 2.4340651
C17: 2 | D17: 3 | E17: 3 | H17: Within Groups | I17: 48.288253 | J17: 145 | K17: 0.33302243
C18: 2 | D18: 2 | E18: 3
C19: 2 | D19: 3 | E19: 4 | H19: Total | I19: 95.333333 | J19: 149
C20: 2 | D20: 2 | E20: 3
C21: 2 | D21: 3 | E21: 3
C22: 2 | D22: 2 | E22: 4
C23: 2 | D23: 3 | E23: 4
C24: 2 | D24: 4 | E24: 4
C25: 2 | D25: 3 | E25: 5
C26: 2 | D26: 3 | E26: 3
C27: 3 | D27: 3 | E27: 3
D28: 3 | E28: 4
D29: 3 | E29: 4
D30: 4 | E30: 4
D31: 2 | E31: 5
D32: 2 | E32: 3
D33: 3 | E33: 4
D34: 3 | E34: 4
D35: 3 | E35: 3
D36: 2
D37: 2
D38: 3
D39: 3
D40: 3
...

Sheet ANNOVA_Q15
A1: Group | B1: 1 | C1: 2 | D1: 3 | E1: 4 | F1: 5
B2: {=_xlfn._xlws.FILTER('QUANTIFIED RESPONSES'!$M:$M,'QUANTIFIED RESPONSES'!$O:$O=1,"")} | C2: {=_xlfn._xlws.FILTER('QUANTIFIED RESPONSES'!$M:$M,'QUANTIFIED RESPONSES'!$O:$O=2,"")} -> 2 | D2: {=_xlfn._xlws.FILTER('QUANTIFIED RESPONSES'!$M:$M,'QUANTIFIED RESPONSES'!$O:$O=3,"")} -> 2 | E2: {=_xlfn._xlws.FILTER('QUANTIFIED RESPONSES'!$M:$M,'QUANTIFIED RESPONSES'!$O:$O=4,"")} -> 4 | F2: {=_xlfn._xlws.FILTER('QUANTIFIED RESPONSES'!$M:$M,'QUANTIFIED RESPONSES'!$O:$O=5,"")} -> 4
C3: 3 | D3: 3 | E3: 4 | F3: 5 | H3: Anova: Single Factor
C4: 2 | D4: 2 | E4: 4 | F4: 4
C5: 2 | D5: 3 | E5: 3 | F5: 4 | H5: SUMMARY
C6: 2 | D6: 3 | E6: 3 | F6: 4 | H6: Groups | I6: Count | J6: Sum | K6: Average | L6: Variance
C7: 1 | D7: 3 | E7: 4 | F7: 4 | H7: 2 | I7: 19 | J7: 40 | K7: 2.1052632 | L7: 0.32163743
C8: 2 | D8: 3 | E8: 4 | F8: 5 | H8: 3 | I8: 65 | J8: 170 | K8: 2.6153846 | L8: 0.27163462
C9: 2 | D9: 2 | E9: 4 | F9: 5 | H9: 4 | I9: 57 | J9: 190 | K9: 3.3333333 | L9: 0.36904762
C10: 3 | D10: 3 | E10: 4 | F10: 5 | H10: 5 | I10: 9 | J10: 40 | K10: 4.4444444 | L10: 0.27777778
C11: 2 | D11: 2 | E11: 3
C12: 2 | D12: 2 | E12: 3
C13: 3 | D13: 3 | E13: 2 | H13: ANOVA
C14: 2 | D14: 3 | E14: 3 | H14: Source of Variation | I14: SS | J14: df | K14: MS | L14: F | M14: P-value | N14: F crit
C15: 2 | D15: 3 | E15: 3 | H15: Between Groups | I15: 49.270355 | J15: 3 | K15: 16.423452 | L15: 52.05534 | M15: 6.1031477e-23 | N15: 2.6665742
C16: 1 | D16: 3 | E16: 4 | H16: Within Groups | I16: 46.062978 | J16: 146 | K16: 0.31549985
C17: 2 | D17: 2 | E17: 4
C18: 2 | D18: 3 | E18: 3 | H18: Total | I18: 95.333333 | J18: 149
C19: 3 | D19: 3 | E19: 4
C20: 2 | D20: 3 | E20: 4
D21: 3 | E21: 3
D22: 3 | E22: 3
D23: 3 | E23: 3
D24: 2 | E24: 3
D25: 2 | E25: 3
D26: 2 | E26: 3
D27: 3 | E27: 3
D28: 2 | E28: 3
D29: 2 | E29: 4
D30: 3 | E30: 3
D31: 3 | E31: 3
D32: 4 | E32: 3
... D58: 3 | E58: 3
D59: 3
D60: 3
D61: 3
D62: 2
D63: 3
D64: 2
D65: 3
...

Sheet ANNOVA_Q16
A1: Group | B1: 1 | C1: 2 | D1: 3 | E1: 4 | F1: 5
B2: {=_xlfn._xlws.FILTER('QUANTIFIED RESPONSES'!$M:$M,'QUANTIFIED RESPONSES'!$P:$P=1,"")} -> 2 | C2: {=_xlfn._xlws.FILTER('QUANTIFIED RESPONSES'!$M:$M,'QUANTIFIED RESPONSES'!$P:$P=2,"")} -> 2 | D2: {=_xlfn._xlws.FILTER('QUANTIFIED RESPONSES'!$M:$M,'QUANTIFIED RESPONSES'!$P:$P=3,"")} -> 2 | E2: {=_xlfn._xlws.FILTER('QUANTIFIED RESPONSES'!$M:$M,'QUANTIFIED RESPONSES'!$P:$P=4,"")} -> 4 | F2: {=_xlfn._xlws.FILTER('QUANTIFIED RESPONSES'!$M:$M,'QUANTIFIED RESPONSES'!$P:$P=5,"")} -> 4
B3: 1 | C3: 3 | D3: 3 | E3: 4 | F3: 4 | H3: Anova: Single Factor
B4: 2 | C4: 2 | D4: 4 | E4: 3 | F4: 5
B5: 1 | C5: 2 | D5: 3 | E5: 4 | H5: SUMMARY
C6: 3 | D6: 4 | E6: 4 | H6: Groups | I6: Count | J6: Sum | K6: Average | L6: Variance
C7: 2 | D7: 3 | E7: 4 | H7: 1 | I7: 4 | J7: 6 | K7: 1.5 | L7: 0.33333333
C8: 3 | D8: 3 | E8: 3 | H8: 2 | I8: 44 | J8: 107 | K8: 2.4318182 | L8: 0.25105708
C9: 2 | D9: 3 | E9: 4 | H9: 3 | I9: 68 | J9: 200 | K9: 2.9411765 | L9: 0.38454785
C10: 3 | D10: 3 | E10: 3 | H10: 4 | I10: 31 | J10: 114 | K10: 3.6774194 | L10: 0.49247312
C11: 3 | D11: 2 | E11: 4 | H11: 5 | I11: 3 | J11: 13 | K11: 4.3333333 | L11: 0.33333333
C12: 3 | D12: 2 | E12: 5
C13: 2 | D13: 4 | E13: 4
C14: 3 | D14: 2 | E14: 3 | H14: ANOVA
C15: 2 | D15: 3 | E15: 3 | H15: Source of Variation | I15: SS | J15: df | K15: MS | L15: F | M15: P-value | N15: F crit
C16: 3 | D16: 3 | E16: 4 | H16: Between Groups | I16: 42.332313 | J16: 4 | K16: 10.583078 | L16: 28.953147 | M16: 1.0874533e-17 | N16: 2.4340651
C17: 2 | D17: 4 | E17: 3 | H17: Within Groups | I17: 53.001021 | J17: 145 | K17: 0.36552428
C18: 3 | D18: 3 | E18: 4
C19: 3 | D19: 3 | E19: 3 | H19: Total | I19: 95.333333 | J19: 149
C20: 3 | D20: 3 | E20: 4
C21: 2 | D21: 2 | E21: 3
C22: 2 | D22: 2 | E22: 2
C23: 3 | D23: 2 | E23: 3
C24: 2 | D24: 3 | E24: 4
C25: 2 | D25: 4 | E25: 3
C26: 3 | D26: 3 | E26: 4
C27: 2 | D27: 3 | E27: 4
C28: 3 | D28: 4 | E28: 5
C29: 2 | D29: 3 | E29: 3
C30: 2 | D30: 3 | E30: 4
C31: 3 | D31: 3 | E31: 4
C32: 2 | D32: 3 | E32: 5
C33: 2 | D33: 3
C34: 2 | D34: 3
C35: 2 | D35: 3
C36: 2 | D36: 3
C37: 2 | D37: 2
C38: 2 | D38: 2
C39: 3 | D39: 3
C40: 2 | D40: 4
...

Sheet ANNOVA_Q17
A1: Group | B1: 1 | C1: 2 | D1: 3 | E1: 4 | F1: 5
B2: {=_xlfn._xlws.FILTER('QUANTIFIED RESPONSES'!$M:$M,'QUANTIFIED RESPONSES'!$Q:$Q=1,"")} -> 2 | C2: {=_xlfn._xlws.FILTER('QUANTIFIED RESPONSES'!$M:$M,'QUANTIFIED RESPONSES'!$Q:$Q=2,"")} -> 2 | D2: {=_xlfn._xlws.FILTER('QUANTIFIED RESPONSES'!$M:$M,'QUANTIFIED RESPONSES'!$Q:$Q=3,"")} -> 3 | E2: {=_xlfn._xlws.FILTER('QUANTIFIED RESPONSES'!$M:$M,'QUANTIFIED RESPONSES'!$Q:$Q=4,"")} -> 4 | F2: {=_xlfn._xlws.FILTER('QUANTIFIED RESPONSES'!$M:$M,'QUANTIFIED RESPONSES'!$Q:$Q=5,"")} -> 4
B3: 2 | C3: 2 | D3: 4 | E3: 4 | F3: 5 | H3: Anova: Single Factor
B4: 2 | C4: 3 | D4: 3 | E4: 4 | F4: 5
B5: 1 | C5: 2 | D5: 3 | E5: 4 | H5: SUMMARY
C6: 2 | D6: 4 | E6: 4 | H6: Groups | I6: Count | J6: Sum | K6: Average | L6: Variance
C7: 2 | D7: 3 | E7: 4 | H7: 1 | I7: 4 | J7: 7 | K7: 1.75 | L7: 0.25
C8: 2 | D8: 3 | E8: 4 | H8: 2 | I8: 42 | J8: 98 | K8: 2.3333333 | L8: 0.27642276
C9: 2 | D9: 3 | E9: 5 | H9: 3 | I9: 72 | J9: 208 | K9: 2.8888889 | L9: 0.26917058
C10: 1 | D10: 3 | E10: 4 | H10: 4 | I10: 29 | J10: 113 | K10: 3.8965517 | L10: 0.23891626
C11: 2 | D11: 3 | E11: 4 | H11: 5 | I11: 3 | J11: 14 | K11: 4.6666667 | L11: 0.33333333
C12: 3 | D12: 3 | E12: 4
C13: 3 | D13: 3 | E13: 3
C14: 2 | D14: 2 | E14: 4 | H14: ANOVA
C15: 3 | D15: 3 | E15: 3 | H15: Source of Variation | I15: SS | J15: df | K15: MS | L15: F | M15: P-value | N15: F crit
C16: 3 | D16: 3 | E16: 4 | H16: Between Groups | I16: 56.782567 | J16: 4 | K16: 14.195642 | L16: 53.3937 | M16: 1.3721383e-27 | N16: 2.4340651
C17: 3 | D17: 4 | E17: 4 | H17: Within Groups | I17: 38.550766 | J17: 145 | K17: 0.26586735
C18: 2 | D18: 2 | E18: 3
C19: 2 | D19: 3 | E19: 4 | H19: Total | I19: 95.333333 | J19: 149
C20: 2 | D20: 3 | E20: 4
C21: 3 | D21: 2 | E21: 3
C22: 3 | D22: 3 | E22: 4
C23: 2 | D23: 3 | E23: 4
C24: 3 | D24: 3 | E24: 4
C25: 3 | D25: 3 | E25: 4
C26: 3 | D26: 3 | E26: 4
C27: 2 | D27: 3 | E27: 5
C28: 2 | D28: 3 | E28: 3
C29: 2 | D29: 2 | E29: 4
C30: 2 | D30: 2 | E30: 4
C31: 2 | D31: 2
C32: 2 | D32: 3
C33: 2 | D33: 3
C34: 2 | D34: 2
C35: 2 | D35: 3
C36: 2 | D36: 3
C37: 3 | D37: 3
C38: 2 | D38: 3
C39: 3 | D39: 3
C40: 3 | D40: 3
...

Sheet ANNOVA_Q18
A1: Group | B1: 1 | C1: 2 | D1: 3 | E1: 4 | F1: 5
B2: {=_xlfn._xlws.FILTER('QUANTIFIED RESPONSES'!$M:$M,'QUANTIFIED RESPONSES'!$R:$R=1,"")} -> 2 | C2: {=_xlfn._xlws.FILTER('QUANTIFIED RESPONSES'!$M:$M,'QUANTIFIED RESPONSES'!$R:$R=2,"")} -> 2 | D2: {=_xlfn._xlws.FILTER('QUANTIFIED RESPONSES'!$M:$M,'QUANTIFIED RESPONSES'!$R:$R=3,"")} -> 4 | E2: {=_xlfn._xlws.FILTER('QUANTIFIED RESPONSES'!$M:$M,'QUANTIFIED RESPONSES'!$R:$R=4,"")} -> 4 | F2: {=_xlfn._xlws.FILTER('QUANTIFIED RESPONSES'!$M:$M,'QUANTIFIED RESPONSES'!$R:$R=5,"")} -> 3
B3: 2 | C3: 3 | D3: 4 | E3: 4 | F3: 4 | H3: Anova: Single Factor
B4: 4 | C4: 3 | D4: 3 | E4: 4 | F4: 3
B5: 3 | C5: 2 | D5: 2 | E5: 2 | F5: 4 | H5: SUMMARY
B6: 3 | C6: 3 | D6: 3 | E6: 3 | F6: 3 | H6: Groups | I6: Count | J6: Sum | K6: Average | L6: Variance
B7: 2 | C7: 2 | D7: 2 | E7: 3 | F7: 2 | H7: 1 | I7: 13 | J7: 37 | K7: 2.8461538 | L7: 0.64102564
B8: 2 | C8: 3 | D8: 3 | E8: 2 | F8: 3 | H8: 2 | I8: 22 | J8: 56 | K8: 2.5454545 | L8: 0.25974026
B9: 3 | C9: 2 | D9: 2 | E9: 2 | F9: 3 | H9: 3 | I9: 23 | J9: 64 | K9: 2.7826087 | L9: 0.54150198
B10: 2 | C10: 2 | D10: 3 | E10: 3 | F10: 3 | H10: 4 | I10: 50 | J10: 156 | K10: 3.12 | L10: 0.92408163
B11: 4 | C11: 3 | D11: 3 | E11: 3 | F11: 4 | H11: 5 | I11: 42 | J11: 127 | K11: 3.0238095 | L11: 0.46283391
B12: 3 | C12: 2 | D12: 2 | E12: 1 | F12: 3
B13: 4 | C13: 2 | D13: 3 | E13: 4 | F13: 4
B14: 3 | C14: 2 | D14: 2 | E14: 4 | F14: 3 | H14: ANOVA
C15: 2 | D15: 2 | E15: 2 | F15: 3 | H15: Source of Variation | I15: SS | J15: df | K15: MS | L15: F | M15: P-value | N15: F crit
C16: 3 | D16: 2 | E16: 3 | F16: 2 | H16: Between Groups | I16: 6.0172462 | J16: 4 | K16: 1.5043116 | L16: 2.4421712 | M16: 0.049372242 | N16: 2.4340651
C17: 3 | D17: 2 | E17: 5 | F17: 4 | H17: Within Groups | I17: 89.316087 | J17: 145 | K17: 0.61597301
C18: 2 | D18: 4 | E18: 3 | F18: 3
C19: 3 | D19: 3 | E19: 3 | F19: 3 | H19: Total | I19: 95.333333 | J19: 149
C20: 3 | D20: 2 | E20: 3 | F20: 2
C21: 3 | D21: 3 | E21: 3 | F21: 3
C22: 3 | D22: 3 | E22: 3 | F22: 3
C23: 3 | D23: 4 | E23: 4 | F23: 4
D24: 3 | E24: 2 | F24: 3
E25: 3 | F25: 2
E26: 2 | F26: 3
E27: 4 | F27: 2
E28: 3 | F28: 4
E29: 3 | F29: 3
E30: 3 | F30: 3
E31: 3 | F31: 3
E32: 2 | F32: 2
E33: 2 | F33: 2
E34: 3 | F34: 3
E35: 3 | F35: 4
E36: 4 | F36: 4
... E43: 4 | F43: 2
E44: 5
E45: 3
E46: 2
...

Sheet ANNOVA_Q19
A1: Group | B1: 1 | C1: 2 | D1: 3 | E1: 4 | F1: 5
B2: {=_xlfn._xlws.FILTER('QUANTIFIED RESPONSES'!$M:$M,'QUANTIFIED RESPONSES'!$S:$S=1,"")} -> 4 | C2: {=_xlfn._xlws.FILTER('QUANTIFIED RESPONSES'!$M:$M,'QUANTIFIED RESPONSES'!$S:$S=2,"")} -> 4 | D2: {=_xlfn._xlws.FILTER('QUANTIFIED RESPONSES'!$M:$M,'QUANTIFIED RESPONSES'!$S:$S=3,"")} -> 2 | E2: {=_xlfn._xlws.FILTER('QUANTIFIED RESPONSES'!$M:$M,'QUANTIFIED RESPONSES'!$S:$S=4,"")} -> 2 | F2: {=_xlfn._xlws.FILTER('QUANTIFIED RESPONSES'!$M:$M,'QUANTIFIED RESPONSES'!$S:$S=5,"")} -> 1
C3: 3 | D3: 4 | E3: 3 | F3: 2 | H3: Anova: Single Factor
C4: 4 | D4: 3 | E4: 2 | F4: 1
C5: 4 | D5: 3 | E5: 2 | F5: 2 | H5: SUMMARY
C6: 3 | D6: 4 | E6: 2 | H6: Groups | I6: Count | J6: Sum | K6: Average | L6: Variance
C7: 4 | D7: 4 | E7: 2 | H7: 1 | I7: 1 | J7: 4 | K7: 4 | L7: #DIV/0!
C8: 4 | D8: 4 | E8: 2 | H8: 2 | I8: 25 | J8: 93 | K8: 3.72 | L8: 0.54333333
C9: 3 | D9: 3 | E9: 3 | H9: 3 | I9: 78 | J9: 238 | K9: 3.0512821 | L9: 0.41292041
C10: 3 | D10: 3 | E10: 3 | H10: 4 | I10: 42 | J10: 99 | K10: 2.3571429 | L10: 0.23519164
C11: 4 | D11: 3 | E11: 2 | H11: 5 | I11: 4 | J11: 6 | K11: 1.5 | L11: 0.33333333
C12: 4 | D12: 3 | E12: 3
C13: 3 | D13: 3 | E13: 3
C14: 3 | D14: 3 | E14: 3 | H14: ANOVA
C15: 3 | D15: 2 | E15: 2 | H15: Source of Variation | I15: SS | J15: df | K15: MS | L15: F | M15: P-value | N15: F crit
C16: 3 | D16: 4 | E16: 3 | H16: Between Groups | I16: 39.855604 | J16: 4 | K16: 9.9639011 | L16: 26.042264 | M16: 2.8121424e-16 | N16: 2.4340651
C17: 2 | D17: 2 | E17: 3 | H17: Within Groups | I17: 55.477729 | J17: 145 | K17: 0.38260503
C18: 4 | D18: 3 | E18: 3
C19: 4 | D19: 2 | E19: 2 | H19: Total | I19: 95.333333 | J19: 149
C20: 4 | D20: 4 | E20: 2
C21: 5 | D21: 3 | E21: 2
C22: 4 | D22: 5 | E22: 2
C23: 5 | D23: 3 | E23: 2
C24: 4 | D24: 3 | E24: 3
C25: 4 | D25: 3 | E25: 2
C26: 5 | D26: 3 | E26: 3
D27: 4 | E27: 2
D28: 2 | E28: 2
D29: 3 | E29: 2
D30: 3 | E30: 3
D31: 3 | E31: 2
D32: 2 | E32: 2
D33: 3 | E33: 2
D34: 3 | E34: 2
D35: 3 | E35: 2
D36: 3 | E36: 2
D37: 3 | E37: 2
D38: 3 | E38: 2
... D43: 4 | E43: 3
D44: 3
...

Sheet ANNOVA_Q20
A1: Group | B1: 1 | C1: 2 | D1: 3 | E1: 4 | F1: 5
B2: {=_xlfn._xlws.FILTER('QUANTIFIED RESPONSES'!$M:$M,'QUANTIFIED RESPONSES'!$T:$T=1,"")} -> 2 | C2: {=_xlfn._xlws.FILTER('QUANTIFIED RESPONSES'!$M:$M,'QUANTIFIED RESPONSES'!$T:$T=2,"")} -> 2 | D2: {=_xlfn._xlws.FILTER('QUANTIFIED RESPONSES'!$M:$M,'QUANTIFIED RESPONSES'!$T:$T=3,"")} -> 2 | E2: {=_xlfn._xlws.FILTER('QUANTIFIED RESPONSES'!$M:$M,'QUANTIFIED RESPONSES'!$T:$T=4,"")} -> 3 | F2: {=_xlfn._xlws.FILTER('QUANTIFIED RESPONSES'!$M:$M,'QUANTIFIED RESPONSES'!$T:$T=5,"")} -> 4
B3: 3 | C3: 4 | D3: 4 | E3: 3 | F3: 2 | H3: Anova: Single Factor
B4: 3 | C4: 3 | D4: 4 | E4: 3 | F4: 4
B5: 3 | C5: 4 | D5: 2 | E5: 3 | F5: 3 | H5: SUMMARY
B6: 3 | C6: 3 | D6: 1 | E6: 2 | F6: 3 | H6: Groups | I6: Count | J6: Sum | K6: Average | L6: Variance
B7: 3 | C7: 2 | D7: 4 | E7: 4 | F7: 4 | H7: 1 | I7: 18 | J7: 48 | K7: 2.6666667 | L7: 0.23529412
B8: 3 | C8: 2 | D8: 2 | E8: 3 | F8: 3 | H8: 2 | I8: 31 | J8: 84 | K8: 2.7096774 | L8: 0.34623656
B9: 3 | C9: 2 | D9: 3 | E9: 2 | F9: 3 | H9: 3 | I9: 34 | J9: 95 | K9: 2.7941176 | L9: 1.0775401
B10: 2 | C10: 3 | D10: 4 | E10: 4 | F10: 2 | H10: 4 | I10: 39 | J10: 117 | K10: 3 | L10: 0.42105263
B11: 2 | C11: 3 | D11: 2 | E11: 3 | F11: 4 | H11: 5 | I11: 28 | J11: 96 | K11: 3.4285714 | L11: 0.6984127
