Workbook

Sheet FINANCIAL STATEMENTS
A2: FINANCIAL STATEMENTS OF PIDILITE
A4: INCOME STATEMENT
A6: PARTICULARS(AMOUNT IN CRORES OF INR) | B6: 43921 | C6: 44286 | D6: 44651 | E6: 45016 | F6: 45382 | G6: 45747
A7: INCOME
A9: REVENUE FROM OPERATIONS | B9: 6332.59 | C9: 6216.33 | D9: 8895.62 | E9: 10597.07 | F9: 11166.97 | G9: 12072.7
A10: OTHER INCOME | B10: 151.86 | C10: 73.49 | D10: 39.96 | E10: 63.04 | F10: 165.55 | G10: 294.34
A11: TOTAL INCOME | B11: =SUM(B9:B10) -> 6484.45 | C11: =SUM(C9:C10) -> 6289.82 | D11: =SUM(D9:D10) -> 8935.58 | E11: =SUM(E9:E10) -> 10660.11 | F11: =SUM(F9:F10) -> 11332.52 | G11: =SUM(G9:G10) -> 12367.04
A13: EXPENSES
A15: COST OF MATERIALS CONSUMED | B15: 2520.7 | C15: 2469.53 | D15: 4523.17 | E15: 5345.97 | F15: 4520.2 | G15: 4850.1
A16: PURCHASES OF STOCK IN TRADE | B16: 387.71 | C16: 453.99 | D16: 607.84 | E16: 858.96 | F16: 837.67 | G16: 825.67
A17: CHANGES IN INVENTORIES OF FINISHED GOODS, WORK IN PROGRESS, AND STOCK IN TRADE | B17: 27.98 | C17: -89.77 | D17: -225.52 | E17: -61.02 | F17: 57.65 | G17: -124.69
A18: EMPLOYEE BENEFITS EXPENSE | B18: 736.89 | C18: 787.75 | D18: 926.76 | E18: 1044.83 | F18: 1254.32 | G18: 1545.47
A19: OTHER EXPENSE | B19: 1175.75 | C19: 1047.15 | D19: 1290.97 | E19: 1553.15 | F19: 1947.45 | G19: 2141.32
A20: TOTAL EXPENSE BEFORE DEPRECIATION AND AMMORTISATION | B20: =SUM(B15:B19) -> 4849.03 | C20: =SUM(C15:C19) -> 4668.65 | D20: =SUM(D15:D19) -> 7123.22 | E20: =SUM(E15:E19) -> 8741.89 | F20: =SUM(F15:F19) -> 8617.29 | G20: =SUM(G15:G19) -> 9237.87
A22: EBITDA | B22: =B11-B20 -> 1635.42 | C22: =C11-C20 -> 1621.17 | D22: =D11-D20 -> 1812.36 | E22: =E11-E20 -> 1918.22 | F22: =F11-F20 -> 2715.23 | G22: =G11-G20 -> 3129.17
A23: DEPRECIATION, AMORTISATION AND IMPAIRMENT EXPENSE | B23: 125.79 | C23: 147.1 | D23: 194.38 | E23: 221.97 | F23: 289.11 | G23: 308.41
A24: EBIT | B24: =B22-B23 -> 1509.63 | C24: =C22-C23 -> 1474.07 | D24: =D22-D23 -> 1617.98 | E24: =E22-E23 -> 1696.25 | F24: =F22-F23 -> 2426.12 | G24: =G22-G23 -> 2820.76
A25: FINANCE COSTS | B25: 13.4 | C25: 16.99 | D25: 27.24 | E25: 28.53 | F25: 29.46 | G25: 34.72
A26: EXCEPTIONAL ITEMS | B26: 59.28 | C26: 0.45 | D26: 0 | E26: 0 | F26: -7.15 | G26: 20.16
A27: PROFIT BEFORE TAX | B27: =B24-SUM(B25:B26) -> 1436.95 | C27: =C24-SUM(C25:C26) -> 1456.63 | D27: =D24-SUM(D25:D26) -> 1590.74 | E27: =E24-SUM(E25:E26) -> 1667.72 | F27: =F24-SUM(F25:F26) -> 2403.81 | G27: =G24-SUM(G25:G26) -> 2765.88
A29: TAX EXPENSE
A31: CURRENT TAX | B31: 368.65 | C31: 375.05 | D31: 397.53 | E31: 423.05 | F31: 604.74 | G31: 676.08
A32: DEFERRED TAX | B32: -33.32 | C32: 0.12 | D32: 1.8 | E32: -12.51 | F32: -0.4 | G32: 15.97
A33: NET TAX EXPENSE | B33: =B31+B32 -> 335.33 | C33: =C31+C32 -> 375.17 | D33: =D31+D32 -> 399.33 | E33: =E31+E32 -> 410.54 | F33: =F31+F32 -> 604.34 | G33: =G31+G32 -> 692.05
A34: TAX RATE | B34: =B33/B27 -> 0.23336233 | C34: =C33/C27 -> 0.25756026 | D34: =D33/D27 -> 0.25103411 | E34: =E33/E27 -> 0.24616842 | F34: =F33/F27 -> 0.25140922 | G34: =G33/G27 -> 0.2502097
A36: TOTAL PROFIT FOR THE YEAR ( PROFIT AFTER TAX) | B36: =B27-B33 -> 1101.62 | C36: =C27-C33 -> 1081.46 | D36: =D27-D33 -> 1191.41 | E36: =E27-E33 -> 1257.18 | F36: =F27-F33 -> 1799.47 | G36: =G27-G33 -> 2073.83
A38: OTHER COMPREHENSIVE INCOME
A39: ITEMS THAT WILL NOT BE RECLASSIFIED TO INCOME STATEMENT
A41: REMEASUREMENT OF DEFINED BENEFIT PLAN | B41: -14.88 | C41: -0.95 | D41: -12.11 | E41: 1.94 | F41: -26.78 | G41: -15.24
A42: INCOME TAX RELATING TO ITEMS THAT WILL NOT RECLASSIFIED TO PROFIT OR LOSS | B42: 3.08 | C42: 0.24 | D42: 3.05 | E42: -0.49 | F42: 6.74 | G42: 3.84
A43: TOTAL OTHER COMPREHENSIVE LOSS | B43: =B42+B41 -> -11.8 | C43: =C42+C41 -> -0.71 | D43: =D42+D41 -> -9.06 | E43: =E42+E41 -> 1.45 | F43: =F42+F41 -> -20.04 | G43: =G42+G41 -> -11.4
A45: TOTAL COMPREHENSIVE INCOME FOR THE YEAR | B45: =B36+B43 -> 1089.82 | C45: =C36+C43 -> 1080.75 | D45: =D36+D43 -> 1182.35 | E45: =E36+E43 -> 1258.63 | F45: =F36+F43 -> 1779.43 | G45: =G36+G43 -> 2062.43
A47: EARNINGS PER EQUITY SHARE
A49: BASIC | B49: 21.69 | C49: 21.28 | D49: 23.45 | E49: 24.73 | F49: 35.39 | G49: 40.77
A50: DILUTED | B50: 21.68 | C50: 21.27 | D50: 23.43 | E50: 24.72 | F50: 35.35 | G50: 40.68
A53: BALANCE SHEET
A55: PARTICULARS(AMOUNT IN CRORES OF INR) | B55: 43921 | C55: 44286 | D55: 44651 | E55: 45016 | F55: 45382 | G55: 45747
A56: ASSETS
A58: NON CURRENT ASSETS
A60: PROPERTY , PLANT AND EQUIPMENT | B60: 861.24 | C60: 1023.38 | D60: 1322.77 | E60: 1443.37 | F60: 1897.08 | G60: 2096.07
...

Sheet SHAREHOLDERS
A1: SHAREHOLDERS | B1: HOLDING
A2: UTI,MUTUAL FUNDS,BANKS,INSURANCE COMPANIES | B2: 0.0904
A3: FII'S AND FPI'S | B3: 0.116
A4: BODIES CORPORATE AND INDIAN PUBLIC | B4: 0.0986
A5: PROMOTER AND PROMOTER GROUP | B5: 0.695

Sheet TREND ANALYSIS
A2: TREND ANALYSIS
A4: INCOME STATEMENT
A6: PARTICULARS(AMOUNT IN CRORES OF INR) | B6: 43921 | C6: 44286 | D6: 44651 | E6: 45016 | F6: 45382 | G6: 45747
A7: INCOME
A9: REVENUE FROM OPERATIONS | B9: ='FINANCIAL STATEMENTS'!B9/'FINANCIAL STATEMENTS'!$B9 -> 1 | C9: ='FINANCIAL STATEMENTS'!C9/'FINANCIAL STATEMENTS'!$B9 -> 0.981641 | D9: ='FINANCIAL STATEMENTS'!D9/'FINANCIAL STATEMENTS'!$B9 -> 1.4047365 | E9: ='FINANCIAL STATEMENTS'!E9/'FINANCIAL STATEMENTS'!$B9 -> 1.673418 | F9: ='FINANCIAL STATEMENTS'!F9/'FINANCIAL STATEMENTS'!$B9 -> 1.7634128 | G9: ='FINANCIAL STATEMENTS'!G9/'FINANCIAL STATEMENTS'!$B9 -> 1.9064395
A10: OTHER INCOME | B10: ='FINANCIAL STATEMENTS'!B10/'FINANCIAL STATEMENTS'!$B10 -> 1 | C10: ='FINANCIAL STATEMENTS'!C10/'FINANCIAL STATEMENTS'!$B10 -> 0.48393257 | D10: ='FINANCIAL STATEMENTS'!D10/'FINANCIAL STATEMENTS'!$B10 -> 0.2631371 | E10: ='FINANCIAL STATEMENTS'!E10/'FINANCIAL STATEMENTS'!$B10 -> 0.41511919 | F10: ='FINANCIAL STATEMENTS'!F10/'FINANCIAL STATEMENTS'!$B10 -> 1.0901488 | G10: ='FINANCIAL STATEMENTS'!G10/'FINANCIAL STATEMENTS'!$B10 -> 1.9382326
A11: TOTAL INCOME | B11: ='FINANCIAL STATEMENTS'!B11/'FINANCIAL STATEMENTS'!$B11 -> 1 | C11: ='FINANCIAL STATEMENTS'!C11/'FINANCIAL STATEMENTS'!$B11 -> 0.96998512 | D11: ='FINANCIAL STATEMENTS'!D11/'FINANCIAL STATEMENTS'!$B11 -> 1.3780012 | E11: ='FINANCIAL STATEMENTS'!E11/'FINANCIAL STATEMENTS'!$B11 -> 1.6439498 | F11: ='FINANCIAL STATEMENTS'!F11/'FINANCIAL STATEMENTS'!$B11 -> 1.7476455 | G11: ='FINANCIAL STATEMENTS'!G11/'FINANCIAL STATEMENTS'!$B11 -> 1.9071841
A13: EXPENSES
A15: COST OF MATERIALS CONSUMED | B15: ='FINANCIAL STATEMENTS'!B15/'FINANCIAL STATEMENTS'!$B15 -> 1 | C15: ='FINANCIAL STATEMENTS'!C15/'FINANCIAL STATEMENTS'!$B15 -> 0.97970008 | D15: ='FINANCIAL STATEMENTS'!D15/'FINANCIAL STATEMENTS'!$B15 -> 1.7944103 | E15: ='FINANCIAL STATEMENTS'!E15/'FINANCIAL STATEMENTS'!$B15 -> 2.1208275 | F15: ='FINANCIAL STATEMENTS'!F15/'FINANCIAL STATEMENTS'!$B15 -> 1.793232 | G15: ='FINANCIAL STATEMENTS'!G15/'FINANCIAL STATEMENTS'!$B15 -> 1.9241084
A16: PURCHASES OF STOCK IN TRADE | B16: ='FINANCIAL STATEMENTS'!B16/'FINANCIAL STATEMENTS'!$B16 -> 1 | C16: ='FINANCIAL STATEMENTS'!C16/'FINANCIAL STATEMENTS'!$B16 -> 1.1709525 | D16: ='FINANCIAL STATEMENTS'!D16/'FINANCIAL STATEMENTS'!$B16 -> 1.5677697 | E16: ='FINANCIAL STATEMENTS'!E16/'FINANCIAL STATEMENTS'!$B16 -> 2.2154703 | F16: ='FINANCIAL STATEMENTS'!F16/'FINANCIAL STATEMENTS'!$B16 -> 2.1605581 | G16: ='FINANCIAL STATEMENTS'!G16/'FINANCIAL STATEMENTS'!$B16 -> 2.1296072
A17: CHANGES IN INVENTORIES OF FINISHED GOODS, WORK IN PROGRESS, AND STOCK IN TRADE | B17: ='FINANCIAL STATEMENTS'!B17/'FINANCIAL STATEMENTS'!$B17 -> 1 | C17: ='FINANCIAL STATEMENTS'!C17/'FINANCIAL STATEMENTS'!$B17 -> -3.2083631 | D17: ='FINANCIAL STATEMENTS'!D17/'FINANCIAL STATEMENTS'!$B17 -> -8.0600429 | E17: ='FINANCIAL STATEMENTS'!E17/'FINANCIAL STATEMENTS'!$B17 -> -2.1808435 | F17: ='FINANCIAL STATEMENTS'!F17/'FINANCIAL STATEMENTS'!$B17 -> 2.0604003 | G17: ='FINANCIAL STATEMENTS'!G17/'FINANCIAL STATEMENTS'!$B17 -> -4.4563974
A18: EMPLOYEE BENEFITS EXPENSE | B18: ='FINANCIAL STATEMENTS'!B18/'FINANCIAL STATEMENTS'!$B18 -> 1 | C18: ='FINANCIAL STATEMENTS'!C18/'FINANCIAL STATEMENTS'!$B18 -> 1.0690198 | D18: ='FINANCIAL STATEMENTS'!D18/'FINANCIAL STATEMENTS'!$B18 -> 1.257664 | E18: ='FINANCIAL STATEMENTS'!E18/'FINANCIAL STATEMENTS'!$B18 -> 1.4178914 | F18: ='FINANCIAL STATEMENTS'!F18/'FINANCIAL STATEMENTS'!$B18 -> 1.7021808 | G18: ='FINANCIAL STATEMENTS'!G18/'FINANCIAL STATEMENTS'!$B18 -> 2.0972872
A19: OTHER EXPENSE | B19: ='FINANCIAL STATEMENTS'!B19/'FINANCIAL STATEMENTS'!$B19 -> 1 | C19: ='FINANCIAL STATEMENTS'!C19/'FINANCIAL STATEMENTS'!$B19 -> 0.89062301 | D19: ='FINANCIAL STATEMENTS'!D19/'FINANCIAL STATEMENTS'!$B19 -> 1.097997 | E19: ='FINANCIAL STATEMENTS'!E19/'FINANCIAL STATEMENTS'!$B19 -> 1.3209866 | F19: ='FINANCIAL STATEMENTS'!F19/'FINANCIAL STATEMENTS'!$B19 -> 1.656347 | G19: ='FINANCIAL STATEMENTS'!G19/'FINANCIAL STATEMENTS'!$B19 -> 1.8212375
A20: TOTAL EXPENSE BEFORE DEPRECIATION AND AMMORTISATION | B20: ='FINANCIAL STATEMENTS'!B20/'FINANCIAL STATEMENTS'!$B20 -> 1 | C20: ='FINANCIAL STATEMENTS'!C20/'FINANCIAL STATEMENTS'!$B20 -> 0.96280081 | D20: ='FINANCIAL STATEMENTS'!D20/'FINANCIAL STATEMENTS'!$B20 -> 1.468999 | E20: ='FINANCIAL STATEMENTS'!E20/'FINANCIAL STATEMENTS'!$B20 -> 1.8028121 | F20: ='FINANCIAL STATEMENTS'!F20/'FINANCIAL STATEMENTS'!$B20 -> 1.7771162 | G20: ='FINANCIAL STATEMENTS'!G20/'FINANCIAL STATEMENTS'!$B20 -> 1.9050965
A22: EBITDA | B22: ='FINANCIAL STATEMENTS'!B22/'FINANCIAL STATEMENTS'!$B22 -> 1 | C22: ='FINANCIAL STATEMENTS'!C22/'FINANCIAL STATEMENTS'!$B22 -> 0.99128664 | D22: ='FINANCIAL STATEMENTS'!D22/'FINANCIAL STATEMENTS'!$B22 -> 1.1081924 | E22: ='FINANCIAL STATEMENTS'!E22/'FINANCIAL STATEMENTS'!$B22 -> 1.1729219 | F22: ='FINANCIAL STATEMENTS'!F22/'FINANCIAL STATEMENTS'!$B22 -> 1.6602646 | G22: ='FINANCIAL STATEMENTS'!G22/'FINANCIAL STATEMENTS'!$B22 -> 1.9133739
A23: DEPRECIATION, AMORTISATION AND IMPAIRMENT EXPENSE | B23: ='FINANCIAL STATEMENTS'!B23/'FINANCIAL STATEMENTS'!$B23 -> 1 | C23: ='FINANCIAL STATEMENTS'!C23/'FINANCIAL STATEMENTS'!$B23 -> 1.1694093 | D23: ='FINANCIAL STATEMENTS'!D23/'FINANCIAL STATEMENTS'!$B23 -> 1.5452739 | E23: ='FINANCIAL STATEMENTS'!E23/'FINANCIAL STATEMENTS'!$B23 -> 1.7646077 | F23: ='FINANCIAL STATEMENTS'!F23/'FINANCIAL STATEMENTS'!$B23 -> 2.2983544 | G23: ='FINANCIAL STATEMENTS'!G23/'FINANCIAL STATEMENTS'!$B23 -> 2.4517847
A24: EBIT | B24: ='FINANCIAL STATEMENTS'!B24/'FINANCIAL STATEMENTS'!$B24 -> 1 | C24: ='FINANCIAL STATEMENTS'!C24/'FINANCIAL STATEMENTS'!$B24 -> 0.97644456 | D24: ='FINANCIAL STATEMENTS'!D24/'FINANCIAL STATEMENTS'!$B24 -> 1.0717726 | E24: ='FINANCIAL STATEMENTS'!E24/'FINANCIAL STATEMENTS'!$B24 -> 1.1236197 | F24: ='FINANCIAL STATEMENTS'!F24/'FINANCIAL STATEMENTS'!$B24 -> 1.6070958 | G24: ='FINANCIAL STATEMENTS'!G24/'FINANCIAL STATEMENTS'!$B24 -> 1.8685108
A25: FINANCE COSTS | B25: ='FINANCIAL STATEMENTS'!B25/'FINANCIAL STATEMENTS'!$B25 -> 1 | C25: ='FINANCIAL STATEMENTS'!C25/'FINANCIAL STATEMENTS'!$B25 -> 1.2679104 | D25: ='FINANCIAL STATEMENTS'!D25/'FINANCIAL STATEMENTS'!$B25 -> 2.0328358 | E25: ='FINANCIAL STATEMENTS'!E25/'FINANCIAL STATEMENTS'!$B25 -> 2.1291045 | F25: ='FINANCIAL STATEMENTS'!F25/'FINANCIAL STATEMENTS'!$B25 -> 2.1985075 | G25: ='FINANCIAL STATEMENTS'!G25/'FINANCIAL STATEMENTS'!$B25 -> 2.5910448
A26: EXCEPTIONAL ITEMS | B26: ='FINANCIAL STATEMENTS'!B26/'FINANCIAL STATEMENTS'!$B26 -> 1 | C26: ='FINANCIAL STATEMENTS'!C26/'FINANCIAL STATEMENTS'!$B26 -> 0.0075910931 | D26: ='FINANCIAL STATEMENTS'!D26/'FINANCIAL STATEMENTS'!$B26 -> 0 | E26: ='FINANCIAL STATEMENTS'!E26/'FINANCIAL STATEMENTS'!$B26 -> 0 | F26: ='FINANCIAL STATEMENTS'!F26/'FINANCIAL STATEMENTS'!$B26 -> -0.12061404 | G26: ='FINANCIAL STATEMENTS'!G26/'FINANCIAL STATEMENTS'!$B26 -> 0.34008097
A27: PROFIT BEFORE TAX | B27: ='FINANCIAL STATEMENTS'!B27/'FINANCIAL STATEMENTS'!$B27 -> 1 | C27: ='FINANCIAL STATEMENTS'!C27/'FINANCIAL STATEMENTS'!$B27 -> 1.0136957 | D27: ='FINANCIAL STATEMENTS'!D27/'FINANCIAL STATEMENTS'!$B27 -> 1.1070253 | E27: ='FINANCIAL STATEMENTS'!E27/'FINANCIAL STATEMENTS'!$B27 -> 1.1605971 | F27: ='FINANCIAL STATEMENTS'!F27/'FINANCIAL STATEMENTS'!$B27 -> 1.6728557 | G27: ='FINANCIAL STATEMENTS'!G27/'FINANCIAL STATEMENTS'!$B27 -> 1.9248269
A29: TAX EXPENSE
A31: CURRENT TAX | B31: ='FINANCIAL STATEMENTS'!B31/'FINANCIAL STATEMENTS'!$B31 -> 1 | C31: ='FINANCIAL STATEMENTS'!C31/'FINANCIAL STATEMENTS'!$B31 -> 1.0173606 | D31: ='FINANCIAL STATEMENTS'!D31/'FINANCIAL STATEMENTS'!$B31 -> 1.0783399 | E31: ='FINANCIAL STATEMENTS'!E31/'FINANCIAL STATEMENTS'!$B31 -> 1.1475654 | F31: ='FINANCIAL STATEMENTS'!F31/'FINANCIAL STATEMENTS'!$B31 -> 1.6404177 | G31: ='FINANCIAL STATEMENTS'!G31/'FINANCIAL STATEMENTS'!$B31 -> 1.8339346
A32: DEFERRED TAX | B32: ='FINANCIAL STATEMENTS'!B32/'FINANCIAL STATEMENTS'!$B32 -> 1 | C32: ='FINANCIAL STATEMENTS'!C32/'FINANCIAL STATEMENTS'!$B32 -> -0.0036014406 | D32: ='FINANCIAL STATEMENTS'!D32/'FINANCIAL STATEMENTS'!$B32 -> -0.054021609 | E32: ='FINANCIAL STATEMENTS'!E32/'FINANCIAL STATEMENTS'!$B32 -> 0.37545018 | F32: ='FINANCIAL STATEMENTS'!F32/'FINANCIAL STATEMENTS'!$B32 -> 0.012004802 | G32: ='FINANCIAL STATEMENTS'!G32/'FINANCIAL STATEMENTS'!$B32 -> -0.47929172
A33: NET TAX EXPENSE | B33: ='FINANCIAL STATEMENTS'!B33/'FINANCIAL STATEMENTS'!$B33 -> 1 | C33: ='FINANCIAL STATEMENTS'!C33/'FINANCIAL STATEMENTS'!$B33 -> 1.1188083 | D33: ='FINANCIAL STATEMENTS'!D33/'FINANCIAL STATEMENTS'!$B33 -> 1.1908568 | E33: ='FINANCIAL STATEMENTS'!E33/'FINANCIAL STATEMENTS'!$B33 -> 1.2242865 | F33: ='FINANCIAL STATEMENTS'!F33/'FINANCIAL STATEMENTS'!$B33 -> 1.8022247 | G33: ='FINANCIAL STATEMENTS'!G33/'FINANCIAL STATEMENTS'!$B33 -> 2.0637879
A34: TAX RATE | B34: ='FINANCIAL STATEMENTS'!B34/'FINANCIAL STATEMENTS'!$B34 -> 1 | C34: ='FINANCIAL STATEMENTS'!C34/'FINANCIAL STATEMENTS'!$B34 -> 1.1036925 | D34: ='FINANCIAL STATEMENTS'!D34/'FINANCIAL STATEMENTS'!$B34 -> 1.0757268 | E34: ='FINANCIAL STATEMENTS'!E34/'FINANCIAL STATEMENTS'!$B34 -> 1.0548764 | F34: ='FINANCIAL STATEMENTS'!F34/'FINANCIAL STATEMENTS'!$B34 -> 1.0773342 | G34: ='FINANCIAL STATEMENTS'!G34/'FINANCIAL STATEMENTS'!$B34 -> 1.072194
A36: TOTAL PROFIT FOR THE YEAR ( PROFIT AFTER TAX) | B36: ='FINANCIAL STATEMENTS'!B36/'FINANCIAL STATEMENTS'!$B36 -> 1 | C36: ='FINANCIAL STATEMENTS'!C36/'FINANCIAL STATEMENTS'!$B36 -> 0.98169968 | D36: ='FINANCIAL STATEMENTS'!D36/'FINANCIAL STATEMENTS'!$B36 -> 1.0815072 | E36: ='FINANCIAL STATEMENTS'!E36/'FINANCIAL STATEMENTS'!$B36 -> 1.1412102 | F36: ='FINANCIAL STATEMENTS'!F36/'FINANCIAL STATEMENTS'!$B36 -> 1.6334762 | G36: ='FINANCIAL STATEMENTS'!G36/'FINANCIAL STATEMENTS'!$B36 -> 1.8825276
A38: OTHER COMPREHENSIVE INCOME
A39: ITEMS THAT WILL NOT BE RECLASSIFIED TO INCOME STATEMENT
A41: REMEASUREMENT OF DEFINED BENEFIT PLAN | B41: ='FINANCIAL STATEMENTS'!B41/'FINANCIAL STATEMENTS'!$B41 -> 1 | C41: ='FINANCIAL STATEMENTS'!C41/'FINANCIAL STATEMENTS'!$B41 -> 0.063844086 | D41: ='FINANCIAL STATEMENTS'!D41/'FINANCIAL STATEMENTS'!$B41 -> 0.81384409 | E41: ='FINANCIAL STATEMENTS'!E41/'FINANCIAL STATEMENTS'!$B41 -> -0.13037634 | F41: ='FINANCIAL STATEMENTS'!F41/'FINANCIAL STATEMENTS'!$B41 -> 1.7997312 | G41: ='FINANCIAL STATEMENTS'!G41/'FINANCIAL STATEMENTS'!$B41 -> 1.0241935
A42: INCOME TAX RELATING TO ITEMS THAT WILL NOT RECLASSIFIED TO PROFIT OR LOSS | B42: ='FINANCIAL STATEMENTS'!B42/'FINANCIAL STATEMENTS'!$B42 -> 1 | C42: ='FINANCIAL STATEMENTS'!C42/'FINANCIAL STATEMENTS'!$B42 -> 0.077922078 | D42: ='FINANCIAL STATEMENTS'!D42/'FINANCIAL STATEMENTS'!$B42 -> 0.99025974 | E42: ='FINANCIAL STATEMENTS'!E42/'FINANCIAL STATEMENTS'!$B42 -> -0.15909091 | F42: ='FINANCIAL STATEMENTS'!F42/'FINANCIAL STATEMENTS'!$B42 -> 2.1883117 | G42: ='FINANCIAL STATEMENTS'!G42/'FINANCIAL STATEMENTS'!$B42 -> 1.2467532
A43: TOTAL OTHER COMPREHENSIVE LOSS | B43: ='FINANCIAL STATEMENTS'!B43/'FINANCIAL STATEMENTS'!$B43 -> 1 | C43: ='FINANCIAL STATEMENTS'!C43/'FINANCIAL STATEMENTS'!$B43 -> 0.060169492 | D43: ='FINANCIAL STATEMENTS'!D43/'FINANCIAL STATEMENTS'!$B43 -> 0.76779661 | E43: ='FINANCIAL STATEMENTS'!E43/'FINANCIAL STATEMENTS'!$B43 -> -0.12288136 | F43: ='FINANCIAL STATEMENTS'!F43/'FINANCIAL STATEMENTS'!$B43 -> 1.6983051 | G43: ='FINANCIAL STATEMENTS'!G43/'FINANCIAL STATEMENTS'!$B43 -> 0.96610169
A45: TOTAL COMPREHENSIVE INCOME FOR THE YEAR | B45: ='FINANCIAL STATEMENTS'!B45/'FINANCIAL STATEMENTS'!$B45 -> 1 | C45: ='FINANCIAL STATEMENTS'!C45/'FINANCIAL STATEMENTS'!$B45 -> 0.99167752 | D45: ='FINANCIAL STATEMENTS'!D45/'FINANCIAL STATEMENTS'!$B45 -> 1.0849039 | E45: ='FINANCIAL STATEMENTS'!E45/'FINANCIAL STATEMENTS'!$B45 -> 1.1548971 | F45: ='FINANCIAL STATEMENTS'!F45/'FINANCIAL STATEMENTS'!$B45 -> 1.6327742 | G45: ='FINANCIAL STATEMENTS'!G45/'FINANCIAL STATEMENTS'!$B45 -> 1.8924501
A47: EARNINGS PER EQUITY SHARE
A48: BASIC | B48: ='FINANCIAL STATEMENTS'!B49/'FINANCIAL STATEMENTS'!$B49 -> 1 | C48: ='FINANCIAL STATEMENTS'!C49/'FINANCIAL STATEMENTS'!$B49 -> 0.98109728 | D48: ='FINANCIAL STATEMENTS'!D49/'FINANCIAL STATEMENTS'!$B49 -> 1.0811434 | E48: ='FINANCIAL STATEMENTS'!E49/'FINANCIAL STATEMENTS'!$B49 -> 1.1401568 | F48: ='FINANCIAL STATEMENTS'!F49/'FINANCIAL STATEMENTS'!$B49 -> 1.6316275 | G48: ='FINANCIAL STATEMENTS'!G49/'FINANCIAL STATEMENTS'!$B49 -> 1.879668
A49: DILUTED | B49: ='FINANCIAL STATEMENTS'!B50/'FINANCIAL STATEMENTS'!$B50 -> 1 | C49: ='FINANCIAL STATEMENTS'!C50/'FINANCIAL STATEMENTS'!$B50 -> 0.98108856 | D49: ='FINANCIAL STATEMENTS'!D50/'FINANCIAL STATEMENTS'!$B50 -> 1.0807196 | E49: ='FINANCIAL STATEMENTS'!E50/'FINANCIAL STATEMENTS'!$B50 -> 1.1402214 | F49: ='FINANCIAL STATEMENTS'!F50/'FINANCIAL STATEMENTS'!$B50 -> 1.6305351 | G49: ='FINANCIAL STATEMENTS'!G50/'FINANCIAL STATEMENTS'!$B50 -> 1.8763838
A52: BALANCE SHEET
A54: PARTICULARS(AMOUNT IN CRORES OF INR) | B54: 43921 | C54: 44286 | D54: 44651 | E54: 45016 | F54: 45382 | G54: 45747 | O54: PARTICULARS(AMOUNT IN CRORES OF INR) | P54: 43921 | Q54: 44286 | R54: 44651 | S54: 45016 | T54: 45382 | U54: 45747
A55: ASSETS | O55: TOTAL ASSETS | P55: 1 | Q55: 1.3100759 | R55: 1.5016807 | S55: 1.6635213 | T55: 1.9540544 | U55: 2.2806312
O56: TOTAL EQUITY AND LIABILITIES | P56: 1 | Q56: 1.3100759 | R56: 1.5016807 | S56: 1.6635213 | T56: 1.9540544 | U56: 2.2806312
A57: NON CURRENT ASSETS
...

Sheet CASH FLOW STATEMENT
A2: CASH FLOW STATEMENT
A5: CASH FLOW | B5: 43921 | C5: 44286 | D5: 44651 | E5: 45016 | F5: 45382 | G5: 45747
A6: OPERATING ACTIVITIES
A7: PROFIT BEFORE TAX | B7: 1436.95 | C7: 1456.63 | D7: 1590.74 | E7: 1667.72 | F7: 2403.81 | G7: 2765.88
A9: ADJUSTMENTS FOR :
A11: FINANCE COSTS | B11: 13.4 | C11: 16.99 | D11: 27.24 | E11: 28.53 | F11: 29.46 | G11: 34.72
A12: INTEREST INCOME | B12: -5.93 | C12: -12.78 | D12: -2.41 | E12: -4.9 | F12: -7.59 | G12: -5.63
A13: DIVIDEND INCOME | B13: -13.38 | C13: -2.78 | D13: -4.01 | E13: -17.46 | F13: -39.97 | G13: -54.82
A14: LOSS/(PROFIT) ON DISPOSAL OF PROPERTY , PLANT AND EQUIPMENT | B14: -2.67 | C14: 5.85 | D14: 8.2 | E14: -1.96 | F14: 8.88 | G14: 1.36
A15: NET GAIN ARISING ON ASSETS DESIGNATED AS FVTPL | B15: -110.39 | C15: -39.99 | D15: -11.37 | E15: -16.78 | F15: -84.94 | G15: -214.23
A16: ALLOWANCE FOR DOUBTFUL DEBTS | B16: 0 | C16: 3.73 | D16: -2.57 | E16: 4.64 | F16: 4 | G16: 6.87
A17: PROVISION IN RESPECT OF WRITE DOWN OF INVENTORIES | B17: 0 | C17: 0 | D17: 0 | E17: 0 | F17: 0 | G17: 5.34
A18: LIABILITIES NO LONGER REQUIRED WRITTEN BACK | B18: 0 | C18: 0 | D18: 0 | E18: 0 | F18: -3.77 | G18: -2.25
A19: ALLOWANCE FOR DOUBTFUL DEBTS WRITTEN BACK | B19: -5.8 | C19: 0 | D19: 0 | E19: 0 | F19: 0 | G19: 0
A20: EXCEPTIONAL ITEM - IMPAIRMENT IN VALUE OF ASSETS AND INVESTMENTS LOSS/(GAIN) | B20: 59.28 | C20: 0.45 | D20: 194.38 | E20: 0 | F20: -7.15 | G20: 20.16
A21: DEPRECIATION , AMMORTISATION AND IMPAIRMENT EXPENSE | B21: 125.79 | C21: 147.1 | D21: 3.75 | E21: 221.97 | F21: 289.11 | G21: 308.41
A22: UNREALISED FOREIGN EXCHANGE NET LOSS/(GAIN) | B22: -0.15 | C22: -1.88 | D22: 15.79 | E22: 4.73 | F22: -6.73 | G22: 0.57
... A26: OTHER PROVISIONS | B26: 0 | C26: 0 | D26: 0 | E26: 0 | F26: 48.02 | G26: 57.37
A28: OPERATING PROFITS BEFORE WORKING CAPITAL CHANGES | B28: =B7+SUM(B11:B26) -> 1500.05 | C28: =C7+SUM(C11:C26) -> 1598.49 | D28: =D7+SUM(D11:D26) -> 1846.72 | E28: =E7+SUM(E11:E26) -> 1906.26 | F28: =F7+SUM(F11:F26) -> 2656.77 | G28: =G7+SUM(G11:G26) -> 3024.83
A30: MOVEMENTS IN WORKING CAPITAL
A31: (INCREASE)/DECREASE IN OPERATING ASSETS
A33: TRADE RECEIVABLES | B33: -17.94 | C33: -200.06 | D33: -122.46 | E33: -99.3 | F33: -104.06 | G33: -157.35
A34: INVENTORIES | B34: 3.81 | C34: -240.47 | D34: -415.73 | E34: -119.32 | F34: 304.02 | G34: -238.49
A35: NON-CURRENT LOANS | B35: -1.1 | C35: -0.78 | D35: -0.2 | E35: -1.15 | F35: -1.93 | G35: -0.24
A36: CURRENT LOANS | B36: -10 | C36: -7.87 | D36: -1.36 | E36: -6.15 | F36: 2.35 | G36: -0.18
A37: OTHER NON-CURRENT FINANCIAL ASSETS | B37: 5.39 | C37: 0.02 | D37: -3.64 | E37: -15.5 | F37: -4.56 | G37: -3.11
A38: OTHER CURRENT FINANCIAL ASSETS | B38: 1.02 | C38: 0.89 | D38: -2.9 | E38: 3.7 | F38: 1.88 | G38: -1.71
A39: OTHER NON CURRENT NON FINANCIAL ASSETS | B39: 2.83 | C39: -27.8 | D39: -21.06 | E39: -17.32 | F39: -0.14 | G39: -4.92
A40: OTHER CURRENT NON FINANCIAL ASSETS | B40: -25.7 | C40: 13.39 | D40: -15.39 | E40: 15.59 | F40: -10.27 | G40: -69.05
A42: INCREASE/(DECREASE) IN OPERATING LIABILITIES
A44: TRADE PAYABLES | B44: 37.89 | C44: 296.34 | D44: -1.91 | E44: -10.05 | F44: 109.72 | G44: 229.09
A45: OTHER CURRENT FINANCIAL LIABILITIES | B45: 113.99 | C45: 121.42 | D45: 35.02 | E45: 173.36 | F45: 226.72 | G45: 163.24
A46: OTHER NON CURRENT FINANCIAL LIABILITIES | B46: -38.75 | C46: 6.37 | D46: 6.31 | E46: -5.49 | F46: 0 | G46: 0
A47: OTHER CURRENT NON FINANCIAL LIABILITIES | B47: 32.6 | C47: -17.4 | D47: 2.48 | E47: 6.3 | F47: 10.91 | G47: -10.02
A49: CASH GENERATED FROM OPERATIONS | B49: =SUM(B33:B40)+SUM(B44:B47)+B28 -> 1604.09 | C49: =SUM(C33:C40)+SUM(C44:C47)+C28 -> 1542.54 | D49: =SUM(D33:D40)+SUM(D44:D47)+D28 -> 1305.88 | E49: =SUM(E33:E40)+SUM(E44:E47)+E28 -> 1830.93 | F49: =SUM(F33:F40)+SUM(F44:F47)+F28 -> 3191.41 | G49: =SUM(G33:G40)+SUM(G44:G47)+G28 -> 2932.09
A51: TAXES PAID (NET OF REFUNDS) | B51: -375.92 | C51: -342.02 | D51: -448.96 | E51: -398.57 | F51: -605.51 | G51: -703.38
A53: NET CASH GENERATED FROM OPERATING ACTIVITIES [A] | B53: =B49+B51 -> 1228.17 | C53: =C49+C51 -> 1200.52 | D53: =D49+D51 -> 856.92 | E53: =E49+E51 -> 1432.36 | F53: =F49+F51 -> 2585.9 | G53: =G49+G51 -> 2228.71
A55: INVESTING ACTIVITIES
A57: PAYMENTS FOR PURCHASE OF PROPERT,PLANT AND EQUIPMENT, OTHER INTANGIBLE ASSETS AND CAPITAL WORK-IN-PROGRESS | B57: -398.86 | C57: -323.97 | D57: -322.57 | E57: -435.6 | F57: -510.07 | G57: -433.46
A58: PROCEEDS FROM DISPOSAL OF PROPERTY ,PLANT AND EQUIPMENT AND OTHER INTANGIBLE ASSETS | B58: 5.03 | C58: 1.76 | D58: 0.77 | E58: 7 | F58: 5.76 | G58: 4.27
...

Sheet COMMON SIZE FINANCIAL STATMENT
A2: COMMON SIZE FINANCIAL STATEMENT
A4: INCOME STATEMENT
A6: PARTICULARS(AMOUNT IN CRORES OF INR) | B6: 43921 | C6: 44286 | D6: 44651 | E6: 45016 | F6: 45382 | G6: 45747
A7: INCOME
A9: REVENUE FROM OPERATIONS | B9: ='FINANCIAL STATEMENTS'!B9/'FINANCIAL STATEMENTS'!B$9 -> 1 | C9: ='FINANCIAL STATEMENTS'!C9/'FINANCIAL STATEMENTS'!C$9 -> 1 | D9: ='FINANCIAL STATEMENTS'!D9/'FINANCIAL STATEMENTS'!D$9 -> 1 | E9: ='FINANCIAL STATEMENTS'!E9/'FINANCIAL STATEMENTS'!E$9 -> 1 | F9: ='FINANCIAL STATEMENTS'!F9/'FINANCIAL STATEMENTS'!F$9 -> 1 | G9: ='FINANCIAL STATEMENTS'!G9/'FINANCIAL STATEMENTS'!G$9 -> 1
A10: OTHER INCOME | B10: ='FINANCIAL STATEMENTS'!B10/'FINANCIAL STATEMENTS'!B$9 -> 0.023980709 | C10: ='FINANCIAL STATEMENTS'!C10/'FINANCIAL STATEMENTS'!C$9 -> 0.011822088 | D10: ='FINANCIAL STATEMENTS'!D10/'FINANCIAL STATEMENTS'!D$9 -> 0.0044920984 | E10: ='FINANCIAL STATEMENTS'!E10/'FINANCIAL STATEMENTS'!E$9 -> 0.0059488142 | F10: ='FINANCIAL STATEMENTS'!F10/'FINANCIAL STATEMENTS'!F$9 -> 0.01482497 | G10: ='FINANCIAL STATEMENTS'!G10/'FINANCIAL STATEMENTS'!G$9 -> 0.024380627
A11: TOTAL INCOME | B11: ='FINANCIAL STATEMENTS'!B11/'FINANCIAL STATEMENTS'!B$9 -> 1.0239807 | C11: ='FINANCIAL STATEMENTS'!C11/'FINANCIAL STATEMENTS'!C$9 -> 1.0118221 | D11: ='FINANCIAL STATEMENTS'!D11/'FINANCIAL STATEMENTS'!D$9 -> 1.0044921 | E11: ='FINANCIAL STATEMENTS'!E11/'FINANCIAL STATEMENTS'!E$9 -> 1.0059488 | F11: ='FINANCIAL STATEMENTS'!F11/'FINANCIAL STATEMENTS'!F$9 -> 1.014825 | G11: ='FINANCIAL STATEMENTS'!G11/'FINANCIAL STATEMENTS'!G$9 -> 1.0243806
A13: EXPENSES
A15: COST OF MATERIALS CONSUMED | B15: ='FINANCIAL STATEMENTS'!B15/'FINANCIAL STATEMENTS'!B$9 -> 0.39805198 | C15: ='FINANCIAL STATEMENTS'!C15/'FINANCIAL STATEMENTS'!C$9 -> 0.39726495 | D15: ='FINANCIAL STATEMENTS'!D15/'FINANCIAL STATEMENTS'!D$9 -> 0.50847158 | E15: ='FINANCIAL STATEMENTS'!E15/'FINANCIAL STATEMENTS'!E$9 -> 0.50447624 | F15: ='FINANCIAL STATEMENTS'!F15/'FINANCIAL STATEMENTS'!F$9 -> 0.40478303 | G15: ='FINANCIAL STATEMENTS'!G15/'FINANCIAL STATEMENTS'!G$9 -> 0.40174112
A16: PURCHASES OF STOCK IN TRADE | B16: ='FINANCIAL STATEMENTS'!B16/'FINANCIAL STATEMENTS'!B$9 -> 0.061224554 | C16: ='FINANCIAL STATEMENTS'!C16/'FINANCIAL STATEMENTS'!C$9 -> 0.073031837 | D16: ='FINANCIAL STATEMENTS'!D16/'FINANCIAL STATEMENTS'!D$9 -> 0.068330257 | E16: ='FINANCIAL STATEMENTS'!E16/'FINANCIAL STATEMENTS'!E$9 -> 0.081056367 | F16: ='FINANCIAL STATEMENTS'!F16/'FINANCIAL STATEMENTS'!F$9 -> 0.075013186 | G16: ='FINANCIAL STATEMENTS'!G16/'FINANCIAL STATEMENTS'!G$9 -> 0.068391495
A17: CHANGES IN INVENTORIES OF FINISHED GOODS, WORK IN PROGRESS, AND STOCK IN TRADE | B17: ='FINANCIAL STATEMENTS'!B17/'FINANCIAL STATEMENTS'!B$9 -> 0.0044184133 | C17: ='FINANCIAL STATEMENTS'!C17/'FINANCIAL STATEMENTS'!C$9 -> -0.014440997 | D17: ='FINANCIAL STATEMENTS'!D17/'FINANCIAL STATEMENTS'!D$9 -> -0.025351802 | E17: ='FINANCIAL STATEMENTS'!E17/'FINANCIAL STATEMENTS'!E$9 -> -0.0057581954 | F17: ='FINANCIAL STATEMENTS'!F17/'FINANCIAL STATEMENTS'!F$9 -> 0.0051625463 | G17: ='FINANCIAL STATEMENTS'!G17/'FINANCIAL STATEMENTS'!G$9 -> -0.010328261
A18: EMPLOYEE BENEFITS EXPENSE | B18: ='FINANCIAL STATEMENTS'!B18/'FINANCIAL STATEMENTS'!B$9 -> 0.11636471 | C18: ='FINANCIAL STATEMENTS'!C18/'FINANCIAL STATEMENTS'!C$9 -> 0.12672268 | D18: ='FINANCIAL STATEMENTS'!D18/'FINANCIAL STATEMENTS'!D$9 -> 0.10418161 | E18: ='FINANCIAL STATEMENTS'!E18/'FINANCIAL STATEMENTS'!E$9 -> 0.098596121 | F18: ='FINANCIAL STATEMENTS'!F18/'FINANCIAL STATEMENTS'!F$9 -> 0.11232411 | G18: ='FINANCIAL STATEMENTS'!G18/'FINANCIAL STATEMENTS'!G$9 -> 0.12801362
A19: OTHER EXPENSE | B19: ='FINANCIAL STATEMENTS'!B19/'FINANCIAL STATEMENTS'!B$9 -> 0.18566653 | C19: ='FINANCIAL STATEMENTS'!C19/'FINANCIAL STATEMENTS'!C$9 -> 0.16845148 | D19: ='FINANCIAL STATEMENTS'!D19/'FINANCIAL STATEMENTS'!D$9 -> 0.14512423 | E19: ='FINANCIAL STATEMENTS'!E19/'FINANCIAL STATEMENTS'!E$9 -> 0.1465641 | F19: ='FINANCIAL STATEMENTS'!F19/'FINANCIAL STATEMENTS'!F$9 -> 0.17439377 | G19: ='FINANCIAL STATEMENTS'!G19/'FINANCIAL STATEMENTS'!G$9 -> 0.17736877
A20: TOTAL EXPENSE BEFORE DEPRECIATION AND AMMORTISATION | B20: ='FINANCIAL STATEMENTS'!B20/'FINANCIAL STATEMENTS'!B$9 -> 0.76572619 | C20: ='FINANCIAL STATEMENTS'!C20/'FINANCIAL STATEMENTS'!C$9 -> 0.75102995 | D20: ='FINANCIAL STATEMENTS'!D20/'FINANCIAL STATEMENTS'!D$9 -> 0.80075588 | E20: ='FINANCIAL STATEMENTS'!E20/'FINANCIAL STATEMENTS'!E$9 -> 0.82493463 | F20: ='FINANCIAL STATEMENTS'!F20/'FINANCIAL STATEMENTS'!F$9 -> 0.77167665 | G20: ='FINANCIAL STATEMENTS'!G20/'FINANCIAL STATEMENTS'!G$9 -> 0.76518674
A22: EBITDA | B22: ='FINANCIAL STATEMENTS'!B22/'FINANCIAL STATEMENTS'!B$9 -> 0.25825452 | C22: ='FINANCIAL STATEMENTS'!C22/'FINANCIAL STATEMENTS'!C$9 -> 0.26079214 | D22: ='FINANCIAL STATEMENTS'!D22/'FINANCIAL STATEMENTS'!D$9 -> 0.20373622 | E22: ='FINANCIAL STATEMENTS'!E22/'FINANCIAL STATEMENTS'!E$9 -> 0.18101419 | F22: ='FINANCIAL STATEMENTS'!F22/'FINANCIAL STATEMENTS'!F$9 -> 0.24314832 | G22: ='FINANCIAL STATEMENTS'!G22/'FINANCIAL STATEMENTS'!G$9 -> 0.25919388
A23: DEPRECIATION, AMORTISATION AND IMPAIRMENT EXPENSE | B23: ='FINANCIAL STATEMENTS'!B23/'FINANCIAL STATEMENTS'!B$9 -> 0.01986391 | C23: ='FINANCIAL STATEMENTS'!C23/'FINANCIAL STATEMENTS'!C$9 -> 0.02366348 | D23: ='FINANCIAL STATEMENTS'!D23/'FINANCIAL STATEMENTS'!D$9 -> 0.021851203 | E23: ='FINANCIAL STATEMENTS'!E23/'FINANCIAL STATEMENTS'!E$9 -> 0.020946356 | F23: ='FINANCIAL STATEMENTS'!F23/'FINANCIAL STATEMENTS'!F$9 -> 0.025889744 | G23: ='FINANCIAL STATEMENTS'!G23/'FINANCIAL STATEMENTS'!G$9 -> 0.025546067
A24: EBIT | B24: ='FINANCIAL STATEMENTS'!B24/'FINANCIAL STATEMENTS'!B$9 -> 0.23839061 | C24: ='FINANCIAL STATEMENTS'!C24/'FINANCIAL STATEMENTS'!C$9 -> 0.23712866 | D24: ='FINANCIAL STATEMENTS'!D24/'FINANCIAL STATEMENTS'!D$9 -> 0.18188502 | E24: ='FINANCIAL STATEMENTS'!E24/'FINANCIAL STATEMENTS'!E$9 -> 0.16006783 | F24: ='FINANCIAL STATEMENTS'!F24/'FINANCIAL STATEMENTS'!F$9 -> 0.21725858 | G24: ='FINANCIAL STATEMENTS'!G24/'FINANCIAL STATEMENTS'!G$9 -> 0.23364782
A25: FINANCE COSTS | B25: ='FINANCIAL STATEMENTS'!B25/'FINANCIAL STATEMENTS'!B$9 -> 0.0021160378 | C25: ='FINANCIAL STATEMENTS'!C25/'FINANCIAL STATEMENTS'!C$9 -> 0.0027331239 | D25: ='FINANCIAL STATEMENTS'!D25/'FINANCIAL STATEMENTS'!D$9 -> 0.0030621812 | E25: ='FINANCIAL STATEMENTS'!E25/'FINANCIAL STATEMENTS'!E$9 -> 0.0026922536 | F25: ='FINANCIAL STATEMENTS'!F25/'FINANCIAL STATEMENTS'!F$9 -> 0.0026381373 | G25: ='FINANCIAL STATEMENTS'!G25/'FINANCIAL STATEMENTS'!G$9 -> 0.0028759101
A26: EXCEPTIONAL ITEMS | B26: ='FINANCIAL STATEMENTS'!B26/'FINANCIAL STATEMENTS'!B$9 -> 0.0093610987 | C26: ='FINANCIAL STATEMENTS'!C26/'FINANCIAL STATEMENTS'!C$9 -> 7.2389979e-05 | D26: ='FINANCIAL STATEMENTS'!D26/'FINANCIAL STATEMENTS'!D$9 -> 0 | E26: ='FINANCIAL STATEMENTS'!E26/'FINANCIAL STATEMENTS'!E$9 -> 0 | F26: ='FINANCIAL STATEMENTS'!F26/'FINANCIAL STATEMENTS'!F$9 -> -0.00064028111 | G26: ='FINANCIAL STATEMENTS'!G26/'FINANCIAL STATEMENTS'!G$9 -> 0.0016698833
A27: PROFIT BEFORE TAX | B27: ='FINANCIAL STATEMENTS'!B27/'FINANCIAL STATEMENTS'!B$9 -> 0.22691347 | C27: ='FINANCIAL STATEMENTS'!C27/'FINANCIAL STATEMENTS'!C$9 -> 0.23432315 | D27: ='FINANCIAL STATEMENTS'!D27/'FINANCIAL STATEMENTS'!D$9 -> 0.17882284 | E27: ='FINANCIAL STATEMENTS'!E27/'FINANCIAL STATEMENTS'!E$9 -> 0.15737558 | F27: ='FINANCIAL STATEMENTS'!F27/'FINANCIAL STATEMENTS'!F$9 -> 0.21526072 | G27: ='FINANCIAL STATEMENTS'!G27/'FINANCIAL STATEMENTS'!G$9 -> 0.22910202
A29: TAX EXPENSE
A31: CURRENT TAX | B31: ='FINANCIAL STATEMENTS'!B31/'FINANCIAL STATEMENTS'!B$9 -> 0.058214727 | C31: ='FINANCIAL STATEMENTS'!C31/'FINANCIAL STATEMENTS'!C$9 -> 0.060333026 | D31: ='FINANCIAL STATEMENTS'!D31/'FINANCIAL STATEMENTS'!D$9 -> 0.044688285 | E31: ='FINANCIAL STATEMENTS'!E31/'FINANCIAL STATEMENTS'!E$9 -> 0.039921412 | F31: ='FINANCIAL STATEMENTS'!F31/'FINANCIAL STATEMENTS'!F$9 -> 0.05415435 | G31: ='FINANCIAL STATEMENTS'!G31/'FINANCIAL STATEMENTS'!G$9 -> 0.056000729
A32: DEFERRED TAX | B32: ='FINANCIAL STATEMENTS'!B32/'FINANCIAL STATEMENTS'!B$9 -> -0.0052616702 | C32: ='FINANCIAL STATEMENTS'!C32/'FINANCIAL STATEMENTS'!C$9 -> 1.9303994e-05 | D32: ='FINANCIAL STATEMENTS'!D32/'FINANCIAL STATEMENTS'!D$9 -> 0.00020234677 | E32: ='FINANCIAL STATEMENTS'!E32/'FINANCIAL STATEMENTS'!E$9 -> -0.001180515 | F32: ='FINANCIAL STATEMENTS'!F32/'FINANCIAL STATEMENTS'!F$9 -> -3.5819923e-05 | G32: ='FINANCIAL STATEMENTS'!G32/'FINANCIAL STATEMENTS'!G$9 -> 0.0013228193
A33: NET TAX EXPENSE | B33: ='FINANCIAL STATEMENTS'!B33/'FINANCIAL STATEMENTS'!B$9 -> 0.052953057 | C33: ='FINANCIAL STATEMENTS'!C33/'FINANCIAL STATEMENTS'!C$9 -> 0.06035233 | D33: ='FINANCIAL STATEMENTS'!D33/'FINANCIAL STATEMENTS'!D$9 -> 0.044890632 | E33: ='FINANCIAL STATEMENTS'!E33/'FINANCIAL STATEMENTS'!E$9 -> 0.038740897 | F33: ='FINANCIAL STATEMENTS'!F33/'FINANCIAL STATEMENTS'!F$9 -> 0.05411853 | G33: ='FINANCIAL STATEMENTS'!G33/'FINANCIAL STATEMENTS'!G$9 -> 0.057323548
A35: TOTAL PROFIT FOR THE YEAR ( PROFIT AFTER TAX) | B35: ='FINANCIAL STATEMENTS'!B36/'FINANCIAL STATEMENTS'!B$9 -> 0.17396042 | C35: ='FINANCIAL STATEMENTS'!C36/'FINANCIAL STATEMENTS'!C$9 -> 0.17397082 | D35: ='FINANCIAL STATEMENTS'!D36/'FINANCIAL STATEMENTS'!D$9 -> 0.1339322 | E35: ='FINANCIAL STATEMENTS'!E36/'FINANCIAL STATEMENTS'!E$9 -> 0.11863468 | F35: ='FINANCIAL STATEMENTS'!F36/'FINANCIAL STATEMENTS'!F$9 -> 0.16114219 | G35: ='FINANCIAL STATEMENTS'!G36/'FINANCIAL STATEMENTS'!G$9 -> 0.17177848
A37: OTHER COMPREHENSIVE INCOME
A38: ITEMS THAT WILL NOT BE RECLASSIFIED TO INCOME STATEMENT
A40: REMEASUREMENT OF DEFINED BENEFIT PLAN | B40: ='FINANCIAL STATEMENTS'!B41/'FINANCIAL STATEMENTS'!B$9 -> -0.0023497495 | C40: ='FINANCIAL STATEMENTS'!C41/'FINANCIAL STATEMENTS'!C$9 -> -0.00015282329 | D40: ='FINANCIAL STATEMENTS'!D41/'FINANCIAL STATEMENTS'!D$9 -> -0.0013613441 | E40: ='FINANCIAL STATEMENTS'!E41/'FINANCIAL STATEMENTS'!E$9 -> 0.00018306947 | F40: ='FINANCIAL STATEMENTS'!F41/'FINANCIAL STATEMENTS'!F$9 -> -0.0023981438 | G40: ='FINANCIAL STATEMENTS'!G41/'FINANCIAL STATEMENTS'!G$9 -> -0.0012623522
A41: INCOME TAX RELATING TO ITEMS THAT WILL NOT RECLASSIFIED TO PROFIT OR LOSS | B41: ='FINANCIAL STATEMENTS'!B42/'FINANCIAL STATEMENTS'!B$9 -> 0.00048637287 | C41: ='FINANCIAL STATEMENTS'!C42/'FINANCIAL STATEMENTS'!C$9 -> 3.8607989e-05 | D41: ='FINANCIAL STATEMENTS'!D42/'FINANCIAL STATEMENTS'!D$9 -> 0.00034286537 | E41: ='FINANCIAL STATEMENTS'!E42/'FINANCIAL STATEMENTS'!E$9 -> -4.6239196e-05 | F41: ='FINANCIAL STATEMENTS'!F42/'FINANCIAL STATEMENTS'!F$9 -> 0.00060356569 | G41: ='FINANCIAL STATEMENTS'!G42/'FINANCIAL STATEMENTS'!G$9 -> 0.00031807301
A42: TOTAL OTHER COMPREHENSIVE LOSS | B42: ='FINANCIAL STATEMENTS'!B43/'FINANCIAL STATEMENTS'!B$9 -> -0.0018633766 | C42: ='FINANCIAL STATEMENTS'!C43/'FINANCIAL STATEMENTS'!C$9 -> -0.0001142153 | D42: ='FINANCIAL STATEMENTS'!D43/'FINANCIAL STATEMENTS'!D$9 -> -0.0010184788 | E42: ='FINANCIAL STATEMENTS'!E43/'FINANCIAL STATEMENTS'!E$9 -> 0.00013683027 | F42: ='FINANCIAL STATEMENTS'!F43/'FINANCIAL STATEMENTS'!F$9 -> -0.0017945781 | G42: ='FINANCIAL STATEMENTS'!G43/'FINANCIAL STATEMENTS'!G$9 -> -0.00094427924
A44: TOTAL COMPREHENSIVE INCOME FOR THE YEAR | B44: ='FINANCIAL STATEMENTS'!B45/'FINANCIAL STATEMENTS'!B$9 -> 0.17209704 | C44: ='FINANCIAL STATEMENTS'!C45/'FINANCIAL STATEMENTS'!C$9 -> 0.1738566 | D44: ='FINANCIAL STATEMENTS'!D45/'FINANCIAL STATEMENTS'!D$9 -> 0.13291373 | E44: ='FINANCIAL STATEMENTS'!E45/'FINANCIAL STATEMENTS'!E$9 -> 0.11877151 | F44: ='FINANCIAL STATEMENTS'!F45/'FINANCIAL STATEMENTS'!F$9 -> 0.15934761 | G44: ='FINANCIAL STATEMENTS'!G45/'FINANCIAL STATEMENTS'!G$9 -> 0.1708342
A46: EARNINGS PER EQUITY SHARE
A47: BASIC | B47: ='FINANCIAL STATEMENTS'!B49/'FINANCIAL STATEMENTS'!B$9 -> 0.0034251388 | C47: ='FINANCIAL STATEMENTS'!C49/'FINANCIAL STATEMENTS'!C$9 -> 0.0034232417 | D47: ='FINANCIAL STATEMENTS'!D49/'FINANCIAL STATEMENTS'!D$9 -> 0.0026361288 | E47: ='FINANCIAL STATEMENTS'!E49/'FINANCIAL STATEMENTS'!E$9 -> 0.0023336639 | F47: ='FINANCIAL STATEMENTS'!F49/'FINANCIAL STATEMENTS'!F$9 -> 0.0031691676 | G47: ='FINANCIAL STATEMENTS'!G49/'FINANCIAL STATEMENTS'!G$9 -> 0.0033770408
A48: DILUTED | B48: ='FINANCIAL STATEMENTS'!B50/'FINANCIAL STATEMENTS'!B$9 -> 0.0034235597 | C48: ='FINANCIAL STATEMENTS'!C50/'FINANCIAL STATEMENTS'!C$9 -> 0.003421633 | D48: ='FINANCIAL STATEMENTS'!D50/'FINANCIAL STATEMENTS'!D$9 -> 0.0026338805 | E48: ='FINANCIAL STATEMENTS'!E50/'FINANCIAL STATEMENTS'!E$9 -> 0.0023327203 | F48: ='FINANCIAL STATEMENTS'!F50/'FINANCIAL STATEMENTS'!F$9 -> 0.0031655857 | G48: ='FINANCIAL STATEMENTS'!G50/'FINANCIAL STATEMENTS'!G$9 -> 0.0033695859
A51: BALANCE SHEET
A53: PARTICULARS(AMOUNT IN CRORES OF INR) | B53: 43921 | C53: 44286 | D53: 44651 | E53: 45016 | F53: 45382 | G53: 45747
A54: ASSETS
A56: NON CURRENT ASSETS
A57: PROPERTY , PLANT AND EQUIPMENT | B57: ='FINANCIAL STATEMENTS'!B60/'FINANCIAL STATEMENTS'!B$87 -> 0.14800329 | C57: ='FINANCIAL STATEMENTS'!C60/'FINANCIAL STATEMENTS'!C$87 -> 0.13424176 | D57: ='FINANCIAL STATEMENTS'!D60/'FINANCIAL STATEMENTS'!D$87 -> 0.15137491 | E57: ='FINANCIAL STATEMENTS'!E60/'FINANCIAL STATEMENTS'!E$87 -> 0.14910647 | F57: ='FINANCIAL STATEMENTS'!F60/'FINANCIAL STATEMENTS'!F$87 -> 0.16683845 | G57: ='FINANCIAL STATEMENTS'!G60/'FINANCIAL STATEMENTS'!G$87 -> 0.15794209
A58: RIGHT OF USE ASSETS | B58: ='FINANCIAL STATEMENTS'!B61/'FINANCIAL STATEMENTS'!B$87 -> 0.018757325 | C58: ='FINANCIAL STATEMENTS'!C61/'FINANCIAL STATEMENTS'!C$87 -> 0.015566525 | D58: ='FINANCIAL STATEMENTS'!D61/'FINANCIAL STATEMENTS'!D$87 -> 0.019563145 | E58: ='FINANCIAL STATEMENTS'!E61/'FINANCIAL STATEMENTS'!E$87 -> 0.028196935 | F58: ='FINANCIAL STATEMENTS'!F61/'FINANCIAL STATEMENTS'!F$87 -> 0.027583908 | G58: ='FINANCIAL STATEMENTS'!G61/'FINANCIAL STATEMENTS'!G$87 -> 0.029946207
...

Sheet COMPARATIVE FINANCIAL STATEMENT
A2: COMPARATIVE FINANCIAL STATEMENT (YEAR ON YEAR)
A4: INCOME STATEMENT
A6: PARTICULARS(AMOUNT IN CRORES OF INR) | B6: 44286 | C6: 44651 | D6: 45016 | E6: 45382 | F6: 45747
A7: INCOME
A9: REVENUE FROM OPERATIONS | B9: =('FINANCIAL STATEMENTS'!C9-'FINANCIAL STATEMENTS'!B9)/'FINANCIAL STATEMENTS'!B9 -> -0.018358997 | C9: =('FINANCIAL STATEMENTS'!D9-'FINANCIAL STATEMENTS'!C9)/'FINANCIAL STATEMENTS'!C9 -> 0.43100833 | D9: =('FINANCIAL STATEMENTS'!E9-'FINANCIAL STATEMENTS'!D9)/'FINANCIAL STATEMENTS'!D9 -> 0.19126829 | E9: =('FINANCIAL STATEMENTS'!F9-'FINANCIAL STATEMENTS'!E9)/'FINANCIAL STATEMENTS'!E9 -> 0.053779016 | F9: =('FINANCIAL STATEMENTS'!G9-'FINANCIAL STATEMENTS'!F9)/'FINANCIAL STATEMENTS'!F9 -> 0.081107946
A10: OTHER INCOME | B10: =('FINANCIAL STATEMENTS'!C10-'FINANCIAL STATEMENTS'!B10)/'FINANCIAL STATEMENTS'!B10 -> -0.51606743 | C10: =('FINANCIAL STATEMENTS'!D10-'FINANCIAL STATEMENTS'!C10)/'FINANCIAL STATEMENTS'!C10 -> -0.45625255 | D10: =('FINANCIAL STATEMENTS'!E10-'FINANCIAL STATEMENTS'!D10)/'FINANCIAL STATEMENTS'!D10 -> 0.57757758 | E10: =('FINANCIAL STATEMENTS'!F10-'FINANCIAL STATEMENTS'!E10)/'FINANCIAL STATEMENTS'!E10 -> 1.6261104 | F10: =('FINANCIAL STATEMENTS'!G10-'FINANCIAL STATEMENTS'!F10)/'FINANCIAL STATEMENTS'!F10 -> 0.77795228
A11: TOTAL INCOME | B11: =('FINANCIAL STATEMENTS'!C11-'FINANCIAL STATEMENTS'!B11)/'FINANCIAL STATEMENTS'!B11 -> -0.030014882 | C11: =('FINANCIAL STATEMENTS'!D11-'FINANCIAL STATEMENTS'!C11)/'FINANCIAL STATEMENTS'!C11 -> 0.42064161 | D11: =('FINANCIAL STATEMENTS'!E11-'FINANCIAL STATEMENTS'!D11)/'FINANCIAL STATEMENTS'!D11 -> 0.19299587 | E11: =('FINANCIAL STATEMENTS'!F11-'FINANCIAL STATEMENTS'!E11)/'FINANCIAL STATEMENTS'!E11 -> 0.06307721 | F11: =('FINANCIAL STATEMENTS'!G11-'FINANCIAL STATEMENTS'!F11)/'FINANCIAL STATEMENTS'!F11 -> 0.091287728
A13: EXPENSES
A15: COST OF MATERIALS CONSUMED | B15: =('FINANCIAL STATEMENTS'!C15-'FINANCIAL STATEMENTS'!B15)/'FINANCIAL STATEMENTS'!B15 -> -0.020299917 | C15: =('FINANCIAL STATEMENTS'!D15-'FINANCIAL STATEMENTS'!C15)/'FINANCIAL STATEMENTS'!C15 -> 0.83159144 | D15: =('FINANCIAL STATEMENTS'!E15-'FINANCIAL STATEMENTS'!D15)/'FINANCIAL STATEMENTS'!D15 -> 0.18190782 | E15: =('FINANCIAL STATEMENTS'!F15-'FINANCIAL STATEMENTS'!E15)/'FINANCIAL STATEMENTS'!E15 -> -0.15446589 | F15: =('FINANCIAL STATEMENTS'!G15-'FINANCIAL STATEMENTS'!F15)/'FINANCIAL STATEMENTS'!F15 -> 0.072983496
A16: PURCHASES OF STOCK IN TRADE | B16: =('FINANCIAL STATEMENTS'!C16-'FINANCIAL STATEMENTS'!B16)/'FINANCIAL STATEMENTS'!B16 -> 0.17095252 | C16: =('FINANCIAL STATEMENTS'!D16-'FINANCIAL STATEMENTS'!C16)/'FINANCIAL STATEMENTS'!C16 -> 0.33888412 | D16: =('FINANCIAL STATEMENTS'!E16-'FINANCIAL STATEMENTS'!D16)/'FINANCIAL STATEMENTS'!D16 -> 0.41313504 | E16: =('FINANCIAL STATEMENTS'!F16-'FINANCIAL STATEMENTS'!E16)/'FINANCIAL STATEMENTS'!E16 -> -0.024785787 | F16: =('FINANCIAL STATEMENTS'!G16-'FINANCIAL STATEMENTS'!F16)/'FINANCIAL STATEMENTS'!F16 -> -0.01432545
A17: CHANGES IN INVENTORIES OF FINISHED GOODS, WORK IN PROGRESS, AND STOCK IN TRADE | B17: =('FINANCIAL STATEMENTS'!C17-'FINANCIAL STATEMENTS'!B17)/'FINANCIAL STATEMENTS'!B17 -> -4.2083631 | C17: =('FINANCIAL STATEMENTS'!D17-'FINANCIAL STATEMENTS'!C17)/'FINANCIAL STATEMENTS'!C17 -> 1.5121978 | D17: =('FINANCIAL STATEMENTS'!E17-'FINANCIAL STATEMENTS'!D17)/'FINANCIAL STATEMENTS'!D17 -> -0.72942533 | E17: =('FINANCIAL STATEMENTS'!F17-'FINANCIAL STATEMENTS'!E17)/'FINANCIAL STATEMENTS'!E17 -> -1.9447722 | F17: =('FINANCIAL STATEMENTS'!G17-'FINANCIAL STATEMENTS'!F17)/'FINANCIAL STATEMENTS'!F17 -> -3.1628794
A18: EMPLOYEE BENEFITS EXPENSE | B18: =('FINANCIAL STATEMENTS'!C18-'FINANCIAL STATEMENTS'!B18)/'FINANCIAL STATEMENTS'!B18 -> 0.069019799 | C18: =('FINANCIAL STATEMENTS'!D18-'FINANCIAL STATEMENTS'!C18)/'FINANCIAL STATEMENTS'!C18 -> 0.17646461 | D18: =('FINANCIAL STATEMENTS'!E18-'FINANCIAL STATEMENTS'!D18)/'FINANCIAL STATEMENTS'!D18 -> 0.12740084 | E18: =('FINANCIAL STATEMENTS'!F18-'FINANCIAL STATEMENTS'!E18)/'FINANCIAL STATEMENTS'!E18 -> 0.20050152 | F18: =('FINANCIAL STATEMENTS'!G18-'FINANCIAL STATEMENTS'!F18)/'FINANCIAL STATEMENTS'!F18 -> 0.2321178
A19: OTHER EXPENSE | B19: =('FINANCIAL STATEMENTS'!C19-'FINANCIAL STATEMENTS'!B19)/'FINANCIAL STATEMENTS'!B19 -> -0.10937699 | C19: =('FINANCIAL STATEMENTS'!D19-'FINANCIAL STATEMENTS'!C19)/'FINANCIAL STATEMENTS'!C19 -> 0.23284152 | D19: =('FINANCIAL STATEMENTS'!E19-'FINANCIAL STATEMENTS'!D19)/'FINANCIAL STATEMENTS'!D19 -> 0.2030876 | E19: =('FINANCIAL STATEMENTS'!F19-'FINANCIAL STATEMENTS'!E19)/'FINANCIAL STATEMENTS'!E19 -> 0.25387117 | F19: =('FINANCIAL STATEMENTS'!G19-'FINANCIAL STATEMENTS'!F19)/'FINANCIAL STATEMENTS'!F19 -> 0.099550694
A20: TOTAL EXPENSE BEFORE DEPRECIATION AND AMMORTISATION | B20: =('FINANCIAL STATEMENTS'!C20-'FINANCIAL STATEMENTS'!B20)/'FINANCIAL STATEMENTS'!B20 -> -0.037199192 | C20: =('FINANCIAL STATEMENTS'!D20-'FINANCIAL STATEMENTS'!C20)/'FINANCIAL STATEMENTS'!C20 -> 0.52575584 | D20: =('FINANCIAL STATEMENTS'!E20-'FINANCIAL STATEMENTS'!D20)/'FINANCIAL STATEMENTS'!D20 -> 0.22723852 | E20: =('FINANCIAL STATEMENTS'!F20-'FINANCIAL STATEMENTS'!E20)/'FINANCIAL STATEMENTS'!E20 -> -0.014253211 | F20: =('FINANCIAL STATEMENTS'!G20-'FINANCIAL STATEMENTS'!F20)/'FINANCIAL STATEMENTS'!F20 -> 0.07201568
A22: EBITDA | B22: =('FINANCIAL STATEMENTS'!C22-'FINANCIAL STATEMENTS'!B22)/'FINANCIAL STATEMENTS'!B22 -> -0.008713358 | C22: =('FINANCIAL STATEMENTS'!D22-'FINANCIAL STATEMENTS'!C22)/'FINANCIAL STATEMENTS'!C22 -> 0.11793334 | D22: =('FINANCIAL STATEMENTS'!E22-'FINANCIAL STATEMENTS'!D22)/'FINANCIAL STATEMENTS'!D22 -> 0.058410029 | E22: =('FINANCIAL STATEMENTS'!F22-'FINANCIAL STATEMENTS'!E22)/'FINANCIAL STATEMENTS'!E22 -> 0.41549457 | F22: =('FINANCIAL STATEMENTS'!G22-'FINANCIAL STATEMENTS'!F22)/'FINANCIAL STATEMENTS'!F22 -> 0.15245117
A23: DEPRECIATION, AMORTISATION AND IMPAIRMENT EXPENSE | B23: =('FINANCIAL STATEMENTS'!C23-'FINANCIAL STATEMENTS'!B23)/'FINANCIAL STATEMENTS'!B23 -> 0.16940933 | C23: =('FINANCIAL STATEMENTS'!D23-'FINANCIAL STATEMENTS'!C23)/'FINANCIAL STATEMENTS'!C23 -> 0.321414 | D23: =('FINANCIAL STATEMENTS'!E23-'FINANCIAL STATEMENTS'!D23)/'FINANCIAL STATEMENTS'!D23 -> 0.14193847 | E23: =('FINANCIAL STATEMENTS'!F23-'FINANCIAL STATEMENTS'!E23)/'FINANCIAL STATEMENTS'!E23 -> 0.30247331 | F23: =('FINANCIAL STATEMENTS'!G23-'FINANCIAL STATEMENTS'!F23)/'FINANCIAL STATEMENTS'!F23 -> 0.066756598
A24: EBIT | B24: =('FINANCIAL STATEMENTS'!C24-'FINANCIAL STATEMENTS'!B24)/'FINANCIAL STATEMENTS'!B24 -> -0.023555441 | C24: =('FINANCIAL STATEMENTS'!D24-'FINANCIAL STATEMENTS'!C24)/'FINANCIAL STATEMENTS'!C24 -> 0.097627657 | D24: =('FINANCIAL STATEMENTS'!E24-'FINANCIAL STATEMENTS'!D24)/'FINANCIAL STATEMENTS'!D24 -> 0.048375134 | E24: =('FINANCIAL STATEMENTS'!F24-'FINANCIAL STATEMENTS'!E24)/'FINANCIAL STATEMENTS'!E24 -> 0.43028445 | F24: =('FINANCIAL STATEMENTS'!G24-'FINANCIAL STATEMENTS'!F24)/'FINANCIAL STATEMENTS'!F24 -> 0.16266302
A25: FINANCE COSTS | B25: =('FINANCIAL STATEMENTS'!C25-'FINANCIAL STATEMENTS'!B25)/'FINANCIAL STATEMENTS'!B25 -> 0.26791045 | C25: =('FINANCIAL STATEMENTS'!D25-'FINANCIAL STATEMENTS'!C25)/'FINANCIAL STATEMENTS'!C25 -> 0.60329606 | D25: =('FINANCIAL STATEMENTS'!E25-'FINANCIAL STATEMENTS'!D25)/'FINANCIAL STATEMENTS'!D25 -> 0.047356828 | E25: =('FINANCIAL STATEMENTS'!F25-'FINANCIAL STATEMENTS'!E25)/'FINANCIAL STATEMENTS'!E25 -> 0.032597266 | F25: =('FINANCIAL STATEMENTS'!G25-'FINANCIAL STATEMENTS'!F25)/'FINANCIAL STATEMENTS'!F25 -> 0.17854718
A26: EXCEPTIONAL ITEMS | B26: =('FINANCIAL STATEMENTS'!C26-'FINANCIAL STATEMENTS'!B26)/'FINANCIAL STATEMENTS'!B26 -> -0.99240891 | C26: =('FINANCIAL STATEMENTS'!D26-'FINANCIAL STATEMENTS'!C26)/'FINANCIAL STATEMENTS'!C26 -> -1 | F26: =('FINANCIAL STATEMENTS'!G26-'FINANCIAL STATEMENTS'!F26)/'FINANCIAL STATEMENTS'!F26 -> -3.8195804
A27: PROFIT BEFORE TAX | B27: =('FINANCIAL STATEMENTS'!C27-'FINANCIAL STATEMENTS'!B27)/'FINANCIAL STATEMENTS'!B27 -> 0.013695675 | C27: =('FINANCIAL STATEMENTS'!D27-'FINANCIAL STATEMENTS'!C27)/'FINANCIAL STATEMENTS'!C27 -> 0.092068679 | D27: =('FINANCIAL STATEMENTS'!E27-'FINANCIAL STATEMENTS'!D27)/'FINANCIAL STATEMENTS'!D27 -> 0.048392572 | E27: =('FINANCIAL STATEMENTS'!F27-'FINANCIAL STATEMENTS'!E27)/'FINANCIAL STATEMENTS'!E27 -> 0.44137505 | F27: =('FINANCIAL STATEMENTS'!G27-'FINANCIAL STATEMENTS'!F27)/'FINANCIAL STATEMENTS'!F27 -> 0.15062339
A29: TAX EXPENSE
A31: CURRENT TAX | B31: =('FINANCIAL STATEMENTS'!C31-'FINANCIAL STATEMENTS'!B31)/'FINANCIAL STATEMENTS'!B31 -> 0.01736064 | C31: =('FINANCIAL STATEMENTS'!D31-'FINANCIAL STATEMENTS'!C31)/'FINANCIAL STATEMENTS'!C31 -> 0.059938675 | D31: =('FINANCIAL STATEMENTS'!E31-'FINANCIAL STATEMENTS'!D31)/'FINANCIAL STATEMENTS'!D31 -> 0.064196413 | E31: =('FINANCIAL STATEMENTS'!F31-'FINANCIAL STATEMENTS'!E31)/'FINANCIAL STATEMENTS'!E31 -> 0.42947642 | F31: =('FINANCIAL STATEMENTS'!G31-'FINANCIAL STATEMENTS'!F31)/'FINANCIAL STATEMENTS'!F31 -> 0.11796805
A32: DEFERRED TAX | B32: =('FINANCIAL STATEMENTS'!C32-'FINANCIAL STATEMENTS'!B32)/'FINANCIAL STATEMENTS'!B32 -> -1.0036014 | C32: =('FINANCIAL STATEMENTS'!D32-'FINANCIAL STATEMENTS'!C32)/'FINANCIAL STATEMENTS'!C32 -> 14 | D32: =('FINANCIAL STATEMENTS'!E32-'FINANCIAL STATEMENTS'!D32)/'FINANCIAL STATEMENTS'!D32 -> -7.95 | E32: =('FINANCIAL STATEMENTS'!F32-'FINANCIAL STATEMENTS'!E32)/'FINANCIAL STATEMENTS'!E32 -> -0.96802558 | F32: =('FINANCIAL STATEMENTS'!G32-'FINANCIAL STATEMENTS'!F32)/'FINANCIAL STATEMENTS'!F32 -> -40.925
A33: NET TAX EXPENSE | B33: =('FINANCIAL STATEMENTS'!C33-'FINANCIAL STATEMENTS'!B33)/'FINANCIAL STATEMENTS'!B33 -> 0.11880834 | C33: =('FINANCIAL STATEMENTS'!D33-'FINANCIAL STATEMENTS'!C33)/'FINANCIAL STATEMENTS'!C33 -> 0.064397473 | D33: =('FINANCIAL STATEMENTS'!E33-'FINANCIAL STATEMENTS'!D33)/'FINANCIAL STATEMENTS'!D33 -> 0.028072021 | E33: =('FINANCIAL STATEMENTS'!F33-'FINANCIAL STATEMENTS'!E33)/'FINANCIAL STATEMENTS'!E33 -> 0.47206119 | F33: =('FINANCIAL STATEMENTS'!G33-'FINANCIAL STATEMENTS'!F33)/'FINANCIAL STATEMENTS'!F33 -> 0.14513353
A34: TAX RATE | B34: =('FINANCIAL STATEMENTS'!C34-'FINANCIAL STATEMENTS'!B34)/'FINANCIAL STATEMENTS'!B34 -> 0.10369252 | C34: =('FINANCIAL STATEMENTS'!D34-'FINANCIAL STATEMENTS'!C34)/'FINANCIAL STATEMENTS'!C34 -> -0.025338339 | D34: =('FINANCIAL STATEMENTS'!E34-'FINANCIAL STATEMENTS'!D34)/'FINANCIAL STATEMENTS'!D34 -> -0.019382579 | E34: =('FINANCIAL STATEMENTS'!F34-'FINANCIAL STATEMENTS'!E34)/'FINANCIAL STATEMENTS'!E34 -> 0.021289488 | F34: =('FINANCIAL STATEMENTS'!G34-'FINANCIAL STATEMENTS'!F34)/'FINANCIAL STATEMENTS'!F34 -> -0.0047711974
A36: TOTAL PROFIT FOR THE YEAR ( PROFIT AFTER TAX) | B36: =('FINANCIAL STATEMENTS'!C36-'FINANCIAL STATEMENTS'!B36)/'FINANCIAL STATEMENTS'!B36 -> -0.018300321 | C36: =('FINANCIAL STATEMENTS'!D36-'FINANCIAL STATEMENTS'!C36)/'FINANCIAL STATEMENTS'!C36 -> 0.10166812 | D36: =('FINANCIAL STATEMENTS'!E36-'FINANCIAL STATEMENTS'!D36)/'FINANCIAL STATEMENTS'!D36 -> 0.055203498 | E36: =('FINANCIAL STATEMENTS'!F36-'FINANCIAL STATEMENTS'!E36)/'FINANCIAL STATEMENTS'!E36 -> 0.4313543 | F36: =('FINANCIAL STATEMENTS'!G36-'FINANCIAL STATEMENTS'!F36)/'FINANCIAL STATEMENTS'!F36 -> 0.15246712
A38: OTHER COMPREHENSIVE INCOME
A39: ITEMS THAT WILL NOT BE RECLASSIFIED TO INCOME STATEMENT
A41: REMEASUREMENT OF DEFINED BENEFIT PLAN | B41: =('FINANCIAL STATEMENTS'!C41-'FINANCIAL STATEMENTS'!B41)/'FINANCIAL STATEMENTS'!B41 -> -0.93615591 | C41: =('FINANCIAL STATEMENTS'!D41-'FINANCIAL STATEMENTS'!C41)/'FINANCIAL STATEMENTS'!C41 -> 11.747368 | D41: =('FINANCIAL STATEMENTS'!E41-'FINANCIAL STATEMENTS'!D41)/'FINANCIAL STATEMENTS'!D41 -> -1.1601982 | E41: =('FINANCIAL STATEMENTS'!F41-'FINANCIAL STATEMENTS'!E41)/'FINANCIAL STATEMENTS'!E41 -> -14.804124 | F41: =('FINANCIAL STATEMENTS'!G41-'FINANCIAL STATEMENTS'!F41)/'FINANCIAL STATEMENTS'!F41 -> -0.4309186
A42: INCOME TAX RELATING TO ITEMS THAT WILL NOT RECLASSIFIED TO PROFIT OR LOSS | B42: =('FINANCIAL STATEMENTS'!C42-'FINANCIAL STATEMENTS'!B42)/'FINANCIAL STATEMENTS'!B42 -> -0.92207792 | C42: =('FINANCIAL STATEMENTS'!D42-'FINANCIAL STATEMENTS'!C42)/'FINANCIAL STATEMENTS'!C42 -> 11.708333 | D42: =('FINANCIAL STATEMENTS'!E42-'FINANCIAL STATEMENTS'!D42)/'FINANCIAL STATEMENTS'!D42 -> -1.1606557 | E42: =('FINANCIAL STATEMENTS'!F42-'FINANCIAL STATEMENTS'!E42)/'FINANCIAL STATEMENTS'!E42 -> -14.755102 | F42: =('FINANCIAL STATEMENTS'!G42-'FINANCIAL STATEMENTS'!F42)/'FINANCIAL STATEMENTS'!F42 -> -0.43026706
A43: TOTAL OTHER COMPREHENSIVE LOSS | B43: =('FINANCIAL STATEMENTS'!C43-'FINANCIAL STATEMENTS'!B43)/'FINANCIAL STATEMENTS'!B43 -> -0.93983051 | C43: =('FINANCIAL STATEMENTS'!D43-'FINANCIAL STATEMENTS'!C43)/'FINANCIAL STATEMENTS'!C43 -> 11.760563 | D43: =('FINANCIAL STATEMENTS'!E43-'FINANCIAL STATEMENTS'!D43)/'FINANCIAL STATEMENTS'!D43 -> -1.1600442 | E43: =('FINANCIAL STATEMENTS'!F43-'FINANCIAL STATEMENTS'!E43)/'FINANCIAL STATEMENTS'!E43 -> -14.82069 | F43: =('FINANCIAL STATEMENTS'!G43-'FINANCIAL STATEMENTS'!F43)/'FINANCIAL STATEMENTS'!F43 -> -0.43113772
A45: TOTAL COMPREHENSIVE INCOME FOR THE YEAR | B45: =('FINANCIAL STATEMENTS'!C45-'FINANCIAL STATEMENTS'!B45)/'FINANCIAL STATEMENTS'!B45 -> -0.0083224753 | C45: =('FINANCIAL STATEMENTS'!D45-'FINANCIAL STATEMENTS'!C45)/'FINANCIAL STATEMENTS'!C45 -> 0.09400879 | D45: =('FINANCIAL STATEMENTS'!E45-'FINANCIAL STATEMENTS'!D45)/'FINANCIAL STATEMENTS'!D45 -> 0.064515583 | E45: =('FINANCIAL STATEMENTS'!F45-'FINANCIAL STATEMENTS'!E45)/'FINANCIAL STATEMENTS'!E45 -> 0.41378324 | F45: =('FINANCIAL STATEMENTS'!G45-'FINANCIAL STATEMENTS'!F45)/'FINANCIAL STATEMENTS'!F45 -> 0.15903969
A47: EARNINGS PER EQUITY SHARE
A48: BASIC | B48: =('FINANCIAL STATEMENTS'!C49-'FINANCIAL STATEMENTS'!B49)/'FINANCIAL STATEMENTS'!B49 -> -0.01890272 | C48: =('FINANCIAL STATEMENTS'!D49-'FINANCIAL STATEMENTS'!C49)/'FINANCIAL STATEMENTS'!C49 -> 0.10197368 | D48: =('FINANCIAL STATEMENTS'!E49-'FINANCIAL STATEMENTS'!D49)/'FINANCIAL STATEMENTS'!D49 -> 0.054584222 | E48: =('FINANCIAL STATEMENTS'!F49-'FINANCIAL STATEMENTS'!E49)/'FINANCIAL STATEMENTS'!E49 -> 0.4310554 | F48: =('FINANCIAL STATEMENTS'!G49-'FINANCIAL STATEMENTS'!F49)/'FINANCIAL STATEMENTS'!F49 -> 0.15202034
A49: DILUTED | B49: =('FINANCIAL STATEMENTS'!C50-'FINANCIAL STATEMENTS'!B50)/'FINANCIAL STATEMENTS'!B50 -> -0.018911439 | C49: =('FINANCIAL STATEMENTS'!D50-'FINANCIAL STATEMENTS'!C50)/'FINANCIAL STATEMENTS'!C50 -> 0.10155148 | D49: =('FINANCIAL STATEMENTS'!E50-'FINANCIAL STATEMENTS'!D50)/'FINANCIAL STATEMENTS'!D50 -> 0.055057618 | E49: =('FINANCIAL STATEMENTS'!F50-'FINANCIAL STATEMENTS'!E50)/'FINANCIAL STATEMENTS'!E50 -> 0.43001618 | F49: =('FINANCIAL STATEMENTS'!G50-'FINANCIAL STATEMENTS'!F50)/'FINANCIAL STATEMENTS'!F50 -> 0.15077793
A52: BALANCE SHEET
A54: PARTICULARS(AMOUNT IN CRORES OF INR) | B54: 44286 | C54: 44651 | D54: 45016 | E54: 45382 | F54: 45747
A55: ASSETS
A57: NON CURRENT ASSETS
A58: PROPERTY , PLANT AND EQUIPMENT | B58: =('FINANCIAL STATEMENTS'!C60-'FINANCIAL STATEMENTS'!B60)/'FINANCIAL STATEMENTS'!B60 -> 0.18826343 | C58: =('FINANCIAL STATEMENTS'!D60-'FINANCIAL STATEMENTS'!C60)/'FINANCIAL STATEMENTS'!C60 -> 0.29255018 | D58: =('FINANCIAL STATEMENTS'!E60-'FINANCIAL STATEMENTS'!D60)/'FINANCIAL STATEMENTS'!D60 -> 0.091172313 | E58: =('FINANCIAL STATEMENTS'!F60-'FINANCIAL STATEMENTS'!E60)/'FINANCIAL STATEMENTS'!E60 -> 0.31434074 | F58: =('FINANCIAL STATEMENTS'!G60-'FINANCIAL STATEMENTS'!F60)/'FINANCIAL STATEMENTS'!F60 -> 0.10489278
...
