Workbook

Sheet FS & Trend Analysis
A2: Financial Statements of Hero Motor Corporation Ltd. | K2: Trend Analysis
A4: Income Statement | K4: Income Statement
A5: Particulars (Amount in Crores of INR) | B5: 42094 | C5: 42460 | D5: 42825 | E5: 43190 | F5: 43555 | G5: 43921 | H5: 44286 | I5: 44651 | K5: Particulars | L5: 42094 | M5: 42460 | N5: 42825 | O5: 43190 | P5: 43555 | Q5: 43921 | R5: 44286 | S5: 44651
A6: Revenue from Operations | B6: 29255.68 | C6: 30871.94 | D6: 30983.66 | E6: 33100.94 | F6: 33972.23 | G6: 29255.32 | H6: 30959.19 | I6: 29551.28 | K6: Revenue from Operations | L6: =B6/$B6 -> 1 | M6: =C6/$B6 -> 1.055246 | N6: =D6/$B6 -> 1.0590648 | O6: =E6/$B6 -> 1.1314364 | P6: =F6/$B6 -> 1.1612183 | Q6: =G6/$B6 -> 0.99998769 | R6: =H6/$B6 -> 1.0582284 | S6: =I6/$B6 -> 1.010104
A7: Other Income | B7: 492.11 | C7: 389.08 | D7: 521.95 | E7: 523.17 | F7: 686.73 | G7: 730.56 | H7: 557.9 | I7: 555.01 | K7: Other Income | L7: =B7/$B7 -> 1 | M7: =C7/$B7 -> 0.79063624 | N7: =D7/$B7 -> 1.0606368 | O7: =E7/$B7 -> 1.063116 | P7: =F7/$B7 -> 1.3954807 | Q7: =G7/$B7 -> 1.4845461 | R7: =H7/$B7 -> 1.1336896 | S7: =I7/$B7 -> 1.127817
A8: Total Income | B8: =SUM(B6:B7) -> 29747.79 | C8: =SUM(C6:C7) -> 31261.02 | D8: =SUM(D6:D7) -> 31505.61 | E8: =SUM(E6:E7) -> 33624.11 | F8: =SUM(F6:F7) -> 34658.96 | G8: =SUM(G6:G7) -> 29985.88 | H8: =SUM(H6:H7) -> 31517.09 | I8: =SUM(I6:I7) -> 30106.29 | K8: Total Income | L8: =B8/$B8 -> 1 | M8: =C8/$B8 -> 1.0508687 | N8: =D8/$B8 -> 1.0590908 | O8: =E8/$B8 -> 1.1303062 | P8: =F8/$B8 -> 1.1650936 | Q8: =G8/$B8 -> 1.0080036 | R8: =H8/$B8 -> 1.0594767 | S8: =I8/$B8 -> 1.0120513
A10: Expenses | K10: Expenses
A11: Raw Material | B11: 19715.3 | C11: 19313.15 | D11: 19116.08 | E11: 21885.82 | F11: 23444.42 | G11: 19830.95 | H11: 21743.61 | I11: 20920.36 | K11: Raw Material | L11: =B11/$B11 -> 1 | M11: =C11/$B11 -> 0.97960214 | N11: =D11/$B11 -> 0.96960635 | O11: =E11/$B11 -> 1.1100932 | P11: =F11/$B11 -> 1.1891485 | Q11: =G11/$B11 -> 1.005866 | R11: =H11/$B11 -> 1.10288 | S11: =I11/$B11 -> 1.0611231
A12: Excise Duty | B12: 1717.65 | C12: 2258.21 | D12: 2373.23 | E12: 642.57 | F12: 1.41 | G12: 1.35 | H12: 0 | I12: 0 | K12: Excise Duty | L12: =B12/$B12 -> 1 | M12: =C12/$B12 -> 1.3147091 | N12: =D12/$B12 -> 1.3816726 | O12: =E12/$B12 -> 0.37409833 | P12: =F12/$B12 -> 0.00082088901 | Q12: =G12/$B12 -> 0.00078595756 | R12: =H12/$B12 -> 0 | S12: =I12/$B12 -> 0
A13: Employee Costs | B13: 1178.72 | C13: 1343.06 | D13: 1432.49 | E13: 1583.71 | F13: 1778.03 | G13: 1889.32 | H13: 1951.02 | I13: 1995.78 | K13: Employee Costs | L13: =B13/$B13 -> 1 | M13: =C13/$B13 -> 1.1394224 | N13: =D13/$B13 -> 1.2152929 | O13: =E13/$B13 -> 1.3435846 | P13: =F13/$B13 -> 1.5084414 | Q13: =G13/$B13 -> 1.6028573 | R13: =H13/$B13 -> 1.6552023 | S13: =I13/$B13 -> 1.6931756
A14: Other Expenses | B14: 3292.01 | C14: 3575.27 | D14: 3485.89 | E14: 3663.79 | F14: 3729.94 | G14: 3472.78 | H14: 3165.05 | I14: 3190.37 | K14: Other Expenses | L14: =B14/$B14 -> 1 | M14: =C14/$B14 -> 1.0860447 | N14: =D14/$B14 -> 1.0588941 | O14: =E14/$B14 -> 1.112934 | P14: =F14/$B14 -> 1.1330281 | Q14: =G14/$B14 -> 1.0549117 | R14: =H14/$B14 -> 0.9614339 | S14: =I14/$B14 -> 0.96912525
A15: Total Expenses | B15: =SUM(B10:B14) -> 25903.68 | C15: =SUM(C10:C14) -> 26489.69 | D15: =SUM(D10:D14) -> 26407.69 | E15: =SUM(E10:E14) -> 27775.89 | F15: =SUM(F10:F14) -> 28953.8 | G15: =SUM(G10:G14) -> 25194.4 | H15: =SUM(H10:H14) -> 26859.68 | I15: =SUM(I10:I14) -> 26106.51 | K15: Total Expenses | L15: =B15/$B15 -> 1 | M15: =C15/$B15 -> 1.0226227 | N15: =D15/$B15 -> 1.0194571 | O15: =E15/$B15 -> 1.0722758 | P15: =F15/$B15 -> 1.1177485 | Q15: =G15/$B15 -> 0.97261856 | R15: =H15/$B15 -> 1.036906 | S15: =I15/$B15 -> 1.0078302
A17: EBITDA | B17: =B8-B15 -> 3844.11 | C17: =C8-C15 -> 4771.33 | D17: =D8-D15 -> 5097.92 | E17: =E8-E15 -> 5848.22 | F17: =F8-F15 -> 5705.16 | G17: =G8-G15 -> 4791.48 | H17: =H8-H15 -> 4657.41 | I17: =I8-I15 -> 3999.78 | K17: EBITDA | L17: =B17/$B17 -> 1 | M17: =C17/$B17 -> 1.2412054 | N17: =D17/$B17 -> 1.3261639 | O17: =E17/$B17 -> 1.5213456 | P17: =F17/$B17 -> 1.4841303 | Q17: =G17/$B17 -> 1.2464472 | R17: =H17/$B17 -> 1.2115704 | S17: =I17/$B17 -> 1.0404957
A18: Depreciation & Amortization | B18: 540.45 | C18: 447.01 | D18: 502.25 | E18: 574.98 | F18: 624.44 | G18: 845.76 | H18: 715.12 | I18: 689.52 | K18: Depreciation & Amortization | L18: =B18/$B18 -> 1 | M18: =C18/$B18 -> 0.82710704 | N18: =D18/$B18 -> 0.92931816 | O18: =E18/$B18 -> 1.0638912 | P18: =F18/$B18 -> 1.1554075 | Q18: =G18/$B18 -> 1.5649181 | R18: =H18/$B18 -> 1.3231936 | S18: =I18/$B18 -> 1.2758257
A19: EBIT | B19: =B17-B18 -> 3303.66 | C19: =C17-C18 -> 4324.32 | D19: =D17-D18 -> 4595.67 | E19: =E17-E18 -> 5273.24 | F19: =F17-F18 -> 5080.72 | G19: =G17-G18 -> 3945.72 | H19: =H17-H18 -> 3942.29 | I19: =I17-I18 -> 3310.26 | K19: EBIT | L19: =B19/$B19 -> 1 | M19: =C19/$B19 -> 1.3089483 | N19: =D19/$B19 -> 1.3910844 | O19: =E19/$B19 -> 1.5961812 | P19: =F19/$B19 -> 1.5379064 | Q19: =G19/$B19 -> 1.1943481 | R19: =H19/$B19 -> 1.1933098 | S19: =I19/$B19 -> 1.0019978
A20: Finance Expenses | B20: 11.7 | C20: 11.87 | D20: 27.28 | E20: 30.8 | F20: 37.18 | G20: 46.64 | H20: 46.41 | I20: 53.1 | K20: Finance Expenses | L20: =B20/$B20 -> 1 | M20: =C20/$B20 -> 1.0145299 | N20: =D20/$B20 -> 2.3316239 | O20: =E20/$B20 -> 2.6324786 | P20: =F20/$B20 -> 3.1777778 | Q20: =G20/$B20 -> 3.9863248 | R20: =H20/$B20 -> 3.9666667 | S20: =I20/$B20 -> 4.5384615
A21: PBT before profits of JVs | B21: =B19-B20 -> 3291.96 | C21: =C19-C20 -> 4312.45 | D21: =D19-D20 -> 4568.39 | E21: =E19-E20 -> 5242.44 | F21: =F19-F20 -> 5043.54 | G21: =G19-G20 -> 3899.08 | H21: =H19-H20 -> 3895.88 | I21: =I19-I20 -> 3257.16 | K21: PBT before profits of JVs | L21: =B21/$B21 -> 1 | M21: =C21/$B21 -> 1.3099947 | N21: =D21/$B21 -> 1.3877416 | O21: =E21/$B21 -> 1.5924981 | P21: =F21/$B21 -> 1.5320782 | Q21: =G21/$B21 -> 1.1844251 | R21: =H21/$B21 -> 1.183453 | S21: =I21/$B21 -> 0.98942879
A22: Add: Share of Profits of JVs | B22: 15.15 | C22: 39.46 | D22: 279.04 | E22: 51.43 | F22: 60.76 | G22: 34.63 | H22: -46.56 | I22: -199.05 | K22: Add: Share of Profits of JVs | L22: =B22/$B22 -> 1 | M22: =C22/$B22 -> 2.6046205 | N22: =D22/$B22 -> 18.418482 | O22: =E22/$B22 -> 3.3947195 | P22: =F22/$B22 -> 4.0105611 | Q22: =G22/$B22 -> 2.2858086 | R22: =H22/$B22 -> -3.0732673 | S22: =I22/$B22 -> -13.138614
A23: PBT & Exceptional Items | B23: =SUM(B21:B22) -> 3307.11 | C23: =SUM(C21:C22) -> 4351.91 | D23: =SUM(D21:D22) -> 4847.43 | E23: =SUM(E21:E22) -> 5293.87 | F23: =SUM(F21:F22) -> 5104.3 | G23: =SUM(G21:G22) -> 3933.71 | H23: =SUM(H21:H22) -> 3849.32 | I23: =SUM(I21:I22) -> 3058.11 | K23: PBT & Exceptional Items | L23: =B23/$B23 -> 1 | M23: =C23/$B23 -> 1.3159254 | N23: =D23/$B23 -> 1.4657601 | O23: =E23/$B23 -> 1.6007541 | P23: =F23/$B23 -> 1.5434322 | Q23: =G23/$B23 -> 1.1894706 | R23: =H23/$B23 -> 1.1639528 | S23: =I23/$B23 -> 0.92470768
A24: Exceptional Items | G24: 677.37 | K24: Exceptional Items
A25: PBT | B25: =B23+B24 -> 3307.11 | C25: =C23+C24 -> 4351.91 | D25: =D23+D24 -> 4847.43 | E25: =E23+E24 -> 5293.87 | F25: =F23+F24 -> 5104.3 | G25: =G23+G24 -> 4611.08 | H25: =H23+H24 -> 3849.32 | I25: =I23+I24 -> 3058.11 | K25: PBT | L25: =B25/$B25 -> 1 | M25: =C25/$B25 -> 1.3159254 | N25: =D25/$B25 -> 1.4657601 | O25: =E25/$B25 -> 1.6007541 | P25: =F25/$B25 -> 1.5434322 | Q25: =G25/$B25 -> 1.3942929 | R25: =H25/$B25 -> 1.1639528 | S25: =I25/$B25 -> 0.92470768
A26: Tax | B26: 943.45 | C26: 1262.24 | D26: 1339.1 | E26: 1569.93 | F26: 1637.95 | G26: 951.67 | H26: 913.27 | I26: 729.06 | K26: Tax | L26: =B26/$B26 -> 1 | M26: =C26/$B26 -> 1.3378981 | N26: =D26/$B26 -> 1.4193651 | O26: =E26/$B26 -> 1.664031 | P26: =F26/$B26 -> 1.736128 | Q26: =G26/$B26 -> 1.0087127 | R26: =H26/$B26 -> 0.96801102 | S26: =I26/$B26 -> 0.77275955
A27: PAT | B27: =B25-B26 -> 2363.66 | C27: =C25-C26 -> 3089.67 | D27: =D25-D26 -> 3508.33 | E27: =E25-E26 -> 3723.94 | F27: =F25-F26 -> 3466.35 | G27: =G25-G26 -> 3659.41 | H27: =H25-H26 -> 2936.05 | I27: =I25-I26 -> 2329.05 | K27: PAT | L27: =B27/$B27 -> 1 | M27: =C27/$B27 -> 1.307155 | N27: =D27/$B27 -> 1.4842786 | O27: =E27/$B27 -> 1.5754973 | P27: =F27/$B27 -> 1.466518 | Q27: =G27/$B27 -> 1.5481964 | R27: =H27/$B27 -> 1.2421626 | S27: =I27/$B27 -> 0.98535745
A28: Less: Share of Minority Interest | B28: -1.04 | C28: -4.11 | D28: -37.97 | E28: 1.77 | F28: 22.66 | G28: 21.3 | H28: 18.3 | I28: 12.17 | K28: Less: Share of Minority Interest | L28: =B28/$B28 -> 1 | M28: =C28/$B28 -> 3.9519231 | N28: =D28/$B28 -> 36.509615 | O28: =E28/$B28 -> -1.7019231 | P28: =F28/$B28 -> -21.788462 | Q28: =G28/$B28 -> -20.480769 | R28: =H28/$B28 -> -17.596154 | S28: =I28/$B28 -> -11.701923
A29: PAT for Equity Shareholders | B29: =B27-B28 -> 2364.7 | C29: =C27-C28 -> 3093.78 | D29: =D27-D28 -> 3546.3 | E29: =E27-E28 -> 3722.17 | F29: =F27-F28 -> 3443.69 | G29: =G27-G28 -> 3638.11 | H29: =H27-H28 -> 2917.75 | I29: =I27-I28 -> 2316.88 | K29: PAT for Equity Shareholders | L29: =B29/$B29 -> 1 | M29: =C29/$B29 -> 1.3083182 | N29: =D29/$B29 -> 1.4996828 | O29: =E29/$B29 -> 1.5740559 | P29: =F29/$B29 -> 1.4562904 | Q29: =G29/$B29 -> 1.5385081 | R29: =H29/$B29 -> 1.2338774 | S29: =I29/$B29 -> 0.97977756
A30: Dividend | B30: 1198.12 | C30: 1397.81 | D30: 1737.34 | E30: 1697.5 | F30: 1897.35 | G30: 1937 | H30: 1398.46 | I30: =85*I37/2 -> 1698.3 | K30: Dividend | L30: =B30/$B30 -> 1 | M30: =C30/$B30 -> 1.1666694 | N30: =D30/$B30 -> 1.4500551 | O30: =E30/$B30 -> 1.416803 | P30: =F30/$B30 -> 1.583606 | Q30: =G30/$B30 -> 1.6166995 | R30: =H30/$B30 -> 1.167212 | S30: =I30/$B30 -> 1.4174707
A31: Tax Rate (%) | B31: =B26/B25 -> 0.28527929 | C31: =C26/C25 -> 0.29004276 | D31: =D26/D25 -> 0.27624948 | E31: =E26/E25 -> 0.29655621 | F31: =F26/F25 -> 0.32089611 | G31: =G26/G25 -> 0.20638766 | H31: =H26/H25 -> 0.23725489 | I31: =I26/I25 -> 0.23840215
A34: Balance Sheet | K34: Balance Sheet
A35: Particulars | B35: 42094 | C35: 42460 | D35: 42825 | E35: 43190 | F35: 43555 | G35: 43921 | H35: 44286 | I35: 44651 | K35: Particulars | L35: 42094 | M35: 42460 | N35: 42825 | O35: 43190 | P35: 43555 | Q35: 43921 | R35: 44286 | S35: 44651
A36: Equity & Liabilities | K36: Equity & Liabilities
A37: Equity Share Capital | B37: 39.94 | C37: 39.94 | D37: 39.94 | E37: 39.94 | F37: 39.95 | G37: 39.95 | H37: 39.96 | I37: 39.96 | K37: Equity Share Capital | L37: =B37/$B37 -> 1 | M37: =C37/$B37 -> 1 | N37: =D37/$B37 -> 1 | O37: =E37/$B37 -> 1 | P37: =F37/$B37 -> 1.0002504 | Q37: =G37/$B37 -> 1.0002504 | R37: =H37/$B37 -> 1.0005008 | S37: =I37/$B37 -> 1.0005008
A38: Other Equity | B38: 6500.06 | C38: 7912.74 | D38: 10275.57 | E38: 11931.52 | F38: 13080.46 | G38: 14366.33 | H38: 15376.46 | I38: 15806.69 | K38: Other Equity | L38: =B38/$B38 -> 1 | M38: =C38/$B38 -> 1.2173334 | N38: =D38/$B38 -> 1.5808423 | O38: =E38/$B38 -> 1.8356015 | P38: =F38/$B38 -> 2.0123599 | Q38: =G38/$B38 -> 2.2101842 | R38: =H38/$B38 -> 2.3655874 | S38: =I38/$B38 -> 2.431776
A39: Total Equity | B39: =SUM(B37:B38) -> 6540 | C39: =SUM(C37:C38) -> 7952.68 | D39: =SUM(D37:D38) -> 10315.51 | E39: =SUM(E37:E38) -> 11971.46 | F39: =SUM(F37:F38) -> 13120.41 | G39: =SUM(G37:G38) -> 14406.28 | H39: =SUM(H37:H38) -> 15416.42 | I39: =SUM(I37:I38) -> 15846.65 | K39: Total Equity | L39: =B39/$B39 -> 1 | M39: =C39/$B39 -> 1.2160061 | N39: =D39/$B39 -> 1.5772951 | O39: =E39/$B39 -> 1.8304985 | P39: =F39/$B39 -> 2.0061789 | Q39: =G39/$B39 -> 2.2027951 | R39: =H39/$B39 -> 2.3572508 | S39: =I39/$B39 -> 2.4230352
A40: Non-Controlling Interest | B40: 18.54 | C40: 53.62 | D40: 67.38 | E40: 93.21 | F40: 116.11 | G40: 140.6 | H40: 143.19 | I40: 148.05 | K40: Non-Controlling Interest | L40: =B40/$B40 -> 1 | M40: =C40/$B40 -> 2.8921251 | N40: =D40/$B40 -> 3.6343042 | O40: =E40/$B40 -> 5.0275081 | P40: =F40/$B40 -> 6.2626753 | Q40: =G40/$B40 -> 7.583603 | R40: =H40/$B40 -> 7.723301 | S40: =I40/$B40 -> 7.9854369
A42: Non-Current Liabilities | K42: Non-Current Liabilities
A43: Borrowings | B43: 12 | C43: 145.98 | D43: 207.9 | E43: 149.63 | F43: 124.84 | G43: 44.02 | H43: 45.18 | I43: 36.17 | K43: Borrowings | L43: =B43/$B43 -> 1 | M43: =C43/$B43 -> 12.165 | N43: =D43/$B43 -> 17.325 | O43: =E43/$B43 -> 12.469167 | P43: =F43/$B43 -> 10.403333 | Q43: =G43/$B43 -> 3.6683333 | R43: =H43/$B43 -> 3.765 | S43: =I43/$B43 -> 3.0141667
A44: Lease Liabilities | B44: 0 | C44: 0 | D44: 0 | E44: 0 | F44: 0 | G44: 207.62 | H44: 212.42 | I44: 215.51 | K44: Lease Liabilities | L44: =B44/$B44 -> #DIV/0! | M44: =C44/$B44 -> #DIV/0! | N44: =D44/$B44 -> #DIV/0! | O44: =E44/$B44 -> #DIV/0! | P44: =F44/$B44 -> #DIV/0! | Q44: =G44/$B44 -> #DIV/0! | R44: =H44/$B44 -> #DIV/0! | S44: =I44/$B44 -> #DIV/0!
A45: Other financial liabilities | B45: 0 | C45: 0 | D45: 0 | E45: 0 | F45: 0 | G45: 0 | H45: 0 | I45: 155.04 | K45: Other financial liabilities | L45: =B45/$B45 -> #DIV/0! | M45: =C45/$B45 -> #DIV/0! | N45: =D45/$B45 -> #DIV/0! | O45: =E45/$B45 -> #DIV/0! | P45: =F45/$B45 -> #DIV/0! | Q45: =G45/$B45 -> #DIV/0! | R45: =H45/$B45 -> #DIV/0! | S45: =I45/$B45 -> #DIV/0!
A46: Provisions | B46: 0 | C46: 0 | D46: 0 | E46: 0 | F46: 0 | G46: 0 | H46: 0 | I46: 181.13 | K46: Provisions | L46: =B46/$B46 -> #DIV/0! | M46: =C46/$B46 -> #DIV/0! | N46: =D46/$B46 -> #DIV/0! | O46: =E46/$B46 -> #DIV/0! | P46: =F46/$B46 -> #DIV/0! | Q46: =G46/$B46 -> #DIV/0! | R46: =H46/$B46 -> #DIV/0! | S46: =I46/$B46 -> #DIV/0!
A47: Deferred Tax Liabilities | B47: 0 | C47: 227.79 | D47: 468.9 | E47: 581.89 | F47: 612.88 | G47: 472.58 | H47: 452.74 | I47: 378.21 | K47: Deferred Tax Liabilities | L47: =B47/$B47 -> #DIV/0! | M47: =C47/$B47 -> #DIV/0! | N47: =D47/$B47 -> #DIV/0! | O47: =E47/$B47 -> #DIV/0! | P47: =F47/$B47 -> #DIV/0! | Q47: =G47/$B47 -> #DIV/0! | R47: =H47/$B47 -> #DIV/0! | S47: =I47/$B47 -> #DIV/0!
...

Sheet Common Size FS
A2: Common Size statement
A4: Income Statement
A5: Particulars | B5: 42094 | C5: 42460 | D5: 42825 | E5: 43190 | F5: 43555 | G5: 43921 | H5: 44286 | I5: 44651
A6: Revenue from Operations | B6: ='FS & Trend Analysis'!B6/'FS & Trend Analysis'!B$6 -> 1 | C6: ='FS & Trend Analysis'!C6/'FS & Trend Analysis'!C$6 -> 1 | D6: ='FS & Trend Analysis'!D6/'FS & Trend Analysis'!D$6 -> 1 | E6: ='FS & Trend Analysis'!E6/'FS & Trend Analysis'!E$6 -> 1 | F6: ='FS & Trend Analysis'!F6/'FS & Trend Analysis'!F$6 -> 1 | G6: ='FS & Trend Analysis'!G6/'FS & Trend Analysis'!G$6 -> 1 | H6: ='FS & Trend Analysis'!H6/'FS & Trend Analysis'!H$6 -> 1 | I6: ='FS & Trend Analysis'!I6/'FS & Trend Analysis'!I$6 -> 1
A7: Other Income | B7: ='FS & Trend Analysis'!B7/'FS & Trend Analysis'!B$6 -> 0.016821007 | C7: ='FS & Trend Analysis'!C7/'FS & Trend Analysis'!C$6 -> 0.01260303 | D7: ='FS & Trend Analysis'!D7/'FS & Trend Analysis'!D$6 -> 0.016845976 | E7: ='FS & Trend Analysis'!E7/'FS & Trend Analysis'!E$6 -> 0.015805291 | F7: ='FS & Trend Analysis'!F7/'FS & Trend Analysis'!F$6 -> 0.020214452 | G7: ='FS & Trend Analysis'!G7/'FS & Trend Analysis'!G$6 -> 0.024971868 | H7: ='FS & Trend Analysis'!H7/'FS & Trend Analysis'!H$6 -> 0.018020497 | I7: ='FS & Trend Analysis'!I7/'FS & Trend Analysis'!I$6 -> 0.018781251
A8: Total Income | B8: ='FS & Trend Analysis'!B8/'FS & Trend Analysis'!B$6 -> 1.016821 | C8: ='FS & Trend Analysis'!C8/'FS & Trend Analysis'!C$6 -> 1.012603 | D8: ='FS & Trend Analysis'!D8/'FS & Trend Analysis'!D$6 -> 1.016846 | E8: ='FS & Trend Analysis'!E8/'FS & Trend Analysis'!E$6 -> 1.0158053 | F8: ='FS & Trend Analysis'!F8/'FS & Trend Analysis'!F$6 -> 1.0202145 | G8: ='FS & Trend Analysis'!G8/'FS & Trend Analysis'!G$6 -> 1.0249719 | H8: ='FS & Trend Analysis'!H8/'FS & Trend Analysis'!H$6 -> 1.0180205 | I8: ='FS & Trend Analysis'!I8/'FS & Trend Analysis'!I$6 -> 1.0187813
A10: Expenses
A11: Raw Material | B11: ='FS & Trend Analysis'!B11/'FS & Trend Analysis'!B$6 -> 0.67389649 | C11: ='FS & Trend Analysis'!C11/'FS & Trend Analysis'!C$6 -> 0.62558913 | D11: ='FS & Trend Analysis'!D11/'FS & Trend Analysis'!D$6 -> 0.61697295 | E11: ='FS & Trend Analysis'!E11/'FS & Trend Analysis'!E$6 -> 0.66118424 | F11: ='FS & Trend Analysis'!F11/'FS & Trend Analysis'!F$6 -> 0.69010542 | G11: ='FS & Trend Analysis'!G11/'FS & Trend Analysis'!G$6 -> 0.67785791 | H11: ='FS & Trend Analysis'!H11/'FS & Trend Analysis'!H$6 -> 0.70233136 | I11: ='FS & Trend Analysis'!I11/'FS & Trend Analysis'!I$6 -> 0.70793414
A12: Excise Duty | B12: ='FS & Trend Analysis'!B12/'FS & Trend Analysis'!B$6 -> 0.058711676 | C12: ='FS & Trend Analysis'!C12/'FS & Trend Analysis'!C$6 -> 0.073147654 | D12: ='FS & Trend Analysis'!D12/'FS & Trend Analysis'!D$6 -> 0.07659618 | E12: ='FS & Trend Analysis'!E12/'FS & Trend Analysis'!E$6 -> 0.01941244 | F12: ='FS & Trend Analysis'!F12/'FS & Trend Analysis'!F$6 -> 4.1504488e-05 | G12: ='FS & Trend Analysis'!G12/'FS & Trend Analysis'!G$6 -> 4.6145453e-05 | H12: ='FS & Trend Analysis'!H12/'FS & Trend Analysis'!H$6 -> 0 | I12: ='FS & Trend Analysis'!I12/'FS & Trend Analysis'!I$6 -> 0
A13: Employee Costs | B13: ='FS & Trend Analysis'!B13/'FS & Trend Analysis'!B$6 -> 0.040290296 | C13: ='FS & Trend Analysis'!C13/'FS & Trend Analysis'!C$6 -> 0.043504231 | D13: ='FS & Trend Analysis'!D13/'FS & Trend Analysis'!D$6 -> 0.046233724 | E13: ='FS & Trend Analysis'!E13/'FS & Trend Analysis'!E$6 -> 0.047844865 | F13: ='FS & Trend Analysis'!F13/'FS & Trend Analysis'!F$6 -> 0.052337748 | G13: ='FS & Trend Analysis'!G13/'FS & Trend Analysis'!G$6 -> 0.064580391 | H13: ='FS & Trend Analysis'!H13/'FS & Trend Analysis'!H$6 -> 0.063019091 | I13: ='FS & Trend Analysis'!I13/'FS & Trend Analysis'!I$6 -> 0.067536161
A14: Other Expenses | B14: ='FS & Trend Analysis'!B14/'FS & Trend Analysis'!B$6 -> 0.1125255 | C14: ='FS & Trend Analysis'!C14/'FS & Trend Analysis'!C$6 -> 0.1158097 | D14: ='FS & Trend Analysis'!D14/'FS & Trend Analysis'!D$6 -> 0.11250737 | E14: ='FS & Trend Analysis'!E14/'FS & Trend Analysis'!E$6 -> 0.11068538 | F14: ='FS & Trend Analysis'!F14/'FS & Trend Analysis'!F$6 -> 0.10979379 | G14: ='FS & Trend Analysis'!G14/'FS & Trend Analysis'!G$6 -> 0.11870593 | H14: ='FS & Trend Analysis'!H14/'FS & Trend Analysis'!H$6 -> 0.10223297 | I14: ='FS & Trend Analysis'!I14/'FS & Trend Analysis'!I$6 -> 0.10796047
A15: Total Expenses | B15: ='FS & Trend Analysis'!B15/'FS & Trend Analysis'!B$6 -> 0.88542396 | C15: ='FS & Trend Analysis'!C15/'FS & Trend Analysis'!C$6 -> 0.85805071 | D15: ='FS & Trend Analysis'!D15/'FS & Trend Analysis'!D$6 -> 0.85231022 | E15: ='FS & Trend Analysis'!E15/'FS & Trend Analysis'!E$6 -> 0.83912693 | F15: ='FS & Trend Analysis'!F15/'FS & Trend Analysis'!F$6 -> 0.85227846 | G15: ='FS & Trend Analysis'!G15/'FS & Trend Analysis'!G$6 -> 0.86119037 | H15: ='FS & Trend Analysis'!H15/'FS & Trend Analysis'!H$6 -> 0.86758342 | I15: ='FS & Trend Analysis'!I15/'FS & Trend Analysis'!I$6 -> 0.88343077
A17: EBITDA | B17: ='FS & Trend Analysis'!B17/'FS & Trend Analysis'!B$6 -> 0.13139705 | C17: ='FS & Trend Analysis'!C17/'FS & Trend Analysis'!C$6 -> 0.15455232 | D17: ='FS & Trend Analysis'!D17/'FS & Trend Analysis'!D$6 -> 0.16453576 | E17: ='FS & Trend Analysis'!E17/'FS & Trend Analysis'!E$6 -> 0.17667837 | F17: ='FS & Trend Analysis'!F17/'FS & Trend Analysis'!F$6 -> 0.16793599 | G17: ='FS & Trend Analysis'!G17/'FS & Trend Analysis'!G$6 -> 0.16378149 | H17: ='FS & Trend Analysis'!H17/'FS & Trend Analysis'!H$6 -> 0.15043708 | I17: ='FS & Trend Analysis'!I17/'FS & Trend Analysis'!I$6 -> 0.13535048
A18: Depreciation & Amortization | B18: ='FS & Trend Analysis'!B18/'FS & Trend Analysis'!B$6 -> 0.018473336 | C18: ='FS & Trend Analysis'!C18/'FS & Trend Analysis'!C$6 -> 0.014479492 | D18: ='FS & Trend Analysis'!D18/'FS & Trend Analysis'!D$6 -> 0.016210157 | E18: ='FS & Trend Analysis'!E18/'FS & Trend Analysis'!E$6 -> 0.017370504 | F18: ='FS & Trend Analysis'!F18/'FS & Trend Analysis'!F$6 -> 0.018380895 | G18: ='FS & Trend Analysis'!G18/'FS & Trend Analysis'!G$6 -> 0.028909614 | H18: ='FS & Trend Analysis'!H18/'FS & Trend Analysis'!H$6 -> 0.023098796 | I18: ='FS & Trend Analysis'!I18/'FS & Trend Analysis'!I$6 -> 0.023332999
A19: EBIT | B19: ='FS & Trend Analysis'!B19/'FS & Trend Analysis'!B$6 -> 0.11292371 | C19: ='FS & Trend Analysis'!C19/'FS & Trend Analysis'!C$6 -> 0.14007283 | D19: ='FS & Trend Analysis'!D19/'FS & Trend Analysis'!D$6 -> 0.1483256 | E19: ='FS & Trend Analysis'!E19/'FS & Trend Analysis'!E$6 -> 0.15930786 | F19: ='FS & Trend Analysis'!F19/'FS & Trend Analysis'!F$6 -> 0.14955509 | G19: ='FS & Trend Analysis'!G19/'FS & Trend Analysis'!G$6 -> 0.13487188 | H19: ='FS & Trend Analysis'!H19/'FS & Trend Analysis'!H$6 -> 0.12733828 | I19: ='FS & Trend Analysis'!I19/'FS & Trend Analysis'!I$6 -> 0.11201748
A20: Finance Expenses | B20: ='FS & Trend Analysis'!B20/'FS & Trend Analysis'!B$6 -> 0.00039992234 | C20: ='FS & Trend Analysis'!C20/'FS & Trend Analysis'!C$6 -> 0.00038449155 | D20: ='FS & Trend Analysis'!D20/'FS & Trend Analysis'!D$6 -> 0.00088046409 | E20: ='FS & Trend Analysis'!E20/'FS & Trend Analysis'!E$6 -> 0.00093048717 | F20: ='FS & Trend Analysis'!F20/'FS & Trend Analysis'!F$6 -> 0.0010944233 | G20: ='FS & Trend Analysis'!G20/'FS & Trend Analysis'!G$6 -> 0.00159424 | H20: ='FS & Trend Analysis'!H20/'FS & Trend Analysis'!H$6 -> 0.0014990702 | I20: ='FS & Trend Analysis'!I20/'FS & Trend Analysis'!I$6 -> 0.0017968765
A21: PBT before profits of JVs | B21: ='FS & Trend Analysis'!B21/'FS & Trend Analysis'!B$6 -> 0.11252379 | C21: ='FS & Trend Analysis'!C21/'FS & Trend Analysis'!C$6 -> 0.13968834 | D21: ='FS & Trend Analysis'!D21/'FS & Trend Analysis'!D$6 -> 0.14744514 | E21: ='FS & Trend Analysis'!E21/'FS & Trend Analysis'!E$6 -> 0.15837738 | F21: ='FS & Trend Analysis'!F21/'FS & Trend Analysis'!F$6 -> 0.14846067 | G21: ='FS & Trend Analysis'!G21/'FS & Trend Analysis'!G$6 -> 0.13327764 | H21: ='FS & Trend Analysis'!H21/'FS & Trend Analysis'!H$6 -> 0.12583921 | I21: ='FS & Trend Analysis'!I21/'FS & Trend Analysis'!I$6 -> 0.11022061
A22: Add: Share of Profits of JVs | B22: ='FS & Trend Analysis'!B22/'FS & Trend Analysis'!B$6 -> 0.00051784816 | C22: ='FS & Trend Analysis'!C22/'FS & Trend Analysis'!C$6 -> 0.0012781834 | D22: ='FS & Trend Analysis'!D22/'FS & Trend Analysis'!D$6 -> 0.0090060374 | E22: ='FS & Trend Analysis'!E22/'FS & Trend Analysis'!E$6 -> 0.0015537323 | F22: ='FS & Trend Analysis'!F22/'FS & Trend Analysis'!F$6 -> 0.0017885196 | G22: ='FS & Trend Analysis'!G22/'FS & Trend Analysis'!G$6 -> 0.0011837163 | H22: ='FS & Trend Analysis'!H22/'FS & Trend Analysis'!H$6 -> -0.0015039153 | I22: ='FS & Trend Analysis'!I22/'FS & Trend Analysis'!I$6 -> -0.0067357488
A23: PBT & Exceptional Items | B23: ='FS & Trend Analysis'!B23/'FS & Trend Analysis'!B$6 -> 0.11304164 | C23: ='FS & Trend Analysis'!C23/'FS & Trend Analysis'!C$6 -> 0.14096652 | D23: ='FS & Trend Analysis'!D23/'FS & Trend Analysis'!D$6 -> 0.15645117 | E23: ='FS & Trend Analysis'!E23/'FS & Trend Analysis'!E$6 -> 0.15993111 | F23: ='FS & Trend Analysis'!F23/'FS & Trend Analysis'!F$6 -> 0.15024919 | G23: ='FS & Trend Analysis'!G23/'FS & Trend Analysis'!G$6 -> 0.13446136 | H23: ='FS & Trend Analysis'!H23/'FS & Trend Analysis'!H$6 -> 0.12433529 | I23: ='FS & Trend Analysis'!I23/'FS & Trend Analysis'!I$6 -> 0.10348486
... A30: Dividend | B30: ='FS & Trend Analysis'!B30/'FS & Trend Analysis'!B$6 -> 0.040953415 | C30: ='FS & Trend Analysis'!C30/'FS & Trend Analysis'!C$6 -> 0.045277686 | D30: ='FS & Trend Analysis'!D30/'FS & Trend Analysis'!D$6 -> 0.056072782 | E30: ='FS & Trend Analysis'!E30/'FS & Trend Analysis'!E$6 -> 0.051282532 | F30: ='FS & Trend Analysis'!F30/'FS & Trend Analysis'!F$6 -> 0.055850028 | G30: ='FS & Trend Analysis'!G30/'FS & Trend Analysis'!G$6 -> 0.06621018 | H30: ='FS & Trend Analysis'!H30/'FS & Trend Analysis'!H$6 -> 0.045171078 | I30: ='FS & Trend Analysis'!I30/'FS & Trend Analysis'!I$6 -> 0.057469592
A33: Balance Sheet
A34: Particulars | B34: 42094 | C34: 42460 | D34: 42825 | E34: 43190 | F34: 43555 | G34: 43921 | H34: 44286 | I34: 44651
A35: Equity & Liabilities
A36: Equity Share Capital | B36: ='FS & Trend Analysis'!B37/'FS & Trend Analysis'!B$60 -> 0.0037487036 | C36: ='FS & Trend Analysis'!C37/'FS & Trend Analysis'!C$60 -> 0.0031519054 | D36: ='FS & Trend Analysis'!D37/'FS & Trend Analysis'!D$60 -> 0.0026084117 | E36: ='FS & Trend Analysis'!E37/'FS & Trend Analysis'!E$60 -> 0.0022958338 | F36: ='FS & Trend Analysis'!F37/'FS & Trend Analysis'!F$60 -> 0.0021589506 | G36: ='FS & Trend Analysis'!G37/'FS & Trend Analysis'!G$60 -> 0.0020305915 | H36: ='FS & Trend Analysis'!H37/'FS & Trend Analysis'!H$60 -> 0.001730163 | I36: ='FS & Trend Analysis'!I37/'FS & Trend Analysis'!I$60 -> 0.0017777074
A37: Other Equity | B37: ='FS & Trend Analysis'!B38/'FS & Trend Analysis'!B$60 -> 0.61008508 | C37: ='FS & Trend Analysis'!C38/'FS & Trend Analysis'!C$60 -> 0.62444187 | D37: ='FS & Trend Analysis'!D38/'FS & Trend Analysis'!D$60 -> 0.67107955 | E37: ='FS & Trend Analysis'!E38/'FS & Trend Analysis'!E$60 -> 0.68584843 | F37: ='FS & Trend Analysis'!F38/'FS & Trend Analysis'!F$60 -> 0.7068853 | G37: ='FS & Trend Analysis'!G38/'FS & Trend Analysis'!G$60 -> 0.73021647 | H37: ='FS & Trend Analysis'!H38/'FS & Trend Analysis'!H$60 -> 0.66576031 | I37: ='FS & Trend Analysis'!I38/'FS & Trend Analysis'!I$60 -> 0.70319494
A38: Total Equity | B38: ='FS & Trend Analysis'!B39/'FS & Trend Analysis'!B$60 -> 0.61383379 | C38: ='FS & Trend Analysis'!C39/'FS & Trend Analysis'!C$60 -> 0.62759377 | D38: ='FS & Trend Analysis'!D39/'FS & Trend Analysis'!D$60 -> 0.67368796 | E38: ='FS & Trend Analysis'!E39/'FS & Trend Analysis'!E$60 -> 0.68814427 | F38: ='FS & Trend Analysis'!F39/'FS & Trend Analysis'!F$60 -> 0.70904425 | G38: ='FS & Trend Analysis'!G39/'FS & Trend Analysis'!G$60 -> 0.73224706 | H38: ='FS & Trend Analysis'!H39/'FS & Trend Analysis'!H$60 -> 0.66749047 | I38: ='FS & Trend Analysis'!I39/'FS & Trend Analysis'!I$60 -> 0.70497264
A39: Non-Controlling Interest | B39: ='FS & Trend Analysis'!B40/'FS & Trend Analysis'!B$60 -> 0.0017401343 | C39: ='FS & Trend Analysis'!C40/'FS & Trend Analysis'!C$60 -> 0.0042314764 | D39: ='FS & Trend Analysis'!D40/'FS & Trend Analysis'!D$60 -> 0.0044004702 | E39: ='FS & Trend Analysis'!E40/'FS & Trend Analysis'!E$60 -> 0.0053579035 | F39: ='FS & Trend Analysis'!F40/'FS & Trend Analysis'!F$60 -> 0.0062747374 | G39: ='FS & Trend Analysis'!G40/'FS & Trend Analysis'!G$60 -> 0.0071464623 | H39: ='FS & Trend Analysis'!H40/'FS & Trend Analysis'!H$60 -> 0.0061997507 | I39: ='FS & Trend Analysis'!I40/'FS & Trend Analysis'!I$60 -> 0.0065863258
A41: Non-Current Liabilities
A42: Borrowings | B42: ='FS & Trend Analysis'!B43/'FS & Trend Analysis'!B$60 -> 0.0011263005 | C42: ='FS & Trend Analysis'!C43/'FS & Trend Analysis'!C$60 -> 0.011520159 | D42: ='FS & Trend Analysis'!D43/'FS & Trend Analysis'!D$60 -> 0.013577586 | E42: ='FS & Trend Analysis'!E43/'FS & Trend Analysis'!E$60 -> 0.0086010417 | F42: ='FS & Trend Analysis'!F43/'FS & Trend Analysis'!F$60 -> 0.0067465181 | G42: ='FS & Trend Analysis'!G43/'FS & Trend Analysis'!G$60 -> 0.0022374628 | H42: ='FS & Trend Analysis'!H43/'FS & Trend Analysis'!H$60 -> 0.0019561753 | I42: ='FS & Trend Analysis'!I43/'FS & Trend Analysis'!I$60 -> 0.001609101
A43: Lease Liabilities | B43: ='FS & Trend Analysis'!B44/'FS & Trend Analysis'!B$60 -> 0 | C43: ='FS & Trend Analysis'!C44/'FS & Trend Analysis'!C$60 -> 0 | D43: ='FS & Trend Analysis'!D44/'FS & Trend Analysis'!D$60 -> 0 | E43: ='FS & Trend Analysis'!E44/'FS & Trend Analysis'!E$60 -> 0 | F43: ='FS & Trend Analysis'!F44/'FS & Trend Analysis'!F$60 -> 0 | G43: ='FS & Trend Analysis'!G44/'FS & Trend Analysis'!G$60 -> 0.010552977 | H43: ='FS & Trend Analysis'!H44/'FS & Trend Analysis'!H$60 -> 0.0091972278 | I43: ='FS & Trend Analysis'!I44/'FS & Trend Analysis'!I$60 -> 0.0095874304
A44: Other financial liabilities | B44: ='FS & Trend Analysis'!B45/'FS & Trend Analysis'!B$60 -> 0 | C44: ='FS & Trend Analysis'!C45/'FS & Trend Analysis'!C$60 -> 0 | D44: ='FS & Trend Analysis'!D45/'FS & Trend Analysis'!D$60 -> 0 | E44: ='FS & Trend Analysis'!E45/'FS & Trend Analysis'!E$60 -> 0 | F44: ='FS & Trend Analysis'!F45/'FS & Trend Analysis'!F$60 -> 0 | G44: ='FS & Trend Analysis'!G45/'FS & Trend Analysis'!G$60 -> 0 | H44: ='FS & Trend Analysis'!H45/'FS & Trend Analysis'!H$60 -> 0 | I44: ='FS & Trend Analysis'!I45/'FS & Trend Analysis'!I$60 -> 0.0068972911
A45: Provisions | B45: ='FS & Trend Analysis'!B46/'FS & Trend Analysis'!B$60 -> 0 | C45: ='FS & Trend Analysis'!C46/'FS & Trend Analysis'!C$60 -> 0 | D45: ='FS & Trend Analysis'!D46/'FS & Trend Analysis'!D$60 -> 0 | E45: ='FS & Trend Analysis'!E46/'FS & Trend Analysis'!E$60 -> 0 | F45: ='FS & Trend Analysis'!F46/'FS & Trend Analysis'!F$60 -> 0 | G45: ='FS & Trend Analysis'!G46/'FS & Trend Analysis'!G$60 -> 0 | H45: ='FS & Trend Analysis'!H46/'FS & Trend Analysis'!H$60 -> 0 | I45: ='FS & Trend Analysis'!I46/'FS & Trend Analysis'!I$60 -> 0.0080579614
A46: Deferred Tax Liabilities | B46: ='FS & Trend Analysis'!B47/'FS & Trend Analysis'!B$60 -> 0 | C46: ='FS & Trend Analysis'!C47/'FS & Trend Analysis'!C$60 -> 0.017976278 | D46: ='FS & Trend Analysis'!D47/'FS & Trend Analysis'!D$60 -> 0.030623041 | E46: ='FS & Trend Analysis'!E47/'FS & Trend Analysis'!E$60 -> 0.03344824 | F46: ='FS & Trend Analysis'!F47/'FS & Trend Analysis'!F$60 -> 0.033120843 | G46: ='FS & Trend Analysis'!G47/'FS & Trend Analysis'!G$60 -> 0.024020449 | H46: ='FS & Trend Analysis'!H47/'FS & Trend Analysis'!H$60 -> 0.019602452 | I46: ='FS & Trend Analysis'!I47/'FS & Trend Analysis'!I$60 -> 0.016825493
A47: Other Non-Current Liabilities | B47: ='FS & Trend Analysis'!B48/'FS & Trend Analysis'!B$60 -> 0.0091587004 | C47: ='FS & Trend Analysis'!C48/'FS & Trend Analysis'!C$60 -> 0.0094328306 | D47: ='FS & Trend Analysis'!D48/'FS & Trend Analysis'!D$60 -> 0.0049386102 | E47: ='FS & Trend Analysis'!E48/'FS & Trend Analysis'!E$60 -> 0.0068507127 | F47: ='FS & Trend Analysis'!F48/'FS & Trend Analysis'!F$60 -> 0.006535757 | G47: ='FS & Trend Analysis'!G48/'FS & Trend Analysis'!G$60 -> 0.0062976293 | H47: ='FS & Trend Analysis'!H48/'FS & Trend Analysis'!H$60 -> 0.013924868 | I47: ='FS & Trend Analysis'!I48/'FS & Trend Analysis'!I$60 -> 0
A48: Total Non-Current Liabilities | B48: ='FS & Trend Analysis'!B49/'FS & Trend Analysis'!B$60 -> 0.010285001 | C48: ='FS & Trend Analysis'!C49/'FS & Trend Analysis'!C$60 -> 0.038929268 | D48: ='FS & Trend Analysis'!D49/'FS & Trend Analysis'!D$60 -> 0.049139237 | E48: ='FS & Trend Analysis'!E49/'FS & Trend Analysis'!E$60 -> 0.048899994 | F48: ='FS & Trend Analysis'!F49/'FS & Trend Analysis'!F$60 -> 0.046403118 | G48: ='FS & Trend Analysis'!G49/'FS & Trend Analysis'!G$60 -> 0.043108518 | H48: ='FS & Trend Analysis'!H49/'FS & Trend Analysis'!H$60 -> 0.044680723 | I48: ='FS & Trend Analysis'!I49/'FS & Trend Analysis'!I$60 -> 0.042977277
A50: Current Liabilities
A51: Short Term Borrowings | B51: ='FS & Trend Analysis'!B52/'FS & Trend Analysis'!B$60 -> 0.0082595372 | C51: ='FS & Trend Analysis'!C52/'FS & Trend Analysis'!C$60 -> 0.0066336798 | D51: ='FS & Trend Analysis'!D52/'FS & Trend Analysis'!D$60 -> 0.0026175549 | E51: ='FS & Trend Analysis'!E52/'FS & Trend Analysis'!E$60 -> 0.0043324234 | F51: ='FS & Trend Analysis'!F52/'FS & Trend Analysis'!F$60 -> 0.0099263093 | G51: ='FS & Trend Analysis'!G52/'FS & Trend Analysis'!G$60 -> 0.0084314023 | H51: ='FS & Trend Analysis'!H52/'FS & Trend Analysis'!H$60 -> 0.012346679 | I51: ='FS & Trend Analysis'!I52/'FS & Trend Analysis'!I$60 -> 0.014116225
A52: Lease Liabilities | B52: ='FS & Trend Analysis'!B53/'FS & Trend Analysis'!B$60 -> 0 | C52: ='FS & Trend Analysis'!C53/'FS & Trend Analysis'!C$60 -> 0 | D52: ='FS & Trend Analysis'!D53/'FS & Trend Analysis'!D$60 -> 0 | E52: ='FS & Trend Analysis'!E53/'FS & Trend Analysis'!E$60 -> 0 | F52: ='FS & Trend Analysis'!F53/'FS & Trend Analysis'!F$60 -> 0 | G52: ='FS & Trend Analysis'!G53/'FS & Trend Analysis'!G$60 -> 0.0017007157 | H52: ='FS & Trend Analysis'!H53/'FS & Trend Analysis'!H$60 -> 0.0012803033 | I52: ='FS & Trend Analysis'!I53/'FS & Trend Analysis'!I$60 -> 0.0016095459
A53: Trade Payables | B53: ='FS & Trend Analysis'!B54/'FS & Trend Analysis'!B$60 -> 0.25464622 | C53: ='FS & Trend Analysis'!C54/'FS & Trend Analysis'!C$60 -> 0.22030982 | D53: ='FS & Trend Analysis'!D54/'FS & Trend Analysis'!D$60 -> 0.21330982 | E53: ='FS & Trend Analysis'!E54/'FS & Trend Analysis'!E$60 -> 0.19401692 | F53: ='FS & Trend Analysis'!F54/'FS & Trend Analysis'!F$60 -> 0.18580702 | G53: ='FS & Trend Analysis'!G54/'FS & Trend Analysis'!G$60 -> 0.15897168 | H53: ='FS & Trend Analysis'!H54/'FS & Trend Analysis'!H$60 -> 0.22792516 | I53: ='FS & Trend Analysis'!I54/'FS & Trend Analysis'!I$60 -> 0.19321179
A54: Other Financial Liabilities | B54: ='FS & Trend Analysis'!B55/'FS & Trend Analysis'!B$60 -> 0 | C54: ='FS & Trend Analysis'!C55/'FS & Trend Analysis'!C$60 -> 0 | D54: ='FS & Trend Analysis'!D55/'FS & Trend Analysis'!D$60 -> 0.023418234 | E54: ='FS & Trend Analysis'!E55/'FS & Trend Analysis'!E$60 -> 0.011645867 | F54: ='FS & Trend Analysis'!F55/'FS & Trend Analysis'!F$60 -> 0.012096609 | G54: ='FS & Trend Analysis'!G55/'FS & Trend Analysis'!G$60 -> 0.013148779 | H54: ='FS & Trend Analysis'!H55/'FS & Trend Analysis'!H$60 -> 0.0072531758 | I54: ='FS & Trend Analysis'!I55/'FS & Trend Analysis'!I$60 -> 0.0064764425
...

Sheet Comparative FS
B2: Comparative Financial Statements (YoY)
B4: Comparative Income Statement
B5: Particulars | C5: 42460 | D5: 42825 | E5: 43190 | F5: 43555 | G5: 43921 | H5: 44286 | I5: 44651
B6: Revenue from Operations
B7: Other Income
B8: Total Income
B10: Expenses
B11: Raw Material
B12: Excise Duty
B13: Employee Costs
B14: Other Expenses
B15: Total Expenses
B17: EBITDA
B18: Depreciation & Amortization
B19: EBIT
... B32: Comparative Balance Sheet
B33: Particulars | C33: 42460 | D33: 42825 | E33: 43190 | F33: 43555 | G33: 43921 | H33: 44286 | I33: 44651
B34: Equity & Liabilities
B35: Equity Share Capital
B36: Other Equity
B37: Total Equity
B38: Non-Controlling Interest
B40: Non-Current Liabilities
B41: Borrowings
B42: Lease Liabilities
B43: Other financial liabilities
B44: Provisions
B45: Deferred Tax Liabilities
B46: Other Non-Current Liabilities
... B83: TOTAL ASSETS

Sheet Cash Flow Statement
A1: Cash Flow Statement
A3: Particulars
A4: Cash Flow from Operating Activities | B4: March 31, 2015 | C4: March 31, 2016 | D4: March 31, 2017 | E4: March 31, 2018 | F4: March 31, 2019 | G4: March 31, 2020 | H4: March 31, 2021 | I4: March 31, 2022
A5: Net profit before tax | B5: 3291.96 | C5: 4312.45 | D5: 3546.3 | E5: 3722.17 | F5: 3466.35 | G5: 3659.41 | H5: 2936.05 | I5: 2329.05
A6: Adjustments for:
A7: Add: Depreciation and amortisation | B7: 540.45 | C7: 447.01 | D7: 502.25 | E7: 574.98 | F7: 624.44 | G7: 845.76 | H7: 715.12 | I7: 689.52
A8: Tax expense | D8: 1339.1 | E8: 1569.93 | F8: 1637.95 | G8: 951.67 | H8: 913.27 | I8: 729.06
A9: Loss on fixed assets sold/discarded | B9: 22.84 | C9: 108.99 | D9: 170.82 | E9: 9.28 | F9: 6.47 | G9: 8.66 | H9: 4.67 | I9: 10.23
A10: Loss on sale of non-trade current investments | B10: 0.21 | C10: 0.03
A11: Provision for diminution in value of investment:
A12: Exceptional item: Long term trade investment - non current | B12: 144.73
A13: Long term non trade investment | B13: 0.72 | C13: 0.52
A14: Finance cost | B14: 11.7 | C14: 11.87 | D14: 27.28 | E14: 30.8 | F14: 37.18 | G14: 46.64 | H14: 46.41 | I14: 53.1
A15: Exchange differences | B15: 0.03
A16: Impairment of goodwill on consolidation | B16: 3.94
A17: Expense on employee stock option scheme | C17: 0.93 | D17: 3.42 | E17: 5.35 | F17: 6.55 | G17: 10.15 | H17: 8.86 | I17: 10
A18: Provision for doubtful debts | B18: 0.7 | C18: 3.03
A19: Loss allowance on advances | I19: 52.24
A20: Loss allowance on trade receivables | G20: 53.04 | H20: 46.9 | I20: 0.74
B21: =SUM(B7:B18) -> 725.32 | C21: =SUM(C7:C18) -> 572.38 | D21: =SUM(D7:D18) -> 2042.87 | E21: =SUM(E7:E18) -> 2190.34 | F21: =SUM(F7:F18) -> 2312.59 | G21: =SUM(G7:G20) -> 1915.92 | H21: =SUM(H7:H20) -> 1735.23 | I21: =SUM(I7:I20) -> 1544.89
A22: Less: Interest on long term and current non-trade investments | B22: 50.37 | C22: 41.54 | D22: 159.3 | E22: 157.19 | F22: 288.03 | G22: 277.77 | H22: 100.42 | I22: 189.05
A23: Interest on loans, deposits etc. | B23: 99.64 | C23: 124.24
A24: Profit on sale of fixed assets | B24: 0.68 | C24: 0.51 | D24: 0.76 | E24: 0.54 | F24: 0.66 | G24: 0.37 | H24: 0.89 | I24: 0.62
A25: Profit on sale of investments | D25: 137.85 | E25: 216.09 | F25: 144.61 | G25: 136.07 | H25: 169.07 | I25: 109.11
A26: Gain on investments carried at fair value through profit or loss | D26: 179.6 | E26: 74.59 | F26: 175.11 | G26: 221.78 | H26: 285.77 | I26: 223.82
A27: Share of profit in associates | D27: 317.01 | E27: 49.66 | F27: 60.19 | G27: 34.63 | H27: -46.56 | I27: -199.05
A28: Re-measurement loss on defined benefit plans | D28: 21.58
A29: Foreign currency translation (net) | B29: 3.64 | C29: -1.81 | D29: 2.43 | E29: 11.13 | F29: -9.91 | G29: -19.01 | H29: 6.79 | I29: -7.53
A30: Dividend income: | D30: 37.98 | E30: 70.56 | F30: 71.76 | G30: 48.27 | H30: 1.39 | I30: 1.67
A31: On current Investments - Non-Trade | B31: 1.5 | C31: 7.06
A32: On long-term investments- Non trade | B32: 0.06 | C32: 0.12
A33: Profit on sale of non-trade current investments | B33: 320.75 | C33: 205.18
B34: =SUM(B22:B33) -> 476.64 | C34: =SUM(C22:C33) -> 376.84 | D34: =SUM(D22:D33) -> 856.51 | E34: =SUM(E22:E33) -> 579.76 | F34: =SUM(F22:F33) -> 730.45 | G34: =SUM(G22:G33) -> 699.88 | H34: =SUM(H22:H33) -> 517.77 | I34: =SUM(I22:I33) -> 317.69
A35: Operating profit before working capital changes | B35: =B5+B21-B34 -> 3540.64 | C35: =C5+C21-C34 -> 4507.99 | D35: =D5+D21-D34 -> 4732.66 | E35: =E5+E21-E34 -> 5332.75 | F35: =F5+F21-F34 -> 5048.49 | G35: =G5+G21-G34 -> 4875.45 | H35: =H5+H21-H34 -> 4153.51 | I35: =I5+I21-I34 -> 3556.25
A36: Changes in working capital:
A37: Adjustment for (increase)/decrease in operating assets:
A38: Add: Inventories | B38: -191.84 | C38: 99.4 | D38: 53.41 | E38: -254.1 | F38: -286.86 | G38: -32.79 | H38: -506.95 | I38: 316.86
A39: Trade receivables | B39: -451.97 | C39: 86.71 | D39: -269.68 | E39: 124.78 | F39: -1318.14 | G39: 1180.16 | H39: -809.67 | I39: 115.45
A40: Short-term loans and advances | B40: -243.03 | C40: 38.29 | D40: 1.48 | E40: -3.57 | F40: 3.42 | G40: 1.33 | H40: -16.02 | I40: 0.14
A41: Long-term loans and advances | B41: -23.14 | C41: 44.21 | D41: 3.57 | E41: 2.67 | F41: -14.28 | G41: -7.56 | H41: 15.04 | I41: -0.7
...

Sheet Shareholding
A2: Promoter Group | B2: 0.346
A3: Foreign Institutional Investors (FII) | B3: 0.343
A4: Non Resident Indians (NRIs) | B4: 0.004
A5: Indian Public | B5: 0.083
A6: Insurance companies | B6: 0.083
A7: Mutual Funds / UTI | B7: 0.082
A8: Bodies Corporate | B8: 0.014
A9: Financial Institutions / Banks | B9: 0.02
A10: Others | B10: 0.025
