Workbook

Sheet CAD AS % OF GDP
A1: Country Name | B1: India
A2: Country Code | B2: IND
A3: Indicator Name | B3: Current account balance (% of GDP)
A4: Indicator Code | B4: BN.CAB.XOKA.GD.ZS
A5: 2000 | B5: -0.98234258
A6: 2001 | B6: 0.29049546
A7: 2002 | B7: 1.3709379
A8: 2003 | B8: 1.4435577
A9: 2004 | B9: 0.11001801
A10: 2005 | B10: -1.253504
A11: 2006 | B11: -0.9889883
A12: 2007 | B12: -0.66371765
A13: 2008 | B13: -2.5833775
A14: 2009 | B14: -1.9514621
A15: 2010 | B15: -3.2534837
A16: 2011 | B16: -3.4292847
... A29: 2024 | B29: -0.82224321

Sheet ANNUAL EXCHANGE RATE
A1: YEAR | B1: AVERAGE EXCHANGE ANNUAL | C1: AVERAGE EXCHANGE ANNUAL RATE
A2: 2010 | B2: 45.737276
A3: 2011 | B3: 46.67154 | C3: 2.0426743
A4: 2012 | B4: 53.494454 | C4: 14.619004
A5: 2013 | B5: 58.634698 | C5: 9.6089285
A6: 2014 | B6: 61.027546 | C6: 4.0809424
A7: 2015 | B7: 64.152483 | C7: 5.1205342
A8: 2016 | B8: 67.213172 | C8: 4.7709605
A9: 2017 | B9: 65.116259 | C9: -3.1197949
A10: 2018 | B10: 68.362885 | C10: 4.9858907
A11: 2019 | B11: 70.408582 | C11: 2.9924098
A12: 2020 | B12: 74.070085 | C12: 5.2003646
A13: 2021 | B13: 73.926532 | C13: -0.19380712
A14: 2022 | B14: 78.65309 | C14: 6.3935882
... A17: 2025 | B17: 86.887834 | C17: 3.8351472

Sheet ANNUAL NET FPI
A1: YEAR | B1: ANNUAL FPI
A2: 2011 | B2: 2636.26
A3: 2012 | B3: 29502.74
A4: 2013 | B4: 6878.4301
A5: 2014 | B5: 37740.322
A6: 2015 | B6: 11130.716
A7: 2016 | B7: -4725.2094
A8: 2017 | B8: 30637.785
A9: 2018 | B9: -7777.9396
A10: 2019 | B10: 24584.12
A11: 2020 | B11: 15111.707
A12: 2021 | B12: 5718.1994
A13: 2022 | B13: -18702.836
... A16: 2025 | B16: -9997.3142

Sheet MASTER_ANNUAL
A1: YEAR | B1: CAD (% of GDP) | C1: ANNUAL EXCHANGE RATE | D1: ANNUAL NET FPI | E1: CAD (% of GDP) | F1: CAD x FPI | G1: FPI REGIME | L1: CAD_REGIME | M1: ΔEXR_Inflow | N1: ΔEXR_Outflow
A2: 2011 | B2: =_xlfn.XLOOKUP(A2,'CAD AS % OF GDP'!A16:A29,'CAD AS % OF GDP'!B16:B29) -> -3.4292847 | C2: =_xlfn.XLOOKUP(A2,'ANNUAL EXCHANGE RATE'!A3:A17,'ANNUAL EXCHANGE RATE'!C3:C17) -> 2.0426743 | D2: 2636.26 | E2: -3.4292847 | F2: =B2*D2 -> -9040.486 | G2: =IF(D2>0,"Inflow","Outflow") -> Inflow | L2: =IF(B2<0,"CAD","Non-CAD") -> CAD | M2: =IF(G2="Inflow", C2, "") -> 2.0426743 | N2: =IF(G2="Outflow", C2, "")
A3: 2012 | B3: =_xlfn.XLOOKUP(A3,'CAD AS % OF GDP'!A17:A30,'CAD AS % OF GDP'!B17:B30) -> -5.0048897 | C3: =_xlfn.XLOOKUP(A3,'ANNUAL EXCHANGE RATE'!A4:A18,'ANNUAL EXCHANGE RATE'!C4:C18) -> 14.619004 | D3: 29502.74 | E3: -5.0048897 | F3: =B3*D3 -> -147657.96 | G3: =IF(D3>0,"Inflow","Outflow") -> Inflow | L3: =IF(B3<0,"CAD","Non-CAD") -> CAD | M3: =IF(G3="Inflow", C3, "") -> 14.619004 | N3: =IF(G3="Outflow", C3, "")
A4: 2013 | B4: =_xlfn.XLOOKUP(A4,'CAD AS % OF GDP'!A18:A31,'CAD AS % OF GDP'!B18:B31) -> -2.6456671 | C4: =_xlfn.XLOOKUP(A4,'ANNUAL EXCHANGE RATE'!A5:A19,'ANNUAL EXCHANGE RATE'!C5:C19) -> 9.6089285 | D4: 6878.4301 | E4: -2.6456671 | F4: =B4*D4 -> -18198.036 | G4: =IF(D4>0,"Inflow","Outflow") -> Inflow | L4: =IF(B4<0,"CAD","Non-CAD") -> CAD | M4: =IF(G4="Inflow", C4, "") -> 9.6089285 | N4: =IF(G4="Outflow", C4, "")
A5: 2014 | B5: =_xlfn.XLOOKUP(A5,'CAD AS % OF GDP'!A19:A32,'CAD AS % OF GDP'!B19:B32) -> -1.339509 | C5: =_xlfn.XLOOKUP(A5,'ANNUAL EXCHANGE RATE'!A6:A20,'ANNUAL EXCHANGE RATE'!C6:C20) -> 4.0809424 | D5: 37740.322 | E5: -1.339509 | F5: =B5*D5 -> -50553.5 | G5: =IF(D5>0,"Inflow","Outflow") -> Inflow | L5: =IF(B5<0,"CAD","Non-CAD") -> CAD | M5: =IF(G5="Inflow", C5, "") -> 4.0809424 | N5: =IF(G5="Outflow", C5, "")
A6: 2015 | B6: =_xlfn.XLOOKUP(A6,'CAD AS % OF GDP'!A20:A33,'CAD AS % OF GDP'!B20:B33) -> -1.0675491 | C6: =_xlfn.XLOOKUP(A6,'ANNUAL EXCHANGE RATE'!A7:A21,'ANNUAL EXCHANGE RATE'!C7:C21) -> 5.1205342 | D6: 11130.716 | E6: -1.0675491 | F6: =B6*D6 -> -11882.585 | G6: =IF(D6>0,"Inflow","Outflow") -> Inflow | L6: =IF(B6<0,"CAD","Non-CAD") -> CAD | M6: =IF(G6="Inflow", C6, "") -> 5.1205342 | N6: =IF(G6="Outflow", C6, "")
A7: 2016 | B7: =_xlfn.XLOOKUP(A7,'CAD AS % OF GDP'!A21:A34,'CAD AS % OF GDP'!B21:B34) -> -0.52788061 | C7: =_xlfn.XLOOKUP(A7,'ANNUAL EXCHANGE RATE'!A8:A22,'ANNUAL EXCHANGE RATE'!C8:C22) -> 4.7709605 | D7: -4725.2094 | E7: -0.52788061 | F7: =B7*D7 -> 2494.3464 | G7: =IF(D7>0,"Inflow","Outflow") -> Outflow | L7: =IF(B7<0,"CAD","Non-CAD") -> CAD | M7: =IF(G7="Inflow", C7, "") | N7: =IF(G7="Outflow", C7, "") -> 4.7709605
A8: 2017 | B8: =_xlfn.XLOOKUP(A8,'CAD AS % OF GDP'!A22:A35,'CAD AS % OF GDP'!B22:B35) -> -1.4394882 | C8: =_xlfn.XLOOKUP(A8,'ANNUAL EXCHANGE RATE'!A9:A23,'ANNUAL EXCHANGE RATE'!C9:C23) -> -3.1197949 | D8: 30637.785 | E8: -1.4394882 | F8: =B8*D8 -> -44102.73 | G8: =IF(D8>0,"Inflow","Outflow") -> Inflow | L8: =IF(B8<0,"CAD","Non-CAD") -> CAD | M8: =IF(G8="Inflow", C8, "") -> -3.1197949 | N8: =IF(G8="Outflow", C8, "")
A9: 2018 | B9: =_xlfn.XLOOKUP(A9,'CAD AS % OF GDP'!A23:A36,'CAD AS % OF GDP'!B23:B36) -> -2.4269755 | C9: =_xlfn.XLOOKUP(A9,'ANNUAL EXCHANGE RATE'!A10:A24,'ANNUAL EXCHANGE RATE'!C10:C24) -> 4.9858907 | D9: -7777.9396 | E9: -2.4269755 | F9: =B9*D9 -> 18876.869 | G9: =IF(D9>0,"Inflow","Outflow") -> Outflow | L9: =IF(B9<0,"CAD","Non-CAD") -> CAD | M9: =IF(G9="Inflow", C9, "") | N9: =IF(G9="Outflow", C9, "") -> 4.9858907
A10: 2019 | B10: =_xlfn.XLOOKUP(A10,'CAD AS % OF GDP'!A24:A37,'CAD AS % OF GDP'!B24:B37) -> -1.049612 | C10: =_xlfn.XLOOKUP(A10,'ANNUAL EXCHANGE RATE'!A11:A25,'ANNUAL EXCHANGE RATE'!C11:C25) -> 2.9924098 | D10: 24584.12 | E10: -1.049612 | F10: =B10*D10 -> -25803.788 | G10: =IF(D10>0,"Inflow","Outflow") -> Inflow | L10: =IF(B10<0,"CAD","Non-CAD") -> CAD | M10: =IF(G10="Inflow", C10, "") -> 2.9924098 | N10: =IF(G10="Outflow", C10, "")
A11: 2020 | B11: =_xlfn.XLOOKUP(A11,'CAD AS % OF GDP'!A25:A38,'CAD AS % OF GDP'!B25:B38) -> 1.2236211 | C11: =_xlfn.XLOOKUP(A11,'ANNUAL EXCHANGE RATE'!A12:A26,'ANNUAL EXCHANGE RATE'!C12:C26) -> 5.2003646 | D11: 15111.707 | E11: 1.2236211 | F11: =B11*D11 -> 18491.003 | G11: =IF(D11>0,"Inflow","Outflow") -> Inflow | L11: =IF(B11<0,"CAD","Non-CAD") -> Non-CAD | M11: =IF(G11="Inflow", C11, "") -> 5.2003646 | N11: =IF(G11="Outflow", C11, "")
A12: 2021 | B12: =_xlfn.XLOOKUP(A12,'CAD AS % OF GDP'!A26:A39,'CAD AS % OF GDP'!B26:B39) -> -1.0552417 | C12: =_xlfn.XLOOKUP(A12,'ANNUAL EXCHANGE RATE'!A13:A27,'ANNUAL EXCHANGE RATE'!C13:C27) -> -0.19380712 | D12: 5718.1994 | E12: -1.0552417 | F12: =B12*D12 -> -6034.0822 | G12: =IF(D12>0,"Inflow","Outflow") -> Inflow | L12: =IF(B12<0,"CAD","Non-CAD") -> CAD | M12: =IF(G12="Inflow", C12, "") -> -0.19380712 | N12: =IF(G12="Outflow", C12, "")
A13: 2022 | B13: =_xlfn.XLOOKUP(A13,'CAD AS % OF GDP'!A27:A40,'CAD AS % OF GDP'!B27:B40) -> -2.3624748 | C13: =_xlfn.XLOOKUP(A13,'ANNUAL EXCHANGE RATE'!A14:A28,'ANNUAL EXCHANGE RATE'!C14:C28) -> 6.3935882 | D13: -18702.836 | E13: -2.3624748 | F13: =B13*D13 -> 44184.98 | G13: =IF(D13>0,"Inflow","Outflow") -> Outflow | L13: =IF(B13<0,"CAD","Non-CAD") -> CAD | M13: =IF(G13="Inflow", C13, "") | N13: =IF(G13="Outflow", C13, "") -> 6.3935882
A14: 2023 | B14: =_xlfn.XLOOKUP(A14,'CAD AS % OF GDP'!A28:A41,'CAD AS % OF GDP'!B28:B41) -> -0.87826285 | C14: =_xlfn.XLOOKUP(A14,'ANNUAL EXCHANGE RATE'!A15:A29,'ANNUAL EXCHANGE RATE'!C15:C29) -> 5.028757 | D14: 31025.325 | E14: -0.87826285 | F14: =B14*D14 -> -27248.39 | G14: =IF(D14>0,"Inflow","Outflow") -> Inflow | L14: =IF(B14<0,"CAD","Non-CAD") -> CAD | M14: =IF(G14="Inflow", C14, "") -> 5.028757 | N14: =IF(G14="Outflow", C14, "")
A15: 2024 | B15: =_xlfn.XLOOKUP(A15,'CAD AS % OF GDP'!A29:A42,'CAD AS % OF GDP'!B29:B42) -> -0.82224321 | C15: =_xlfn.XLOOKUP(A15,'ANNUAL EXCHANGE RATE'!A16:A30,'ANNUAL EXCHANGE RATE'!C16:C30) -> 1.2955982 | D15: 20814.571 | E15: -0.82224321 | F15: =B15*D15 -> -17114.64 | G15: =IF(D15>0,"Inflow","Outflow") -> Inflow
A23: t-Test: Two-Sample Assuming Unequal Variances
B25: ΔEXR_Inflow | C25: ΔEXR_Outflow
A26: Mean | B26: 4.4644053 | C26: 5.3834798
A27: Variance | B27: 27.216077 | C27: 0.77678798
A28: Observations | B28: 9 | C28: 3 | I28: ΔEXR_Inflow
A29: Hypothesized Mean Difference | B29: 0 | I29: 2.0426743
A30: df | B30: 9 | I30: 14.619004
A31: t Stat | B31: -0.50724688 | I31: 9.6089285
A32: P(T<=t) one-tail | B32: 0.31208844 | I32: 4.0809424
A33: t Critical one-tail | B33: 1.8331129 | I33: 5.1205342
A34: P(T<=t) two-tail | B34: 0.62417688 | I34: -3.1197949
A35: t Critical two-tail | B35: 2.2621572 | I35: 2.9924098
I36: -0.19380712
I37: 5.028757
I41: ΔEXR_Outflow
I42: 4.7709605
I43: 4.9858907
I44: 6.3935882
A46: SUMMARY OUTPUT
A48: Regression Statistics
A49: Multiple R | B49: 0.64260649
A50: R Square | B50: 0.4129431
A51: Adjusted R Square | B51: 0.23682602
A52: Standard Error | B52: 3.693605
A53: Observations | B53: 14
...

Sheet TESTS
A1: CORRELATION TEST
B3: CAD (% of GDP) | C3: ANNUAL EXCHANGE RATE
A4: CAD (% of GDP) | B4: 1
A5: ANNUAL EXCHANGE RATE | B5: -0.50840978 | C5: 1
B7: ANNUAL EXCHANGE RATE | C7: ANNUAL NET FPI
A8: ANNUAL EXCHANGE RATE | B8: 1
A9: ANNUAL NET FPI | B9: -0.061654562 | C9: 1
B11: ANNUAL NET FPI | C11: CAD (% of GDP)
A12: ANNUAL NET FPI | B12: 1
A13: CAD (% of GDP) | B13: 0.084494092 | C13: 1
A16: T -TEST
A18: NULL HYPOTHESIS: | B18: There is no significant difference in average rupee depreciation between CAD periods with capital inflows and those with capital outflows.
A19: ALTERNATE HYPOTHESIS | B19: Average rupee depreciation is significantly higher during CAD periods accompanied by capital outflows compared to CAD periods with capital inflows.
A21: t-Test: Two-Sample Assuming Unequal Variances
B23: ΔEXR_Inflow | C23: ΔEXR_Outflow
A24: Mean | B24: 4.4644053 | C24: 5.3834798
A25: Variance | B25: 27.216077 | C25: 0.77678798
A26: Observations | B26: 9 | C26: 3
A27: Hypothesized Mean Difference | B27: 0
A28: df | B28: 9
A29: t Stat | B29: -0.50724688
A30: P(T<=t) one-tail | B30: 0.31208844
A31: t Critical one-tail | B31: 1.8331129
A32: P(T<=t) two-tail | B32: 0.62417688
A33: t Critical two-tail | B33: 2.2621572
A45: TEST 3 :- REGRESSION
A47: SUMMARY OUTPUT
A49: Regression Statistics
A50: Multiple R | B50: 0.64260649
A51: R Square | B51: 0.4129431
A52: Adjusted R Square | B52: 0.23682602
A53: Standard Error | B53: 3.693605
A54: Observations | B54: 14
A56: ANOVA
B57: df | C57: SS | D57: MS | E57: F | F57: Significance F
A58: Regression | B58: 3 | C58: 95.964566 | D58: 31.988189 | E58: 2.3447079 | F58: 0.13448903
A59: Residual | B59: 10 | C59: 136.42718 | D59: 13.642718
A60: Total | B60: 13 | C60: 232.39174
B62: Coefficients | C62: Standard Error | D62: t Stat | E62: P-value | F62: Lower 95% | G62: Upper 95% | H62: Lower 95.0% | I62: Upper 95.0%
A63: Intercept | B63: 5.6666967 | C63: 2.7681083 | D63: 2.0471369 | E63: 0.067832581 | F63: -0.50103306 | G63: 11.834426 | H63: -0.50103306 | I63: 11.834426
...
